
D:\>
D:\>
D:\>
D:\>virtualenvironment
'virtualenvironment' is not recognized as an internal or external command,
operable program or batch file.

D:\>virtualenv
You must provide a DEST_DIR
Usage: virtualenv [OPTIONS] DEST_DIR

Options:
  --version             show program's version number and exit
  -h, --help            show this help message and exit
  -v, --verbose         Increase verbosity.
  -q, --quiet           Decrease verbosity.
  -p PYTHON_EXE, --python=PYTHON_EXE
                        The Python interpreter to use, e.g.,
                        --python=python3.5 will use the python3.5 interpreter
                        to create the new environment.  The default is the
                        interpreter that virtualenv was installed with
                        (c:\programdata\anaconda2\python.exe)
  --clear               Clear out the non-root install and start from scratch.
  --no-site-packages    DEPRECATED. Retained only for backward compatibility.
                        Not having access to global site-packages is now the
                        default behavior.
  --system-site-packages
                        Give the virtual environment access to the global
                        site-packages.
  --always-copy         Always copy files rather than symlinking.
  --relocatable         Make an EXISTING virtualenv environment relocatable.
                        This fixes up scripts and makes all .pth files
                        relative.
  --no-setuptools       Do not install setuptools in the new virtualenv.
  --no-pip              Do not install pip in the new virtualenv.
  --no-wheel            Do not install wheel in the new virtualenv.
  --extra-search-dir=DIR
                        Directory to look for setuptools/pip distributions in.
                        This option can be used multiple times.
  --download            Download preinstalled packages from PyPI.
  --no-download, --never-download
                        Do not download preinstalled packages from PyPI.
  --prompt=PROMPT       Provides an alternative prompt prefix for this
                        environment.
  --setuptools          DEPRECATED. Retained only for backward compatibility.
                        This option has no effect.
  --distribute          DEPRECATED. Retained only for backward compatibility.
                        This option has no effect.
  --unzip-setuptools    DEPRECATED.  Retained only for backward compatibility.
                        This option has no effect.

D:\>virtualenv --python=C:\Program Files (x86)\Python37-32\python django
The path C:\Program (from --python=C:\Program) does not exist

D:\>
D:\>
D:\>
D:\>
D:\>
D:\>
D:\>
D:\>
D:\>
D:\>
D:\>
D:\>
D:\>
D:\>
D:\>
D:\>
D:\>python
Python 2.7.15 |Anaconda, Inc.| (default, May  1 2018, 18:37:09) [MSC v.1500 64 bit (AMD64)] on win32
Type "help", "copyright", "credits" or "license" for more information.
>>> import django
>>> django
<module 'django' from 'C:\ProgramData\Anaconda2\lib\site-packages\django\__init__.pyc'>
>>> django -v
Traceback (most recent call last):
  File "<stdin>", line 1, in <module>
NameError: name 'v' is not defined
>>> help(django)
Help on package django:

NAME
    django

FILE
    c:\programdata\anaconda2\lib\site-packages\django\__init__.py

PACKAGE CONTENTS
    __main__
    apps (package)
    conf (package)
    contrib (package)
    core (package)
    db (package)
    dispatch (package)
    forms (package)
    http (package)
    middleware (package)
    shortcuts
    template (package)
    templatetags (package)
    test (package)
    urls (package)
    utils (package)
    views (package)

FUNCTIONS
    setup(set_prefix=True)
        Configure the settings (this happens as a side effect of accessing the
        first setting), configure logging and populate the app registry.
        Set the thread-local urlresolvers script prefix if `set_prefix` is True.

DATA
    VERSION = (1, 11, 18, u'final', 0)
    __version__ = '1.11.18'
    unicode_literals = _Feature((2, 6, 0, 'alpha', 2), (3, 0, 0, 'alpha', ...

VERSION
    1.11.18


>>>
>>>
>>>
>>>
>>>
>>>
>>>
>>>
>>>
>>>
>>>
>>>
>>>
>>>
>>>
>>>
>>>
>>>
>>>
>>> exit()

D:\>
D:\>
D:\>pip install pip --upgarde

Usage:
  pip install [options] <requirement specifier> [package-index-options] ...
  pip install [options] -r <requirements file> [package-index-options] ...
  pip install [options] [-e] <vcs project url> ...
  pip install [options] [-e] <local project path> ...
  pip install [options] <archive url/path> ...

no such option: --upgarde

D:\>pip install pip --upgrade
ERROR: To modify pip, please run the following command:
C:\ProgramData\Anaconda2\python.exe -m pip install pip --upgrade
You are using pip version 10.0.1, however version 19.0.1 is available.
You should consider upgrading via the 'python -m pip install --upgrade pip' command.

D:\>C:\ProgramData\Anaconda2\python.exe -m pip install pip --upgrade
Collecting pip
  Downloading https://files.pythonhosted.org/packages/46/dc/7fd5df840efb3e56c8b4f768793a237ec4ee59891959d6a215d63f727023/pip-19.0.1-py2.py3-none-any.whl (1.4MB)
    100% |################################| 1.4MB 1.2MB/s
distributed 1.21.8 requires msgpack, which is not installed.
grin 1.2.1 requires argparse>=1.1, which is not installed.
Installing collected packages: pip
  Found existing installation: pip 10.0.1
    Uninstalling pip-10.0.1:
Could not install packages due to an EnvironmentError: [Error 5] Access is denied: 'c:\\programdata\\anaconda2\\lib\\site-packages\\pip\\_internal\\basecommand.py'
Consider using the `--user` option or check the permissions.

You are using pip version 10.0.1, however version 19.0.1 is available.
You should consider upgrading via the 'python -m pip install --upgrade pip' command.

D:\>mkdir trydjango

D:\>cd trydjango

D:\trydjango>virtualenv .
New python executable in D:\trydjango\Scripts\python.exe
Installing setuptools, pip, wheel...done.

D:\trydjango>
D:\trydjango>
D:\trydjango>
D:\trydjango>Scripts\activate

(trydjango) D:\trydjango>pip freeze
DEPRECATION: Python 2.7 will reach the end of its life on January 1st, 2020. Please upgrade your Python as Python 2.7 won't be maintained after that date. A future version of pip will drop support for Python 2.7.

(trydjango) D:\trydjango>python
Python 2.7.15 |Anaconda, Inc.| (default, May  1 2018, 18:37:09) [MSC v.1500 64 bit (AMD64)] on win32
Type "help", "copyright", "credits" or "license" for more information.
>>> exit()

(trydjango) D:\trydjango>pip install django==1.9
DEPRECATION: Python 2.7 will reach the end of its life on January 1st, 2020. Please upgrade your Python as Python 2.7 won't be maintained after that date. A future version of pip will drop support for Python 2.7.
Collecting django==1.9
  Downloading https://files.pythonhosted.org/packages/ea/9b/b5a6360b3dfcd88d4bad70f59da26cbde4bdec395a31bb26dc840e806a50/Django-1.9-py2.py3-none-any.whl (6.6MB)
    100% |UUUUUUUUUUUUUUUUUUUUUUUUUUUUUUUU| 6.6MB 2.4MB/s
Installing collected packages: django
Successfully installed django-1.9

(trydjango) D:\trydjango>django-admin.py startproject trydjango

(trydjango) D:\trydjango>dir
 Volume in drive D is New Volume
 Volume Serial Number is AA56-2C4E

 Directory of D:\trydjango

04-02-2019  15:06    <DIR>          .
04-02-2019  15:06    <DIR>          ..
06-08-2018  13:12    <DIR>          Include
04-02-2019  15:01    <DIR>          Lib
04-02-2019  15:01                61 pip-selfcheck.json
04-02-2019  15:05    <DIR>          Scripts
04-02-2019  15:00    <DIR>          tcl
04-02-2019  15:06    <DIR>          trydjango
               1 File(s)             61 bytes
               7 Dir(s)  236,189,011,968 bytes free

(trydjango) D:\trydjango>python manage.py runserver
python: can't open file 'manage.py': [Errno 2] No such file or directory

(trydjango) D:\trydjango>cd trydjango

(trydjango) D:\trydjango\trydjango>python manage.py runserver
Performing system checks...

System check identified no issues (0 silenced).

You have unapplied migrations; your app may not work properly until they are applied.
Run 'python manage.py migrate' to apply them.
February 04, 2019 - 15:07:42
Django version 1.9, using settings 'trydjango.settings'
Starting development server at http://127.0.0.1:8000/
Quit the server with CTRL-BREAK.
Not Found: /
[04/Feb/2019 15:07:52] "GET / HTTP/1.1" 200 1767
Not Found: /favicon.ico
[04/Feb/2019 15:07:53] "GET /favicon.ico HTTP/1.1" 404 1939
^C
(trydjango) D:\trydjango\trydjango>cd ..

(trydjango) D:\trydjango>ren trydjango src

(trydjango) D:\trydjango>dir
 Volume in drive D is New Volume
 Volume Serial Number is AA56-2C4E

 Directory of D:\trydjango

04-02-2019  15:22    <DIR>          .
04-02-2019  15:22    <DIR>          ..
06-08-2018  13:12    <DIR>          Include
04-02-2019  15:01    <DIR>          Lib
04-02-2019  15:01                61 pip-selfcheck.json
04-02-2019  15:05    <DIR>          Scripts
04-02-2019  15:07    <DIR>          src
04-02-2019  15:00    <DIR>          tcl
               1 File(s)             61 bytes
               7 Dir(s)  236,188,987,392 bytes free

(trydjango) D:\trydjango>cd src

(trydjango) D:\trydjango\src>python manage.py migrate
Operations to perform:
  Apply all migrations: admin, contenttypes, auth, sessions
Running migrations:
  Rendering model states... DONE
  Applying contenttypes.0001_initial... OK
  Applying auth.0001_initial... OK
  Applying admin.0001_initial... OK
  Applying admin.0002_logentry_remove_auto_add... OK
  Applying contenttypes.0002_remove_content_type_name... OK
  Applying auth.0002_alter_permission_name_max_length... OK
  Applying auth.0003_alter_user_email_max_length... OK
  Applying auth.0004_alter_user_username_opts... OK
  Applying auth.0005_alter_user_last_login_null... OK
  Applying auth.0006_require_contenttypes_0002... OK
  Applying auth.0007_alter_validators_add_error_messages... OK
  Applying sessions.0001_initial... OK

(trydjango) D:\trydjango\src>python manage.py createsuperuser
Username (leave blank to use 'ravinder.baid'):
Email address:
Password:
Password (again):
Superuser created successfully.

(trydjango) D:\trydjango\src>dir
 Volume in drive D is New Volume
 Volume Serial Number is AA56-2C4E

 Directory of D:\trydjango\src

04-02-2019  15:23    <DIR>          .
04-02-2019  15:23    <DIR>          ..
04-02-2019  15:23           131,072 db.sqlite3
04-02-2019  15:06               252 manage.py
04-02-2019  15:07    <DIR>          trydjango
               2 File(s)        131,324 bytes
               3 Dir(s)  236,188,868,608 bytes free

(trydjango) D:\trydjango\src>python manage.py runserver
Performing system checks...

System check identified no issues (0 silenced).
February 04, 2019 - 15:25:09
Django version 1.9, using settings 'trydjango.settings'
Starting development server at http://127.0.0.1:8000/
Quit the server with CTRL-BREAK.
Not Found: /
[04/Feb/2019 15:25:14] "GET / HTTP/1.1" 200 1767
[04/Feb/2019 15:31:17] "GET /admin/ HTTP/1.1" 302 0
[04/Feb/2019 15:31:17] "GET /admin/login/?next=/admin/ HTTP/1.1" 200 1683
[04/Feb/2019 15:31:18] "GET /static/admin/css/base.css HTTP/1.1" 200 15897
[04/Feb/2019 15:31:18] "GET /static/admin/css/fonts.css HTTP/1.1" 200 423
[04/Feb/2019 15:31:19] "GET /static/admin/css/login.css HTTP/1.1" 200 1203
[04/Feb/2019 15:31:19] "GET /static/admin/fonts/Roboto-Regular-webfont.woff HTTP/1.1" 200 80304
[04/Feb/2019 15:31:19] "GET /static/admin/fonts/Roboto-Light-webfont.woff HTTP/1.1" 200 81348
[04/Feb/2019 15:31:28] "POST /admin/login/?next=/admin/ HTTP/1.1" 302 0
[04/Feb/2019 15:31:28] "GET /admin/ HTTP/1.1" 200 2791
[04/Feb/2019 15:31:28] "GET /static/admin/css/dashboard.css HTTP/1.1" 200 434
[04/Feb/2019 15:31:28] "GET /static/admin/img/icon-addlink.svg HTTP/1.1" 200 331
[04/Feb/2019 15:31:28] "GET /static/admin/img/icon-changelink.svg HTTP/1.1" 200 380
[04/Feb/2019 15:31:28] "GET /static/admin/fonts/Roboto-Bold-webfont.woff HTTP/1.1" 200 82564
[04/Feb/2019 15:32:19] "GET /admin/auth/user/add/ HTTP/1.1" 200 6767
[04/Feb/2019 15:32:19] "GET /static/admin/css/forms.css HTTP/1.1" 200 7750
[04/Feb/2019 15:32:19] "GET /static/admin/js/core.js HTTP/1.1" 200 8171
[04/Feb/2019 15:32:19] "GET /static/admin/js/admin/RelatedObjectLookups.js HTTP/1.1" 200 6055
[04/Feb/2019 15:32:19] "GET /static/admin/js/jquery.init.js HTTP/1.1" 200 363
[04/Feb/2019 15:32:19] "GET /static/admin/js/actions.js HTTP/1.1" 200 6259
[04/Feb/2019 15:32:19] "GET /static/admin/css/widgets.css HTTP/1.1" 200 10340
[04/Feb/2019 15:32:19] "GET /static/admin/js/urlify.js HTTP/1.1" 200 7693
[04/Feb/2019 15:32:19] "GET /static/admin/js/vendor/jquery/jquery.js HTTP/1.1" 200 247597
[04/Feb/2019 15:32:19] "GET /static/admin/js/prepopulate.js HTTP/1.1" 200 1538
[04/Feb/2019 15:32:19] "GET /static/admin/js/vendor/xregexp/xregexp.min.js HTTP/1.1" 200 62474
[04/Feb/2019 15:32:19] "GET /admin/jsi18n/ HTTP/1.1" 200 3217
[04/Feb/2019 15:32:32] "POST /admin/auth/user/add/ HTTP/1.1" 200 6928
[04/Feb/2019 15:32:32] "GET /admin/jsi18n/ HTTP/1.1" 200 3217
[04/Feb/2019 15:32:52] "POST /admin/auth/user/add/ HTTP/1.1" 302 0
[04/Feb/2019 15:32:52] "GET /admin/auth/user/2/change/ HTTP/1.1" 200 15163
[04/Feb/2019 15:32:52] "GET /static/admin/js/SelectBox.js HTTP/1.1" 200 5204
[04/Feb/2019 15:32:52] "GET /static/admin/js/SelectFilter2.js HTTP/1.1" 200 11202
[04/Feb/2019 15:32:52] "GET /static/admin/js/calendar.js HTTP/1.1" 200 6875
[04/Feb/2019 15:32:52] "GET /static/admin/js/admin/DateTimeShortcuts.js HTTP/1.1" 200 18585
[04/Feb/2019 15:32:52] "GET /admin/jsi18n/ HTTP/1.1" 200 3217
[04/Feb/2019 15:32:52] "GET /static/admin/img/icon-yes.svg HTTP/1.1" 200 436
[04/Feb/2019 15:32:53] "GET /static/admin/img/icon-unknown.svg HTTP/1.1" 200 655
[04/Feb/2019 15:32:53] "GET /static/admin/img/search.svg HTTP/1.1" 200 458
[04/Feb/2019 15:32:53] "GET /static/admin/img/selector-icons.svg HTTP/1.1" 200 3291
[04/Feb/2019 15:32:53] "GET /static/admin/img/icon-unknown-alt.svg HTTP/1.1" 200 655
[04/Feb/2019 15:32:53] "GET /static/admin/img/icon-calendar.svg HTTP/1.1" 200 1086
[04/Feb/2019 15:32:53] "GET /static/admin/img/icon-clock.svg HTTP/1.1" 200 677

(trydjango) D:\trydjango\src> python manage.py startapp posts

(trydjango) D:\trydjango\src> python manage.py ,igrate
Traceback (most recent call last):
  File "manage.py", line 10, in <module>
    execute_from_command_line(sys.argv)
  File "D:\trydjango\lib\site-packages\django\core\management\__init__.py", line 350, in execute_from_command_line
    utility.execute()
  File "D:\trydjango\lib\site-packages\django\core\management\__init__.py", line 324, in execute
    django.setup()
  File "D:\trydjango\lib\site-packages\django\__init__.py", line 18, in setup
    apps.populate(settings.INSTALLED_APPS)
  File "D:\trydjango\lib\site-packages\django\apps\registry.py", line 108, in populate
    app_config.import_models(all_models)
  File "D:\trydjango\lib\site-packages\django\apps\config.py", line 202, in import_models
    self.models_module = import_module(models_module_name)
  File "c:\programdata\anaconda2\Lib\importlib\__init__.py", line 37, in import_module
    __import__(name)
  File "D:\trydjango\src\posts\models.py", line 6, in <module>
    class Post(models.Model):
  File "D:\trydjango\src\posts\models.py", line 9, in Post
    updated = models.DateTimeField(auto_now=True, auto_add_now=False)
  File "D:\trydjango\lib\site-packages\django\db\models\fields\__init__.py", line 1187, in __init__
    super(DateField, self).__init__(verbose_name, name, **kwargs)
TypeError: __init__() got an unexpected keyword argument 'auto_add_now'

(trydjango) D:\trydjango\src> python manage.py migrate
Traceback (most recent call last):
  File "manage.py", line 10, in <module>
    execute_from_command_line(sys.argv)
  File "D:\trydjango\lib\site-packages\django\core\management\__init__.py", line 350, in execute_from_command_line
    utility.execute()
  File "D:\trydjango\lib\site-packages\django\core\management\__init__.py", line 324, in execute
    django.setup()
  File "D:\trydjango\lib\site-packages\django\__init__.py", line 18, in setup
    apps.populate(settings.INSTALLED_APPS)
  File "D:\trydjango\lib\site-packages\django\apps\registry.py", line 108, in populate
    app_config.import_models(all_models)
  File "D:\trydjango\lib\site-packages\django\apps\config.py", line 202, in import_models
    self.models_module = import_module(models_module_name)
  File "c:\programdata\anaconda2\Lib\importlib\__init__.py", line 37, in import_module
    __import__(name)
  File "D:\trydjango\src\posts\models.py", line 6, in <module>
    class Post(models.Model):
  File "D:\trydjango\src\posts\models.py", line 9, in Post
    updated = models.DateTimeField(auto_now=True, auto_add_now=False)
  File "D:\trydjango\lib\site-packages\django\db\models\fields\__init__.py", line 1187, in __init__
    super(DateField, self).__init__(verbose_name, name, **kwargs)
TypeError: __init__() got an unexpected keyword argument 'auto_add_now'

(trydjango) D:\trydjango\src> python manage.py migrate
Operations to perform:
  Apply all migrations: admin, contenttypes, auth, sessions
Running migrations:
  No migrations to apply.
  Your models have changes that are not yet reflected in a migration, and so won't be applied.
  Run 'manage.py makemigrations' to make new migrations, and then re-run 'manage.py migrate' to apply them.

(trydjango) D:\trydjango\src>python manage.py makemigrations
Migrations for 'posts':
  0001_initial.py:
    - Create model Post

(trydjango) D:\trydjango\src>python manage.py migrate
Operations to perform:
  Apply all migrations: admin, contenttypes, posts, auth, sessions
Running migrations:
  Rendering model states... DONE
  Applying posts.0001_initial... OK

(trydjango) D:\trydjango\src>python manage.py runserver
Performing system checks...

System check identified no issues (0 silenced).
February 04, 2019 - 16:21:10
Django version 1.9, using settings 'trydjango.settings'
Starting development server at http://127.0.0.1:8000/
Quit the server with CTRL-BREAK.
[04/Feb/2019 16:21:17] "GET /admin/ HTTP/1.1" 200 3726
[04/Feb/2019 16:21:17] "GET /static/admin/css/base.css HTTP/1.1" 304 0
[04/Feb/2019 16:21:17] "GET /static/admin/css/dashboard.css HTTP/1.1" 304 0
[04/Feb/2019 16:21:17] "GET /static/admin/css/fonts.css HTTP/1.1" 304 0
[04/Feb/2019 16:21:17] "GET /static/admin/img/icon-changelink.svg HTTP/1.1" 304 0
[04/Feb/2019 16:21:17] "GET /static/admin/img/icon-addlink.svg HTTP/1.1" 304 0
[04/Feb/2019 16:21:17] "GET /static/admin/fonts/Roboto-Light-webfont.woff HTTP/1.1" 304 0
[04/Feb/2019 16:21:17] "GET /static/admin/fonts/Roboto-Bold-webfont.woff HTTP/1.1" 304 0
[04/Feb/2019 16:21:17] "GET /static/admin/fonts/Roboto-Regular-webfont.woff HTTP/1.1" 304 0
[04/Feb/2019 16:21:20] "GET /admin/posts/post/ HTTP/1.1" 200 3163
[04/Feb/2019 16:21:20] "GET /static/admin/js/core.js HTTP/1.1" 304 0
[04/Feb/2019 16:21:20] "GET /static/admin/js/admin/RelatedObjectLookups.js HTTP/1.1" 304 0
[04/Feb/2019 16:21:20] "GET /static/admin/js/vendor/jquery/jquery.js HTTP/1.1" 304 0
[04/Feb/2019 16:21:20] "GET /static/admin/js/jquery.init.js HTTP/1.1" 304 0
[04/Feb/2019 16:21:20] "GET /static/admin/js/actions.js HTTP/1.1" 304 0
[04/Feb/2019 16:21:20] "GET /static/admin/js/urlify.js HTTP/1.1" 304 0
[04/Feb/2019 16:21:20] "GET /static/admin/js/prepopulate.js HTTP/1.1" 304 0
[04/Feb/2019 16:21:20] "GET /static/admin/js/vendor/xregexp/xregexp.min.js HTTP/1.1" 304 0
[04/Feb/2019 16:21:20] "GET /admin/jsi18n/ HTTP/1.1" 200 3217
[04/Feb/2019 16:21:20] "GET /static/admin/css/changelists.css HTTP/1.1" 200 6100
[04/Feb/2019 16:21:20] "GET /static/admin/img/tooltag-add.svg HTTP/1.1" 200 331
[04/Feb/2019 16:22:27] "GET /admin/posts/post/add/ HTTP/1.1" 200 5840
[04/Feb/2019 16:22:27] "GET /static/admin/css/forms.css HTTP/1.1" 304 0
[04/Feb/2019 16:22:27] "GET /static/admin/css/widgets.css HTTP/1.1" 304 0
[04/Feb/2019 16:22:27] "GET /admin/jsi18n/ HTTP/1.1" 200 3217
Internal Server Error: /admin/posts/post/add/
Traceback (most recent call last):
  File "D:\trydjango\lib\site-packages\django\core\handlers\base.py", line 149, in get_response
    response = self.process_exception_by_middleware(e, request)
  File "D:\trydjango\lib\site-packages\django\core\handlers\base.py", line 147, in get_response
    response = wrapped_callback(request, *callback_args, **callback_kwargs)
  File "D:\trydjango\lib\site-packages\django\contrib\admin\options.py", line 541, in wrapper
    return self.admin_site.admin_view(view)(*args, **kwargs)
  File "D:\trydjango\lib\site-packages\django\utils\decorators.py", line 149, in _wrapped_view
    response = view_func(request, *args, **kwargs)
  File "D:\trydjango\lib\site-packages\django\views\decorators\cache.py", line 57, in _wrapped_view_func
    response = view_func(request, *args, **kwargs)
  File "D:\trydjango\lib\site-packages\django\contrib\admin\sites.py", line 244, in inner
    return view(request, *args, **kwargs)
  File "D:\trydjango\lib\site-packages\django\contrib\admin\options.py", line 1435, in add_view
    return self.changeform_view(request, None, form_url, extra_context)
  File "D:\trydjango\lib\site-packages\django\utils\decorators.py", line 67, in _wrapper
    return bound_func(*args, **kwargs)
  File "D:\trydjango\lib\site-packages\django\utils\decorators.py", line 149, in _wrapped_view
    response = view_func(request, *args, **kwargs)
  File "D:\trydjango\lib\site-packages\django\utils\decorators.py", line 63, in bound_func
    return func.__get__(self, type(self))(*args2, **kwargs2)
  File "D:\trydjango\lib\site-packages\django\utils\decorators.py", line 184, in inner
    return func(*args, **kwargs)
  File "D:\trydjango\lib\site-packages\django\contrib\admin\options.py", line 1382, in changeform_view
    self.log_addition(request, new_object, change_message)
  File "D:\trydjango\lib\site-packages\django\contrib\admin\options.py", line 714, in log_addition
    object_repr=force_text(object),
  File "D:\trydjango\lib\site-packages\django\utils\encoding.py", line 78, in force_text
    s = six.text_type(s)
  File "D:\trydjango\src\posts\models.py", line 16, in __unicode__
    return self.title
NameError: global name 'self' is not defined
[04/Feb/2019 16:22:38] "POST /admin/posts/post/add/ HTTP/1.1" 500 118708
Performing system checks...

System check identified no issues (0 silenced).
February 04, 2019 - 16:23:00
Django version 1.9, using settings 'trydjango.settings'
Starting development server at http://127.0.0.1:8000/
Quit the server with CTRL-BREAK.
[04/Feb/2019 16:23:02] "POST /admin/posts/post/add/ HTTP/1.1" 302 0
[04/Feb/2019 16:23:02] "GET /admin/posts/post/ HTTP/1.1" 200 4473
[04/Feb/2019 16:23:02] "GET /admin/jsi18n/ HTTP/1.1" 200 3217
[04/Feb/2019 16:23:03] "GET /static/admin/img/icon-yes.svg HTTP/1.1" 304 0
Performing system checks...

System check identified no issues (0 silenced).
February 04, 2019 - 16:29:05
Django version 1.9, using settings 'trydjango.settings'
Starting development server at http://127.0.0.1:8000/
Quit the server with CTRL-BREAK.
[04/Feb/2019 16:29:13] "GET /admin/posts/post/ HTTP/1.1" 200 4331
[04/Feb/2019 16:29:14] "GET /static/admin/css/base.css HTTP/1.1" 304 0
[04/Feb/2019 16:29:14] "GET /static/admin/css/changelists.css HTTP/1.1" 304 0
[04/Feb/2019 16:29:14] "GET /static/admin/js/core.js HTTP/1.1" 304 0
[04/Feb/2019 16:29:14] "GET /static/admin/js/admin/RelatedObjectLookups.js HTTP/1.1" 304 0
[04/Feb/2019 16:29:14] "GET /static/admin/js/vendor/jquery/jquery.js HTTP/1.1" 304 0
[04/Feb/2019 16:29:14] "GET /static/admin/js/jquery.init.js HTTP/1.1" 304 0
[04/Feb/2019 16:29:14] "GET /static/admin/js/actions.js HTTP/1.1" 304 0
[04/Feb/2019 16:29:14] "GET /static/admin/css/fonts.css HTTP/1.1" 304 0
[04/Feb/2019 16:29:14] "GET /static/admin/js/urlify.js HTTP/1.1" 304 0
[04/Feb/2019 16:29:14] "GET /static/admin/js/prepopulate.js HTTP/1.1" 304 0
[04/Feb/2019 16:29:14] "GET /static/admin/js/vendor/xregexp/xregexp.min.js HTTP/1.1" 304 0
[04/Feb/2019 16:29:14] "GET /admin/jsi18n/ HTTP/1.1" 200 3217
[04/Feb/2019 16:29:14] "GET /static/admin/img/tooltag-add.svg HTTP/1.1" 304 0
[04/Feb/2019 16:29:14] "GET /static/admin/fonts/Roboto-Light-webfont.woff HTTP/1.1" 304 0
[04/Feb/2019 16:29:14] "GET /static/admin/fonts/Roboto-Bold-webfont.woff HTTP/1.1" 304 0
[04/Feb/2019 16:29:14] "GET /static/admin/fonts/Roboto-Regular-webfont.woff HTTP/1.1" 304 0
[04/Feb/2019 16:29:17] "GET /admin/posts/ HTTP/1.1" 200 2201
[04/Feb/2019 16:29:17] "GET /static/admin/css/dashboard.css HTTP/1.1" 304 0
[04/Feb/2019 16:29:17] "GET /static/admin/img/icon-addlink.svg HTTP/1.1" 304 0
[04/Feb/2019 16:29:17] "GET /static/admin/img/icon-changelink.svg HTTP/1.1" 304 0
[04/Feb/2019 16:29:19] "GET /admin/ HTTP/1.1" 200 4005
[04/Feb/2019 16:29:21] "GET /admin/posts/post/ HTTP/1.1" 200 4331
[04/Feb/2019 16:29:21] "GET /admin/jsi18n/ HTTP/1.1" 200 3217
[04/Feb/2019 16:29:32] "GET /admin/posts/ HTTP/1.1" 200 2201
[04/Feb/2019 16:29:35] "GET /admin/posts/post/ HTTP/1.1" 200 4331
[04/Feb/2019 16:29:35] "GET /admin/jsi18n/ HTTP/1.1" 200 3217
[04/Feb/2019 16:29:38] "GET /admin/posts/post/1/change/ HTTP/1.1" 200 6052
[04/Feb/2019 16:29:38] "GET /admin/jsi18n/ HTTP/1.1" 200 3217
Performing system checks...

Unhandled exception in thread started by <function wrapper at 0x0000000006EC9C88>
Traceback (most recent call last):
  File "D:\trydjango\lib\site-packages\django\utils\autoreload.py", line 226, in wrapper
    fn(*args, **kwargs)
  File "D:\trydjango\lib\site-packages\django\core\management\commands\runserver.py", line 116, in inner_run
    self.check(display_num_errors=True)
  File "D:\trydjango\lib\site-packages\django\core\management\base.py", line 472, in check
    raise SystemCheckError(msg)
django.core.management.base.SystemCheckError: SystemCheckError: System check identified some issues:

ERRORS:
<class 'posts.admin.PostModelAdmin'>: (admin.E107) The value of 'list_display' must be a list or tuple.

System check identified 1 issue (0 silenced).
Performing system checks...

System check identified no issues (0 silenced).
February 04, 2019 - 16:30:32
Django version 1.9, using settings 'trydjango.settings'
Starting development server at http://127.0.0.1:8000/
Quit the server with CTRL-BREAK.
[04/Feb/2019 16:30:36] "GET /admin/posts/post/ HTTP/1.1" 200 4567
[04/Feb/2019 16:30:36] "GET /admin/jsi18n/ HTTP/1.1" 200 3217
Performing system checks...

System check identified no issues (0 silenced).
February 04, 2019 - 16:31:15
Django version 1.9, using settings 'trydjango.settings'
Starting development server at http://127.0.0.1:8000/
Quit the server with CTRL-BREAK.
[04/Feb/2019 16:31:19] "GET /admin/posts/post/ HTTP/1.1" 200 4567
[04/Feb/2019 16:31:19] "GET /admin/jsi18n/ HTTP/1.1" 200 3217
Performing system checks...

System check identified no issues (0 silenced).
February 04, 2019 - 16:33:57
Django version 1.9, using settings 'trydjango.settings'
Starting development server at http://127.0.0.1:8000/
Quit the server with CTRL-BREAK.
[04/Feb/2019 16:34:00] "GET /admin/posts/post/ HTTP/1.1" 200 4823
[04/Feb/2019 16:34:00] "GET /admin/jsi18n/ HTTP/1.1" 200 3217
[04/Feb/2019 16:34:07] "GET /admin/posts/post/add/ HTTP/1.1" 200 5840
[04/Feb/2019 16:34:07] "GET /static/admin/css/forms.css HTTP/1.1" 304 0
[04/Feb/2019 16:34:07] "GET /static/admin/css/widgets.css HTTP/1.1" 304 0
[04/Feb/2019 16:34:07] "GET /admin/jsi18n/ HTTP/1.1" 200 3217
[04/Feb/2019 16:34:13] "POST /admin/posts/post/add/ HTTP/1.1" 302 0
[04/Feb/2019 16:34:13] "GET /admin/posts/post/2/change/ HTTP/1.1" 200 6209
[04/Feb/2019 16:34:13] "GET /admin/jsi18n/ HTTP/1.1" 200 3217
[04/Feb/2019 16:34:13] "GET /static/admin/img/icon-yes.svg HTTP/1.1" 304 0
[04/Feb/2019 16:34:15] "POST /admin/posts/post/2/change/ HTTP/1.1" 302 0
[04/Feb/2019 16:34:15] "GET /admin/posts/post/ HTTP/1.1" 200 5288
[04/Feb/2019 16:34:15] "GET /admin/jsi18n/ HTTP/1.1" 200 3217
Performing system checks...

System check identified no issues (0 silenced).
February 04, 2019 - 16:34:28
Django version 1.9, using settings 'trydjango.settings'
Starting development server at http://127.0.0.1:8000/
Quit the server with CTRL-BREAK.
[04/Feb/2019 16:34:28] "GET /admin/posts/post/ HTTP/1.1" 200 5616
[04/Feb/2019 16:34:28] "GET /admin/jsi18n/ HTTP/1.1" 200 3217
Performing system checks...

System check identified no issues (0 silenced).
February 04, 2019 - 16:35:29
Django version 1.9, using settings 'trydjango.settings'
Starting development server at http://127.0.0.1:8000/
Quit the server with CTRL-BREAK.
[04/Feb/2019 16:35:31] "GET /admin/posts/post/ HTTP/1.1" 200 6018
[04/Feb/2019 16:35:32] "GET /static/admin/img/search.svg HTTP/1.1" 304 0
[04/Feb/2019 16:35:32] "GET /admin/jsi18n/ HTTP/1.1" 200 3217
[04/Feb/2019 16:35:35] "GET /admin/posts/post/?q=abc HTTP/1.1" 200 5944
[04/Feb/2019 16:35:35] "GET /admin/jsi18n/ HTTP/1.1" 200 3217
Performing system checks...

System check identified no issues (0 silenced).
February 04, 2019 - 16:35:50
Django version 1.9, using settings 'trydjango.settings'
Starting development server at http://127.0.0.1:8000/
Quit the server with CTRL-BREAK.
Internal Server Error: /admin/posts/post/
Traceback (most recent call last):
  File "D:\trydjango\lib\site-packages\django\core\handlers\base.py", line 149, in get_response
    response = self.process_exception_by_middleware(e, request)
  File "D:\trydjango\lib\site-packages\django\core\handlers\base.py", line 147, in get_response
    response = wrapped_callback(request, *callback_args, **callback_kwargs)
  File "D:\trydjango\lib\site-packages\django\contrib\admin\options.py", line 541, in wrapper
    return self.admin_site.admin_view(view)(*args, **kwargs)
  File "D:\trydjango\lib\site-packages\django\utils\decorators.py", line 149, in _wrapped_view
    response = view_func(request, *args, **kwargs)
  File "D:\trydjango\lib\site-packages\django\views\decorators\cache.py", line 57, in _wrapped_view_func
    response = view_func(request, *args, **kwargs)
  File "D:\trydjango\lib\site-packages\django\contrib\admin\sites.py", line 244, in inner
    return view(request, *args, **kwargs)
  File "D:\trydjango\lib\site-packages\django\utils\decorators.py", line 67, in _wrapper
    return bound_func(*args, **kwargs)
  File "D:\trydjango\lib\site-packages\django\utils\decorators.py", line 149, in _wrapped_view
    response = view_func(request, *args, **kwargs)
  File "D:\trydjango\lib\site-packages\django\utils\decorators.py", line 63, in bound_func
    return func.__get__(self, type(self))(*args2, **kwargs2)
  File "D:\trydjango\lib\site-packages\django\contrib\admin\options.py", line 1468, in changelist_view
    self.list_max_show_all, self.list_editable, self)
  File "D:\trydjango\lib\site-packages\django\contrib\admin\views\main.py", line 78, in __init__
    self.queryset = self.get_queryset(request)
  File "D:\trydjango\lib\site-packages\django\contrib\admin\views\main.py", line 356, in get_queryset
    request, qs, self.query)
  File "D:\trydjango\lib\site-packages\django\contrib\admin\options.py", line 900, in get_search_results
    queryset = queryset.filter(reduce(operator.or_, or_queries))
  File "D:\trydjango\lib\site-packages\django\db\models\query.py", line 790, in filter
    return self._filter_or_exclude(False, *args, **kwargs)
  File "D:\trydjango\lib\site-packages\django\db\models\query.py", line 808, in _filter_or_exclude
    clone.query.add_q(Q(*args, **kwargs))
  File "D:\trydjango\lib\site-packages\django\db\models\sql\query.py", line 1243, in add_q
    clause, _ = self._add_q(q_object, self.used_aliases)
  File "D:\trydjango\lib\site-packages\django\db\models\sql\query.py", line 1263, in _add_q
    current_negated, allow_joins, split_subq)
  File "D:\trydjango\lib\site-packages\django\db\models\sql\query.py", line 1269, in _add_q
    allow_joins=allow_joins, split_subq=split_subq,
  File "D:\trydjango\lib\site-packages\django\db\models\sql\query.py", line 1149, in build_filter
    lookups, parts, reffed_expression = self.solve_lookup_type(arg)
  File "D:\trydjango\lib\site-packages\django\db\models\sql\query.py", line 1035, in solve_lookup_type
    _, field, _, lookup_parts = self.names_to_path(lookup_splitted, self.get_meta())
  File "D:\trydjango\lib\site-packages\django\db\models\sql\query.py", line 1330, in names_to_path
    "Choices are: %s" % (name, ", ".join(available)))
FieldError: Cannot resolve keyword '*' into field. Choices are: content, id, timestamp, title, updated
[04/Feb/2019 16:35:51] "GET /admin/posts/post/?q=abc HTTP/1.1" 500 153836
Performing system checks...

System check identified no issues (0 silenced).
February 04, 2019 - 16:36:18
Django version 1.9, using settings 'trydjango.settings'
Starting development server at http://127.0.0.1:8000/
Quit the server with CTRL-BREAK.
Performing system checks...

Unhandled exception in thread started by <function wrapper at 0x0000000007019C18>
Traceback (most recent call last):
  File "D:\trydjango\lib\site-packages\django\utils\autoreload.py", line 226, in wrapper
    fn(*args, **kwargs)
  File "D:\trydjango\lib\site-packages\django\core\management\commands\runserver.py", line 116, in inner_run
    self.check(display_num_errors=True)
  File "D:\trydjango\lib\site-packages\django\core\management\base.py", line 426, in check
    include_deployment_checks=include_deployment_checks,
  File "D:\trydjango\lib\site-packages\django\core\checks\registry.py", line 75, in run_checks
    new_errors = check(app_configs=app_configs)
  File "D:\trydjango\lib\site-packages\django\core\checks\urls.py", line 10, in check_url_config
    return check_resolver(resolver)
  File "D:\trydjango\lib\site-packages\django\core\checks\urls.py", line 19, in check_resolver
    for pattern in resolver.url_patterns:
  File "D:\trydjango\lib\site-packages\django\utils\functional.py", line 33, in __get__
    res = instance.__dict__[self.name] = self.func(instance)
  File "D:\trydjango\lib\site-packages\django\core\urlresolvers.py", line 417, in url_patterns
    patterns = getattr(self.urlconf_module, "urlpatterns", self.urlconf_module)
  File "D:\trydjango\lib\site-packages\django\utils\functional.py", line 33, in __get__
    res = instance.__dict__[self.name] = self.func(instance)
  File "D:\trydjango\lib\site-packages\django\core\urlresolvers.py", line 410, in urlconf_module
    return import_module(self.urlconf_name)
  File "c:\programdata\anaconda2\Lib\importlib\__init__.py", line 37, in import_module
    __import__(name)
  File "D:\trydjango\src\trydjango\urls.py", line 19, in <module>
    from posts.views import post_home
ImportError: cannot import name post_home
Performing system checks...

Unhandled exception in thread started by <function wrapper at 0x000000000655CC18>
Traceback (most recent call last):
  File "D:\trydjango\lib\site-packages\django\utils\autoreload.py", line 226, in wrapper
    fn(*args, **kwargs)
  File "D:\trydjango\lib\site-packages\django\core\management\commands\runserver.py", line 116, in inner_run
    self.check(display_num_errors=True)
  File "D:\trydjango\lib\site-packages\django\core\management\base.py", line 426, in check
    include_deployment_checks=include_deployment_checks,
  File "D:\trydjango\lib\site-packages\django\core\checks\registry.py", line 75, in run_checks
    new_errors = check(app_configs=app_configs)
  File "D:\trydjango\lib\site-packages\django\core\checks\urls.py", line 10, in check_url_config
    return check_resolver(resolver)
  File "D:\trydjango\lib\site-packages\django\core\checks\urls.py", line 19, in check_resolver
    for pattern in resolver.url_patterns:
  File "D:\trydjango\lib\site-packages\django\utils\functional.py", line 33, in __get__
    res = instance.__dict__[self.name] = self.func(instance)
  File "D:\trydjango\lib\site-packages\django\core\urlresolvers.py", line 417, in url_patterns
    patterns = getattr(self.urlconf_module, "urlpatterns", self.urlconf_module)
  File "D:\trydjango\lib\site-packages\django\utils\functional.py", line 33, in __get__
    res = instance.__dict__[self.name] = self.func(instance)
  File "D:\trydjango\lib\site-packages\django\core\urlresolvers.py", line 410, in urlconf_module
    return import_module(self.urlconf_name)
  File "c:\programdata\anaconda2\Lib\importlib\__init__.py", line 37, in import_module
    __import__(name)
  File "D:\trydjango\src\trydjango\urls.py", line 23, in <module>
    url(r'^post/', views.post_home),
NameError: name 'views' is not defined
Performing system checks...

System check identified no issues (0 silenced).
February 04, 2019 - 16:59:36
Django version 1.9, using settings 'trydjango.settings'
Starting development server at http://127.0.0.1:8000/
Quit the server with CTRL-BREAK.
Internal Server Error: /post/
Traceback (most recent call last):
  File "D:\trydjango\lib\site-packages\django\core\handlers\base.py", line 149, in get_response
    response = self.process_exception_by_middleware(e, request)
  File "D:\trydjango\lib\site-packages\django\core\handlers\base.py", line 147, in get_response
    response = wrapped_callback(request, *callback_args, **callback_kwargs)
TypeError: posts_home() takes no arguments (1 given)
[04/Feb/2019 16:59:49] "GET /post/ HTTP/1.1" 500 60630
Performing system checks...

System check identified no issues (0 silenced).
February 04, 2019 - 17:00:16
Django version 1.9, using settings 'trydjango.settings'
Starting development server at http://127.0.0.1:8000/
Quit the server with CTRL-BREAK.
[04/Feb/2019 17:00:18] "GET /post/ HTTP/1.1" 200 25
Performing system checks...

Unhandled exception in thread started by <function wrapper at 0x000000000696AC18>
Traceback (most recent call last):
  File "D:\trydjango\lib\site-packages\django\utils\autoreload.py", line 226, in wrapper
    fn(*args, **kwargs)
  File "D:\trydjango\lib\site-packages\django\core\management\commands\runserver.py", line 116, in inner_run
    self.check(display_num_errors=True)
  File "D:\trydjango\lib\site-packages\django\core\management\base.py", line 426, in check
    include_deployment_checks=include_deployment_checks,
  File "D:\trydjango\lib\site-packages\django\core\checks\registry.py", line 75, in run_checks
    new_errors = check(app_configs=app_configs)
  File "D:\trydjango\lib\site-packages\django\core\checks\urls.py", line 10, in check_url_config
    return check_resolver(resolver)
  File "D:\trydjango\lib\site-packages\django\core\checks\urls.py", line 19, in check_resolver
    for pattern in resolver.url_patterns:
  File "D:\trydjango\lib\site-packages\django\utils\functional.py", line 33, in __get__
    res = instance.__dict__[self.name] = self.func(instance)
  File "D:\trydjango\lib\site-packages\django\core\urlresolvers.py", line 417, in url_patterns
    patterns = getattr(self.urlconf_module, "urlpatterns", self.urlconf_module)
  File "D:\trydjango\lib\site-packages\django\utils\functional.py", line 33, in __get__
    res = instance.__dict__[self.name] = self.func(instance)
  File "D:\trydjango\lib\site-packages\django\core\urlresolvers.py", line 410, in urlconf_module
    return import_module(self.urlconf_name)
  File "c:\programdata\anaconda2\Lib\importlib\__init__.py", line 37, in import_module
    __import__(name)
  File "D:\trydjango\src\trydjango\urls.py", line 19, in <module>
    from posts.views import posts_home
ImportError: cannot import name posts_home
Performing system checks...

D:\trydjango\src\trydjango\urls.py:24: RemovedInDjango110Warning: Support for string view arguments to url() is deprecated and will be removed in Django 1.10 (got posts.views.post_home). Pass the callable instead.
  url(r'^post/$', "posts.views.post_home"),

System check identified no issues (0 silenced).
February 04, 2019 - 17:10:06
Django version 1.9, using settings 'trydjango.settings'
Starting development server at http://127.0.0.1:8000/
Quit the server with CTRL-BREAK.
[04/Feb/2019 17:10:09] "GET /post/ HTTP/1.1" 200 25
[04/Feb/2019 17:10:12] "GET /post/ HTTP/1.1" 200 25
[04/Feb/2019 17:10:14] "GET /post/ HTTP/1.1" 200 25
[04/Feb/2019 17:10:14] "GET /post/ HTTP/1.1" 200 25
[04/Feb/2019 17:10:14] "GET /post/ HTTP/1.1" 200 25
Performing system checks...

D:\trydjango\src\trydjango\urls.py:24: RemovedInDjango110Warning: Support for string view arguments to url() is deprecated and will be removed in Django 1.10 (got posts.views.post_home). Pass the callable instead.
  url(r'^post/$', "posts.views.post_home"),

System check identified no issues (0 silenced).
February 04, 2019 - 17:10:31
Django version 1.9, using settings 'trydjango.settings'
Starting development server at http://127.0.0.1:8000/
Quit the server with CTRL-BREAK.
[04/Feb/2019 17:10:31] "GET /post/ HTTP/1.1" 200 36
Performing system checks...

D:\trydjango\src\posts\urls.py:6: RemovedInDjango110Warning: Support for string view arguments to url() is deprecated and will be removed in Django 1.10 (got posts.views.post_home). Pass the callable instead.
  url(r'^$', "posts.views.post_home"),

System check identified some issues:

WARNINGS:
?: (urls.W001) Your URL pattern '^post/$' uses include with a regex ending with a '$'. Remove the dollar from the regex to avoid problems including URLs.

System check identified 1 issue (0 silenced).
February 04, 2019 - 17:15:10
Django version 1.9, using settings 'trydjango.settings'
Starting development server at http://127.0.0.1:8000/
Quit the server with CTRL-BREAK.
[04/Feb/2019 17:15:12] "GET /post/ HTTP/1.1" 200 36
Performing system checks...

D:\trydjango\src\posts\urls.py:6: RemovedInDjango110Warning: Support for string view arguments to url() is deprecated and will be removed in Django 1.10 (got posts.views.post_home). Pass the callable instead.
  url(r'^$', "posts.views.post_home"),

System check identified no issues (0 silenced).
February 04, 2019 - 17:15:28
Django version 1.9, using settings 'trydjango.settings'
Starting development server at http://127.0.0.1:8000/
Quit the server with CTRL-BREAK.
[04/Feb/2019 17:15:30] "GET /post/ HTTP/1.1" 200 36
Performing system checks...

D:\trydjango\src\posts\urls.py:6: RemovedInDjango110Warning: Support for string view arguments to url() is deprecated and will be removed in Django 1.10 (got posts.views.post_home). Pass the callable instead.
  url(r'^$', "posts.views.post_home"),

System check identified no issues (0 silenced).
February 04, 2019 - 17:17:00
Django version 1.9, using settings 'trydjango.settings'
Starting development server at http://127.0.0.1:8000/
Quit the server with CTRL-BREAK.
[04/Feb/2019 17:17:01] "GET /post/ HTTP/1.1" 200 36

(trydjango) D:\trydjango\src>
(trydjango) D:\trydjango\src>
(trydjango) D:\trydjango\src>
(trydjango) D:\trydjango\src>
(trydjango) D:\trydjango\src>
(trydjango) D:\trydjango\src>
(trydjango) D:\trydjango\src>
(trydjango) D:\trydjango\src>
(trydjango) D:\trydjango\src>
(trydjango) D:\trydjango\src>python manage.py runserver
Performing system checks...

D:\trydjango\src\posts\urls.py:6: RemovedInDjango110Warning: Support for string view arguments to url() is deprecated and will be removed in Django 1.10 (got posts.views.post_home). Pass the callable instead.
  url(r'^$', "posts.views.post_home"),

System check identified no issues (0 silenced).
February 04, 2019 - 17:17:15
Django version 1.9, using settings 'trydjango.settings'
Starting development server at http://127.0.0.1:8000/
Quit the server with CTRL-BREAK.
Performing system checks...

D:\trydjango\src\posts\urls.py:6: RemovedInDjango110Warning: Support for string view arguments to url() is deprecated and will be removed in Django 1.10 (got posts.views.post_home). Pass the callable instead.
  url(r'^abc$', "posts.views.post_home"),

System check identified no issues (0 silenced).
February 04, 2019 - 17:17:44
Django version 1.9, using settings 'trydjango.settings'
Starting development server at http://127.0.0.1:8000/
Quit the server with CTRL-BREAK.
[04/Feb/2019 17:17:49] "GET /post/abc HTTP/1.1" 200 36
Performing system checks...

D:\trydjango\src\posts\urls.py:6: RemovedInDjango110Warning: Support for string view arguments to url() is deprecated and will be removed in Django 1.10 (got posts.views.post_home). Pass the callable instead.
  url(r'^abc$', "posts.views.post_home"),

System check identified no issues (0 silenced).
February 04, 2019 - 17:19:53
Django version 1.9, using settings 'trydjango.settings'
Starting development server at http://127.0.0.1:8000/
Quit the server with CTRL-BREAK.
Performing system checks...

D:\trydjango\src\posts\urls.py:6: RemovedInDjango110Warning: Support for string view arguments to url() is deprecated and will be removed in Django 1.10 (got posts.views.post_home). Pass the callable instead.
  url(r'^abc$', "posts.views.post_home"),

System check identified no issues (0 silenced).
February 04, 2019 - 17:20:31
Django version 1.9, using settings 'trydjango.settings'
Starting development server at http://127.0.0.1:8000/
Quit the server with CTRL-BREAK.
Not Found: /post/abc
[04/Feb/2019 17:20:45] "GET /post/abc HTTP/1.1" 404 2037
Not Found: /posTS/
[04/Feb/2019 17:20:53] "GET /posTS/ HTTP/1.1" 404 2031
Not Found: /posts/
[04/Feb/2019 17:21:00] "GET /posts/ HTTP/1.1" 404 2083
[04/Feb/2019 17:21:07] "GET /posts/abc HTTP/1.1" 200 36
Performing system checks...

D:\trydjango\src\posts\urls.py:6: RemovedInDjango110Warning: Support for string view arguments to url() is deprecated and will be removed in Django 1.10 (got posts.views.post_home). Pass the callable instead.
  url(r'^abc$', "posts.views.post_home"),

System check identified no issues (0 silenced).
February 04, 2019 - 17:21:18
Django version 1.9, using settings 'trydjango.settings'
Starting development server at http://127.0.0.1:8000/
Quit the server with CTRL-BREAK.
Performing system checks...

D:\trydjango\src\posts\urls.py:6: RemovedInDjango110Warning: Support for string view arguments to url() is deprecated and will be removed in Django 1.10 (got posts.views.post_home). Pass the callable instead.
  url(r'^abc/$', "posts.views.post_home"),

System check identified no issues (0 silenced).
February 04, 2019 - 17:21:29
Django version 1.9, using settings 'trydjango.settings'
Starting development server at http://127.0.0.1:8000/
Quit the server with CTRL-BREAK.
Performing system checks...

D:\trydjango\src\posts\urls.py:7: RemovedInDjango110Warning: Support for string view arguments to url() is deprecated and will be removed in Django 1.10 (got posts.views.post_home). Pass the callable instead.
  url(r'^abc/$', "posts.views.post_home"),

System check identified no issues (0 silenced).
February 04, 2019 - 17:25:02
Django version 1.9, using settings 'trydjango.settings'
Starting development server at http://127.0.0.1:8000/
Quit the server with CTRL-BREAK.
Performing system checks...

D:\trydjango\src\posts\urls.py:7: RemovedInDjango110Warning: Support for string view arguments to url() is deprecated and will be removed in Django 1.10 (got posts.views.post_home). Pass the callable instead.
  url(r'^$', "posts.views.post_home"),

System check identified no issues (0 silenced).
February 04, 2019 - 17:25:18
Django version 1.9, using settings 'trydjango.settings'
Starting development server at http://127.0.0.1:8000/
Quit the server with CTRL-BREAK.
Performing system checks...

D:\trydjango\src\posts\urls.py:7: RemovedInDjango110Warning: Support for string view arguments to url() is deprecated and will be removed in Django 1.10 (got posts.views.post_home). Pass the callable instead.
  url(r'^$', "posts.views.post_home"),

System check identified no issues (0 silenced).
February 04, 2019 - 17:30:45
Django version 1.9, using settings 'trydjango.settings'
Starting development server at http://127.0.0.1:8000/
Quit the server with CTRL-BREAK.
Performing system checks...

D:\trydjango\src\posts\urls.py:7: RemovedInDjango110Warning: Support for string view arguments to url() is deprecated and will be removed in Django 1.10 (got posts.views.post_list). Pass the callable instead.
  url(r'^$', "posts.views.post_list"),

D:\trydjango\src\posts\urls.py:8: RemovedInDjango110Warning: Support for string view arguments to url() is deprecated and will be removed in Django 1.10 (got posts.views.post_create). Pass the callable instead.
  url(r'^create/$', "posts.views.post_create"),

D:\trydjango\src\posts\urls.py:9: RemovedInDjango110Warning: Support for string view arguments to url() is deprecated and will be removed in Django 1.10 (got posts.views.post_delete). Pass the callable instead.
  url(r'^delete/$', "posts.views.post_delete"),

D:\trydjango\src\posts\urls.py:10: RemovedInDjango110Warning: Support for string view arguments to url() is deprecated and will be removed in Django 1.10 (got posts.views.post_update). Pass the callable instead.
  url(r'^update/$', "posts.views.post_update"),

D:\trydjango\src\posts\urls.py:11: RemovedInDjango110Warning: Support for string view arguments to url() is deprecated and will be removed in Django 1.10 (got posts.views.post_detail). Pass the callable instead.
  url(r'^detail/$', "posts.views.post_detail"),

System check identified no issues (0 silenced).
February 04, 2019 - 17:32:31
Django version 1.9, using settings 'trydjango.settings'
Starting development server at http://127.0.0.1:8000/
Quit the server with CTRL-BREAK.
[04/Feb/2019 17:32:42] "GET /posts/ HTTP/1.1" 200 56
Not Found: /posts/create
[04/Feb/2019 17:32:48] "GET /posts/create HTTP/1.1" 301 0
[04/Feb/2019 17:32:48] "GET /posts/create/ HTTP/1.1" 200 48
[04/Feb/2019 17:32:56] "GET /posts/delete/ HTTP/1.1" 200 21
[04/Feb/2019 17:33:05] "GET /posts/update/ HTTP/1.1" 200 68
[04/Feb/2019 17:33:22] "GET /posts/detail/ HTTP/1.1" 200 46
Performing system checks...

D:\trydjango\src\posts\urls.py:7: RemovedInDjango110Warning: Support for string view arguments to url() is deprecated and will be removed in Django 1.10 (got posts.views.post_list). Pass the callable instead.
  url(r'^$', "posts.views.post_list"),

D:\trydjango\src\posts\urls.py:8: RemovedInDjango110Warning: Support for string view arguments to url() is deprecated and will be removed in Django 1.10 (got posts.views.post_create). Pass the callable instead.
  url(r'^create/$', "posts.views.post_create"),

D:\trydjango\src\posts\urls.py:9: RemovedInDjango110Warning: Support for string view arguments to url() is deprecated and will be removed in Django 1.10 (got posts.views.post_delete). Pass the callable instead.
  url(r'^delete/$', "posts.views.post_delete"),

D:\trydjango\src\posts\urls.py:10: RemovedInDjango110Warning: Support for string view arguments to url() is deprecated and will be removed in Django 1.10 (got posts.views.post_update). Pass the callable instead.
  url(r'^update/$', "posts.views.post_update"),

D:\trydjango\src\posts\urls.py:11: RemovedInDjango110Warning: Support for string view arguments to url() is deprecated and will be removed in Django 1.10 (got posts.views.post_detail). Pass the callable instead.
  url(r'^detail/$', "posts.views.post_detail"),

System check identified no issues (0 silenced).
February 04, 2019 - 17:59:11
Django version 1.9, using settings 'trydjango.settings'
Starting development server at http://127.0.0.1:8000/
Quit the server with CTRL-BREAK.
Performing system checks...

D:\trydjango\src\posts\urls.py:7: RemovedInDjango110Warning: Support for string view arguments to url() is deprecated and will be removed in Django 1.10 (got posts.views.post_list). Pass the callable instead.
  url(r'^$', "posts.views.post_list"),

D:\trydjango\src\posts\urls.py:8: RemovedInDjango110Warning: Support for string view arguments to url() is deprecated and will be removed in Django 1.10 (got posts.views.post_create). Pass the callable instead.
  url(r'^create/$', "posts.views.post_create"),

D:\trydjango\src\posts\urls.py:9: RemovedInDjango110Warning: Support for string view arguments to url() is deprecated and will be removed in Django 1.10 (got posts.views.post_delete). Pass the callable instead.
  url(r'^delete/$', "posts.views.post_delete"),

D:\trydjango\src\posts\urls.py:10: RemovedInDjango110Warning: Support for string view arguments to url() is deprecated and will be removed in Django 1.10 (got posts.views.post_update). Pass the callable instead.
  url(r'^update/$', "posts.views.post_update"),

D:\trydjango\src\posts\urls.py:11: RemovedInDjango110Warning: Support for string view arguments to url() is deprecated and will be removed in Django 1.10 (got posts.views.post_detail). Pass the callable instead.
  url(r'^detail/$', "posts.views.post_detail"),

System check identified no issues (0 silenced).
February 04, 2019 - 18:00:30
Django version 1.9, using settings 'trydjango.settings'
Starting development server at http://127.0.0.1:8000/
Quit the server with CTRL-BREAK.
Internal Server Error: /posts/
Traceback (most recent call last):
  File "D:\trydjango\lib\site-packages\django\core\handlers\base.py", line 149, in get_response
    response = self.process_exception_by_middleware(e, request)
  File "D:\trydjango\lib\site-packages\django\core\handlers\base.py", line 147, in get_response
    response = wrapped_callback(request, *callback_args, **callback_kwargs)
  File "D:\trydjango\src\posts\views.py", line 11, in post_list
    return render(self,'index.html',{})
  File "D:\trydjango\lib\site-packages\django\shortcuts.py", line 67, in render
    template_name, context, request=request, using=using)
  File "D:\trydjango\lib\site-packages\django\template\loader.py", line 96, in render_to_string
    template = get_template(template_name, using=using)
  File "D:\trydjango\lib\site-packages\django\template\loader.py", line 26, in get_template
    engines = _engine_list(using)
  File "D:\trydjango\lib\site-packages\django\template\loader.py", line 143, in _engine_list
    return engines.all() if using is None else [engines[using]]
  File "D:\trydjango\lib\site-packages\django\template\utils.py", line 110, in all
    return [self[alias] for alias in self]
  File "D:\trydjango\lib\site-packages\django\template\utils.py", line 107, in __iter__
    return iter(self.templates)
  File "D:\trydjango\lib\site-packages\django\utils\functional.py", line 33, in __get__
    res = instance.__dict__[self.name] = self.func(instance)
  File "D:\trydjango\lib\site-packages\django\template\utils.py", line 64, in templates
    "your TEMPLATES setting.".format(invalid_backend))
ImproperlyConfigured: Invalid BACKEND for a template engine: D:\trydjango\src\templates. Check your TEMPLATES setting.
[04/Feb/2019 18:00:42] "GET /posts/ HTTP/1.1" 500 96849
Internal Server Error: /posts/
Traceback (most recent call last):
  File "D:\trydjango\lib\site-packages\django\core\handlers\base.py", line 149, in get_response
    response = self.process_exception_by_middleware(e, request)
  File "D:\trydjango\lib\site-packages\django\core\handlers\base.py", line 147, in get_response
    response = wrapped_callback(request, *callback_args, **callback_kwargs)
  File "D:\trydjango\src\posts\views.py", line 11, in post_list
    return render(self,'index.html',{})
  File "D:\trydjango\lib\site-packages\django\shortcuts.py", line 67, in render
    template_name, context, request=request, using=using)
  File "D:\trydjango\lib\site-packages\django\template\loader.py", line 96, in render_to_string
    template = get_template(template_name, using=using)
  File "D:\trydjango\lib\site-packages\django\template\loader.py", line 26, in get_template
    engines = _engine_list(using)
  File "D:\trydjango\lib\site-packages\django\template\loader.py", line 143, in _engine_list
    return engines.all() if using is None else [engines[using]]
  File "D:\trydjango\lib\site-packages\django\template\utils.py", line 110, in all
    return [self[alias] for alias in self]
  File "D:\trydjango\lib\site-packages\django\template\utils.py", line 107, in __iter__
    return iter(self.templates)
  File "D:\trydjango\lib\site-packages\django\utils\functional.py", line 33, in __get__
    res = instance.__dict__[self.name] = self.func(instance)
  File "D:\trydjango\lib\site-packages\django\template\utils.py", line 64, in templates
    "your TEMPLATES setting.".format(invalid_backend))
ImproperlyConfigured: Invalid BACKEND for a template engine: D:\trydjango\src\templates. Check your TEMPLATES setting.
[04/Feb/2019 18:01:50] "GET /posts/ HTTP/1.1" 500 96984
Internal Server Error: /posts/
Traceback (most recent call last):
  File "D:\trydjango\lib\site-packages\django\core\handlers\base.py", line 149, in get_response
    response = self.process_exception_by_middleware(e, request)
  File "D:\trydjango\lib\site-packages\django\core\handlers\base.py", line 147, in get_response
    response = wrapped_callback(request, *callback_args, **callback_kwargs)
  File "D:\trydjango\src\posts\views.py", line 11, in post_list
    return render(self,'index.html',{})
  File "D:\trydjango\lib\site-packages\django\shortcuts.py", line 67, in render
    template_name, context, request=request, using=using)
  File "D:\trydjango\lib\site-packages\django\template\loader.py", line 96, in render_to_string
    template = get_template(template_name, using=using)
  File "D:\trydjango\lib\site-packages\django\template\loader.py", line 26, in get_template
    engines = _engine_list(using)
  File "D:\trydjango\lib\site-packages\django\template\loader.py", line 143, in _engine_list
    return engines.all() if using is None else [engines[using]]
  File "D:\trydjango\lib\site-packages\django\template\utils.py", line 110, in all
    return [self[alias] for alias in self]
  File "D:\trydjango\lib\site-packages\django\template\utils.py", line 107, in __iter__
    return iter(self.templates)
  File "D:\trydjango\lib\site-packages\django\utils\functional.py", line 33, in __get__
    res = instance.__dict__[self.name] = self.func(instance)
  File "D:\trydjango\lib\site-packages\django\template\utils.py", line 64, in templates
    "your TEMPLATES setting.".format(invalid_backend))
ImproperlyConfigured: Invalid BACKEND for a template engine: D:\trydjango\src\templates. Check your TEMPLATES setting.
[04/Feb/2019 18:01:51] "GET /posts/ HTTP/1.1" 500 96984
Internal Server Error: /posts/
Traceback (most recent call last):
  File "D:\trydjango\lib\site-packages\django\core\handlers\base.py", line 149, in get_response
    response = self.process_exception_by_middleware(e, request)
  File "D:\trydjango\lib\site-packages\django\core\handlers\base.py", line 147, in get_response
    response = wrapped_callback(request, *callback_args, **callback_kwargs)
  File "D:\trydjango\src\posts\views.py", line 11, in post_list
    return render(self,'index.html',{})
  File "D:\trydjango\lib\site-packages\django\shortcuts.py", line 67, in render
    template_name, context, request=request, using=using)
  File "D:\trydjango\lib\site-packages\django\template\loader.py", line 96, in render_to_string
    template = get_template(template_name, using=using)
  File "D:\trydjango\lib\site-packages\django\template\loader.py", line 26, in get_template
    engines = _engine_list(using)
  File "D:\trydjango\lib\site-packages\django\template\loader.py", line 143, in _engine_list
    return engines.all() if using is None else [engines[using]]
  File "D:\trydjango\lib\site-packages\django\template\utils.py", line 110, in all
    return [self[alias] for alias in self]
  File "D:\trydjango\lib\site-packages\django\template\utils.py", line 107, in __iter__
    return iter(self.templates)
  File "D:\trydjango\lib\site-packages\django\utils\functional.py", line 33, in __get__
    res = instance.__dict__[self.name] = self.func(instance)
  File "D:\trydjango\lib\site-packages\django\template\utils.py", line 64, in templates
    "your TEMPLATES setting.".format(invalid_backend))
ImproperlyConfigured: Invalid BACKEND for a template engine: D:\trydjango\src\templates. Check your TEMPLATES setting.
[04/Feb/2019 18:01:51] "GET /posts/ HTTP/1.1" 500 96984
Internal Server Error: /posts/
Traceback (most recent call last):
  File "D:\trydjango\lib\site-packages\django\core\handlers\base.py", line 149, in get_response
    response = self.process_exception_by_middleware(e, request)
  File "D:\trydjango\lib\site-packages\django\core\handlers\base.py", line 147, in get_response
    response = wrapped_callback(request, *callback_args, **callback_kwargs)
  File "D:\trydjango\src\posts\views.py", line 11, in post_list
    return render(self,'index.html',{})
  File "D:\trydjango\lib\site-packages\django\shortcuts.py", line 67, in render
    template_name, context, request=request, using=using)
  File "D:\trydjango\lib\site-packages\django\template\loader.py", line 96, in render_to_string
    template = get_template(template_name, using=using)
  File "D:\trydjango\lib\site-packages\django\template\loader.py", line 26, in get_template
    engines = _engine_list(using)
  File "D:\trydjango\lib\site-packages\django\template\loader.py", line 143, in _engine_list
    return engines.all() if using is None else [engines[using]]
  File "D:\trydjango\lib\site-packages\django\template\utils.py", line 110, in all
    return [self[alias] for alias in self]
  File "D:\trydjango\lib\site-packages\django\template\utils.py", line 107, in __iter__
    return iter(self.templates)
  File "D:\trydjango\lib\site-packages\django\utils\functional.py", line 33, in __get__
    res = instance.__dict__[self.name] = self.func(instance)
  File "D:\trydjango\lib\site-packages\django\template\utils.py", line 64, in templates
    "your TEMPLATES setting.".format(invalid_backend))
ImproperlyConfigured: Invalid BACKEND for a template engine: D:\trydjango\src\templates. Check your TEMPLATES setting.
[04/Feb/2019 18:01:52] "GET /posts/ HTTP/1.1" 500 96984
Performing system checks...

D:\trydjango\src\posts\urls.py:7: RemovedInDjango110Warning: Support for string view arguments to url() is deprecated and will be removed in Django 1.10 (got posts.views.post_list). Pass the callable instead.
  url(r'^$', "posts.views.post_list"),

D:\trydjango\src\posts\urls.py:8: RemovedInDjango110Warning: Support for string view arguments to url() is deprecated and will be removed in Django 1.10 (got posts.views.post_create). Pass the callable instead.
  url(r'^create/$', "posts.views.post_create"),

D:\trydjango\src\posts\urls.py:9: RemovedInDjango110Warning: Support for string view arguments to url() is deprecated and will be removed in Django 1.10 (got posts.views.post_delete). Pass the callable instead.
  url(r'^delete/$', "posts.views.post_delete"),

D:\trydjango\src\posts\urls.py:10: RemovedInDjango110Warning: Support for string view arguments to url() is deprecated and will be removed in Django 1.10 (got posts.views.post_update). Pass the callable instead.
  url(r'^update/$', "posts.views.post_update"),

D:\trydjango\src\posts\urls.py:11: RemovedInDjango110Warning: Support for string view arguments to url() is deprecated and will be removed in Django 1.10 (got posts.views.post_detail). Pass the callable instead.
  url(r'^detail/$', "posts.views.post_detail"),

System check identified no issues (0 silenced).
February 04, 2019 - 18:03:04
Django version 1.9, using settings 'trydjango.settings'
Starting development server at http://127.0.0.1:8000/
Quit the server with CTRL-BREAK.
Internal Server Error: /posts/
Traceback (most recent call last):
  File "D:\trydjango\lib\site-packages\django\core\handlers\base.py", line 149, in get_response
    response = self.process_exception_by_middleware(e, request)
  File "D:\trydjango\lib\site-packages\django\core\handlers\base.py", line 147, in get_response
    response = wrapped_callback(request, *callback_args, **callback_kwargs)
  File "D:\trydjango\src\posts\views.py", line 11, in post_list
    return render(self,'index.html',{})
  File "D:\trydjango\lib\site-packages\django\shortcuts.py", line 67, in render
    template_name, context, request=request, using=using)
  File "D:\trydjango\lib\site-packages\django\template\loader.py", line 96, in render_to_string
    template = get_template(template_name, using=using)
  File "D:\trydjango\lib\site-packages\django\template\loader.py", line 43, in get_template
    raise TemplateDoesNotExist(template_name, chain=chain)
TemplateDoesNotExist: index.html
[04/Feb/2019 18:03:05] "GET /posts/ HTTP/1.1" 500 80130
Performing system checks...

D:\trydjango\src\posts\urls.py:7: RemovedInDjango110Warning: Support for string view arguments to url() is deprecated and will be removed in Django 1.10 (got posts.views.post_list). Pass the callable instead.
  url(r'^$', "posts.views.post_list"),

D:\trydjango\src\posts\urls.py:8: RemovedInDjango110Warning: Support for string view arguments to url() is deprecated and will be removed in Django 1.10 (got posts.views.post_create). Pass the callable instead.
  url(r'^create/$', "posts.views.post_create"),

D:\trydjango\src\posts\urls.py:9: RemovedInDjango110Warning: Support for string view arguments to url() is deprecated and will be removed in Django 1.10 (got posts.views.post_delete). Pass the callable instead.
  url(r'^delete/$', "posts.views.post_delete"),

D:\trydjango\src\posts\urls.py:10: RemovedInDjango110Warning: Support for string view arguments to url() is deprecated and will be removed in Django 1.10 (got posts.views.post_update). Pass the callable instead.
  url(r'^update/$', "posts.views.post_update"),

D:\trydjango\src\posts\urls.py:11: RemovedInDjango110Warning: Support for string view arguments to url() is deprecated and will be removed in Django 1.10 (got posts.views.post_detail). Pass the callable instead.
  url(r'^detail/$', "posts.views.post_detail"),

System check identified no issues (0 silenced).
February 04, 2019 - 18:03:25
Django version 1.9, using settings 'trydjango.settings'
Starting development server at http://127.0.0.1:8000/
Quit the server with CTRL-BREAK.
[04/Feb/2019 18:03:27] "GET /posts/ HTTP/1.1" 200 101
Performing system checks...

System check identified no issues (0 silenced).
February 04, 2019 - 18:05:38
Django version 1.9, using settings 'trydjango.settings'
Starting development server at http://127.0.0.1:8000/
Quit the server with CTRL-BREAK.
[04/Feb/2019 18:05:43] "GET /posts/ HTTP/1.1" 200 101
Performing system checks...

System check identified no issues (0 silenced).
February 05, 2019 - 12:07:51
Django version 1.9, using settings 'trydjango.settings'
Starting development server at http://127.0.0.1:8000/
Quit the server with CTRL-BREAK.
[05/Feb/2019 12:09:44] "GET /posts/ HTTP/1.1" 200 102
Performing system checks...

System check identified no issues (0 silenced).
February 05, 2019 - 12:10:07
Django version 1.9, using settings 'trydjango.settings'
Starting development server at http://127.0.0.1:8000/
Quit the server with CTRL-BREAK.
Internal Server Error: /posts/
Traceback (most recent call last):
  File "D:\trydjango\lib\site-packages\django\core\handlers\base.py", line 149, in get_response
    response = self.process_exception_by_middleware(e, request)
  File "D:\trydjango\lib\site-packages\django\core\handlers\base.py", line 147, in get_response
    response = wrapped_callback(request, *callback_args, **callback_kwargs)
  File "D:\trydjango\src\posts\views.py", line 15, in post_list
    "comment":"Hello"})
TypeError: render() got an unexpected keyword argument 'data'
[05/Feb/2019 12:10:09] "GET /posts/ HTTP/1.1" 500 64334
Performing system checks...

System check identified no issues (0 silenced).
February 05, 2019 - 12:11:10
Django version 1.9, using settings 'trydjango.settings'
Starting development server at http://127.0.0.1:8000/
Quit the server with CTRL-BREAK.
[05/Feb/2019 12:11:12] "GET /posts/ HTTP/1.1" 200 108
[05/Feb/2019 12:11:51] "GET /posts/ HTTP/1.1" 200 115
[05/Feb/2019 12:12:14] "GET /posts/ HTTP/1.1" 200 128
Performing system checks...

System check identified no issues (0 silenced).
February 05, 2019 - 12:13:29
Django version 1.9, using settings 'trydjango.settings'
Starting development server at http://127.0.0.1:8000/
Quit the server with CTRL-BREAK.
[05/Feb/2019 12:13:32] "GET /posts/ HTTP/1.1" 200 130
[05/Feb/2019 12:13:47] "GET /admin/ HTTP/1.1" 200 4562
[05/Feb/2019 12:13:47] "GET /static/admin/css/base.css HTTP/1.1" 304 0
[05/Feb/2019 12:13:47] "GET /static/admin/css/dashboard.css HTTP/1.1" 304 0
[05/Feb/2019 12:13:47] "GET /static/admin/css/fonts.css HTTP/1.1" 304 0
[05/Feb/2019 12:13:47] "GET /static/admin/fonts/Roboto-Light-webfont.woff HTTP/1.1" 304 0
[05/Feb/2019 12:13:47] "GET /static/admin/fonts/Roboto-Bold-webfont.woff HTTP/1.1" 304 0
[05/Feb/2019 12:13:47] "GET /static/admin/fonts/Roboto-Regular-webfont.woff HTTP/1.1" 304 0
[05/Feb/2019 12:13:47] "GET /static/admin/img/icon-addlink.svg HTTP/1.1" 304 0
[05/Feb/2019 12:13:47] "GET /static/admin/img/icon-changelink.svg HTTP/1.1" 304 0
[05/Feb/2019 12:13:49] "GET /admin/logout/ HTTP/1.1" 200 1349
[05/Feb/2019 12:13:52] "GET /posts/ HTTP/1.1" 200 128
[05/Feb/2019 12:13:56] "GET /admin/ HTTP/1.1" 302 0
[05/Feb/2019 12:13:56] "GET /admin/login/?next=/admin/ HTTP/1.1" 200 1683
[05/Feb/2019 12:13:57] "GET /static/admin/css/login.css HTTP/1.1" 304 0
[05/Feb/2019 12:13:58] "POST /admin/login/?next=/admin/ HTTP/1.1" 302 0
[05/Feb/2019 12:13:59] "GET /admin/ HTTP/1.1" 200 4562

(trydjango) D:\trydjango\src>
(trydjango) D:\trydjango\src>python manage.py shell
Python 2.7.15 |Anaconda, Inc.| (default, May  1 2018, 18:37:09) [MSC v.1500 64 bit (AMD64)] on win32
Type "help", "copyright", "credits" or "license" for more information.
(InteractiveConsole)
>>> from posts.model import Post
Traceback (most recent call last):
  File "<console>", line 1, in <module>
ImportError: No module named model
>>> from posts.models import Post
>>> Post
<class 'posts.models.Post'>
>>> Post.object.all()
Traceback (most recent call last):
  File "<console>", line 1, in <module>
AttributeError: type object 'Post' has no attribute 'object'
>>> Post.objects.all()
[<Post: Title>, <Post: abc>]
>>> query = Post
>>> query = Post()
>>> query.title = "Ra"
>>> dir(query)
['DoesNotExist', 'MultipleObjectsReturned', '__class__', '__delattr__', '__dict__', '__doc__', '__eq__', '__format__', '__getattribute__', '__hash__', '__init__', u'__module__', '__ne__', '__new__', '__reduce__', '__reduce_ex__', '__repr__', '__setattr__', '__setstate__', '__sizeof__', '__str__', '__subclasshook__', '__unicode__', '__weakref__', '_base_manager', '_check_column_name_clashes', '_check_field_name_clashes', '_check_fields', '_check_id_field', '_check_index_together', '_check_local_fields', '_check_long_column_names', '_check_m2m_through_same_relationship', '_check_managers', '_check_model', '_check_ordering', '_check_swappable', '_check_unique_together', '_default_manager', '_deferred', '_do_insert', '_do_update', '_get_FIELD_display', '_get_next_or_previous_by_FIELD', '_get_next_or_previous_in_order', '_get_pk_val', '_get_unique_checks', '_meta', '_perform_date_checks', '_perform_unique_checks', '_save_parents', '_save_table', '_set_pk_val', '_state', 'check', 'clean', 'clean_fields', 'content', 'date_error_message', 'delete', 'from_db', 'full_clean', 'get_deferred_fields', 'get_next_by_timestamp', 'get_next_by_updated', 'get_previous_by_timestamp', 'get_previous_by_updated', 'id', 'objects', 'pk', 'prepare_database_save', 'refresh_from_db', 'save', 'save_base', 'serializable_value', 'timestamp', 'title', 'unique_error_message', 'updated', 'validate_unique']
>>> query.content = "Hello"
>>> query.save()
>>> query.objects.all()
Traceback (most recent call last):
  File "<console>", line 1, in <module>
  File "D:\trydjango\lib\site-packages\django\db\models\manager.py", line 250, in __get__
    raise AttributeError("Manager isn't accessible via %s instances" % type.__name__)
AttributeError: Manager isn't accessible via Post instances
>>> Post.objects.all()
[<Post: Title>, <Post: abc>, <Post: Ra>]
>>>  Post.objects.filter(title = "Ra")
  File "<console>", line 1
    Post.objects.filter(title = "Ra")
    ^
IndentationError: unexpected indent
>>>  Post.objects.filter(title = "Ra")
  File "<console>", line 1
    Post.objects.filter(title = "Ra")
    ^
IndentationError: unexpected indent
>>>
>>> Post.objects.filter(title = "Ra")
[<Post: Ra>]
>>>  Post.objects.filter(title__icontain = "aBc")
  File "<console>", line 1
    Post.objects.filter(title__icontain = "aBc")
    ^
IndentationError: unexpected indent
>>> Post.objects.filter(title__icontain = "aBc")
Traceback (most recent call last):
  File "<console>", line 1, in <module>
  File "D:\trydjango\lib\site-packages\django\db\models\manager.py", line 122, in manager_method
    return getattr(self.get_queryset(), name)(*args, **kwargs)
  File "D:\trydjango\lib\site-packages\django\db\models\query.py", line 790, in filter
    return self._filter_or_exclude(False, *args, **kwargs)
  File "D:\trydjango\lib\site-packages\django\db\models\query.py", line 808, in _filter_or_exclude
    clone.query.add_q(Q(*args, **kwargs))
  File "D:\trydjango\lib\site-packages\django\db\models\sql\query.py", line 1243, in add_q
    clause, _ = self._add_q(q_object, self.used_aliases)
  File "D:\trydjango\lib\site-packages\django\db\models\sql\query.py", line 1269, in _add_q
    allow_joins=allow_joins, split_subq=split_subq,
  File "D:\trydjango\lib\site-packages\django\db\models\sql\query.py", line 1203, in build_filter
    condition = self.build_lookup(lookups, col, value)
  File "D:\trydjango\lib\site-packages\django\db\models\sql\query.py", line 1097, in build_lookup
    lhs = self.try_transform(lhs, name, lookups)
  File "D:\trydjango\lib\site-packages\django\db\models\sql\query.py", line 1115, in try_transform
    (name, lhs.output_field.__class__.__name__))
FieldError: Unsupported lookup 'icontain' for CharField or join on the field not permitted.
>>> Post.objects.filter(title__icontains = "aBc")
[<Post: abc>]
>>>
>>>  Post.objects.create(title="Query",content="Test")
  File "<console>", line 1
    Post.objects.create(title="Query",content="Test")
    ^
IndentationError: unexpected indent
>>> Post.objects.create(title="Query",content="Test")
<Post: Query>
>>> Post.objects.create(title="Query",content="Test")
<Post: Query>
>>> Post.objects.create(title="Query",content="Test")
<Post: Query>
>>> Post.objects.create(title="Query",content="Test")
<Post: Query>
>>> Post.objects.create(title="Query",content="Test")
<Post: Query>
>>> Post.objects.create(title="Query",content="Test")
<Post: Query>
>>> Post.objects.create(title="Query",content="Test")
<Post: Query>
>>> Post.objects.create(title="Query",content="Test")
<Post: Query>
>>> Post.objects.create(title="Query",content="Test")
<Post: Query>
>>> Post.objects.create(title="Query",content="Test")
<Post: Query>
>>> Post.objects.all()
[<Post: Title>, <Post: abc>, <Post: Ra>, <Post: Query>, <Post: Query>, <Post: Query>, <Post: Query>, <Post: Query>, <Post: Query>, <Post: Query>, <Post: Query>, <Post: Query>, <Post: Query>]
>>> Post.objects.all()
[<Post: Title>, <Post: abc>, <Post: Ra>, <Post: Query>, <Post: Query>, <Post: Query>, <Post: Query>, <Post: Query>, <Post: Query>, <Post: Query>, <Post: Query>, <Post: Query>, <Post: Query>]
>>> Post.objects.all()
[<Post: Title>, <Post: abc>, <Post: Ra>, <Post: Query>, <Post: Query>, <Post: Query>, <Post: Query>, <Post: Query>, <Post: Query>, <Post: Query>, <Post: Query>, <Post: Query>, <Post: Query>]
>>>
Traceback (most recent call last):
  File "manage.py", line 10, in <module>
    execute_from_command_line(sys.argv)
  File "D:\trydjango\lib\site-packages\django\core\management\__init__.py", line 350, in execute_from_command_line
    utility.execute()
  File "D:\trydjango\lib\site-packages\django\core\management\__init__.py", line 342, in execute
    self.fetch_command(subcommand).run_from_argv(self.argv)
  File "D:\trydjango\lib\site-packages\django\core\management\base.py", line 360, in run_from_argv
    connections.close_all()
  File "D:\trydjango\lib\site-packages\django\db\utils.py", line 235, in close_all
    connection.close()
  File "D:\trydjango\lib\site-packages\django\db\backends\sqlite3\base.py", line 231, in close
    BaseDatabaseWrapper.close(self)
  File "D:\trydjango\lib\site-packages\django\db\backends\base\base.py", line 272, in close
    self._close()
  File "D:\trydjango\lib\site-packages\django\db\backends\base\base.py", line 221, in _close
    return self.connection.close()
KeyboardInterrupt

(trydjango) D:\trydjango\src>python manage.py migrate
Operations to perform:
  Apply all migrations: admin, contenttypes, posts, auth, sessions
Running migrations:
  No migrations to apply.

(trydjango) D:\trydjango\src>python manage.py makemigrations
No changes detected

(trydjango) D:\trydjango\src> python manage.py migrate
Operations to perform:
  Apply all migrations: admin, contenttypes, posts, auth, sessions
Running migrations:
  No migrations to apply.

(trydjango) D:\trydjango\src>python manage.py shell
Python 2.7.15 |Anaconda, Inc.| (default, May  1 2018, 18:37:09) [MSC v.1500 64 bit (AMD64)] on win32
Type "help", "copyright", "credits" or "license" for more information.
(InteractiveConsole)
>>> Post.objects.all()
Traceback (most recent call last):
  File "<console>", line 1, in <module>
NameError: name 'Post' is not defined
>>> from posts.model import Post
Traceback (most recent call last):
  File "<console>", line 1, in <module>
ImportError: No module named model
>>> from posts.models import Post
>>> Post.objects.all()
Traceback (most recent call last):
  File "<console>", line 1, in <module>
  File "D:\trydjango\lib\site-packages\django\db\models\query.py", line 237, in __repr__
    return repr(data)
  File "D:\trydjango\lib\site-packages\django\db\models\base.py", line 459, in __repr__
    u = six.text_type(self)
TypeError: coercing to Unicode: need string or buffer, tuple found
>>> Post.objects.all()
Traceback (most recent call last):
  File "<console>", line 1, in <module>
  File "D:\trydjango\lib\site-packages\django\db\models\query.py", line 237, in __repr__
    return repr(data)
  File "D:\trydjango\lib\site-packages\django\db\models\base.py", line 459, in __repr__
    u = six.text_type(self)
TypeError: coercing to Unicode: need string or buffer, tuple found
>>> Post.objects.all()
Traceback (most recent call last):
  File "<console>", line 1, in <module>
  File "D:\trydjango\lib\site-packages\django\db\models\query.py", line 237, in __repr__
    return repr(data)
  File "D:\trydjango\lib\site-packages\django\db\models\base.py", line 459, in __repr__
    u = six.text_type(self)
TypeError: coercing to Unicode: need string or buffer, tuple found
>>>
^C
(trydjango) D:\trydjango\src>python manage.py makemigrations
No changes detected

(trydjango) D:\trydjango\src> python manage.py migrate
Operations to perform:
  Apply all migrations: admin, contenttypes, posts, auth, sessions
Running migrations:
  No migrations to apply.

(trydjango) D:\trydjango\src>python manage.py shell
Python 2.7.15 |Anaconda, Inc.| (default, May  1 2018, 18:37:09) [MSC v.1500 64 bit (AMD64)] on win32
Type "help", "copyright", "credits" or "license" for more information.
(InteractiveConsole)
>>>
>>> from posts.model import Post
Traceback (most recent call last):
  File "<console>", line 1, in <module>
ImportError: No module named model
>>> from posts.models import Post
>>> Post.objects.all()
[<Post: Title,Hello world!!!>, <Post: abc,abc123>, <Post: Ra,Hello>, <Post: Query,Test>, <Post: Query,Test>, <Post: Query,Test>, <Post: Query,Test>, <Post: Query,Test>, <Post: Query,Test>, <Post: Query,Test>, <Post: Query,Test>, <Post: Query,Test>, <Post: Query,Test>]
>>> exit()

(trydjango) D:\trydjango\src>python manage.py shell
Python 2.7.15 |Anaconda, Inc.| (default, May  1 2018, 18:37:09) [MSC v.1500 64 bit (AMD64)] on win32
Type "help", "copyright", "credits" or "license" for more information.
(InteractiveConsole)
>>> from posts.models import Post
>>> Post.objects.all()
[<Post: Title,Hello world!!!,>, <Post: abc,abc123,>, <Post: Ra,Hello,>, <Post: Query,Test,>, <Post: Query,Test,>, <Post: Query,Test,>, <Post: Query,Test,>, <Post: Query,Test,>, <Post: Query,Test,>, <Post: Query,Test,>, <Post: Query,Test,>, <Post: Query,Test,>, <Post: Query,Test,>]
>>> exit()

(trydjango) D:\trydjango\src>python manage.py runserver
Performing system checks...

System check identified no issues (0 silenced).
February 05, 2019 - 14:03:45
Django version 1.9, using settings 'trydjango.settings'
Starting development server at http://127.0.0.1:8000/
Quit the server with CTRL-BREAK.
Internal Server Error: /posts/
Traceback (most recent call last):
  File "D:\trydjango\lib\site-packages\django\core\handlers\base.py", line 149, in get_response
    response = self.process_exception_by_middleware(e, request)
  File "D:\trydjango\lib\site-packages\django\core\handlers\base.py", line 147, in get_response
    response = wrapped_callback(request, *callback_args, **callback_kwargs)
  File "D:\trydjango\src\posts\views.py", line 18, in post_list
    return render(self,'index.html',queryset)
  File "D:\trydjango\lib\site-packages\django\shortcuts.py", line 67, in render
    template_name, context, request=request, using=using)
  File "D:\trydjango\lib\site-packages\django\template\loader.py", line 97, in render_to_string
    return template.render(context, request)
  File "D:\trydjango\lib\site-packages\django\template\backends\django.py", line 92, in render
    context = make_context(context, request)
  File "D:\trydjango\lib\site-packages\django\template\context.py", line 291, in make_context
    context.push(original_context)
  File "D:\trydjango\lib\site-packages\django\template\context.py", line 61, in push
    return ContextDict(self, *dicts, **kwargs)
  File "D:\trydjango\lib\site-packages\django\template\context.py", line 20, in __init__
    super(ContextDict, self).__init__(*args, **kwargs)
TypeError: cannot convert dictionary update sequence element #0 to a sequence
[05/Feb/2019 14:03:57] "GET /posts/ HTTP/1.1" 500 92264
Performing system checks...

System check identified no issues (0 silenced).
February 05, 2019 - 14:05:18
Django version 1.9, using settings 'trydjango.settings'
Starting development server at http://127.0.0.1:8000/
Quit the server with CTRL-BREAK.
[05/Feb/2019 14:05:21] "GET /posts/ HTTP/1.1" 200 117
[05/Feb/2019 14:07:43] "GET /posts/ HTTP/1.1" 200 1421
[05/Feb/2019 14:08:43] "GET /posts/ HTTP/1.1" 200 1481
Performing system checks...

System check identified no issues (0 silenced).
February 05, 2019 - 14:15:35
Django version 1.9, using settings 'trydjango.settings'
Starting development server at http://127.0.0.1:8000/
Quit the server with CTRL-BREAK.
Performing system checks...

System check identified no issues (0 silenced).
February 05, 2019 - 14:16:15
Django version 1.9, using settings 'trydjango.settings'
Starting development server at http://127.0.0.1:8000/
Quit the server with CTRL-BREAK.
[05/Feb/2019 14:16:59] "GET /posts/ HTTP/1.1" 200 1481
Internal Server Error: /posts/detail/
Traceback (most recent call last):
  File "D:\trydjango\lib\site-packages\django\core\handlers\base.py", line 149, in get_response
    response = self.process_exception_by_middleware(e, request)
  File "D:\trydjango\lib\site-packages\django\core\handlers\base.py", line 147, in get_response
    response = wrapped_callback(request, *callback_args, **callback_kwargs)
  File "D:\trydjango\src\posts\views.py", line 8, in post_detail
    queryset = get_object_or_404(id=3)
TypeError: get_object_or_404() takes at least 1 argument (0 given)
[05/Feb/2019 14:17:10] "GET /posts/detail/ HTTP/1.1" 500 64180
Performing system checks...

System check identified no issues (0 silenced).
February 05, 2019 - 14:17:37
Django version 1.9, using settings 'trydjango.settings'
Starting development server at http://127.0.0.1:8000/
Quit the server with CTRL-BREAK.
Internal Server Error: /posts/detail/
Traceback (most recent call last):
  File "D:\trydjango\lib\site-packages\django\core\handlers\base.py", line 149, in get_response
    response = self.process_exception_by_middleware(e, request)
  File "D:\trydjango\lib\site-packages\django\core\handlers\base.py", line 147, in get_response
    response = wrapped_callback(request, *callback_args, **callback_kwargs)
  File "D:\trydjango\src\posts\views.py", line 12, in post_detail
    return render(self,'post_detail.html',context)
  File "D:\trydjango\lib\site-packages\django\shortcuts.py", line 67, in render
    template_name, context, request=request, using=using)
  File "D:\trydjango\lib\site-packages\django\template\loader.py", line 96, in render_to_string
    template = get_template(template_name, using=using)
  File "D:\trydjango\lib\site-packages\django\template\loader.py", line 43, in get_template
    raise TemplateDoesNotExist(template_name, chain=chain)
TemplateDoesNotExist: post_detail.html
[05/Feb/2019 14:17:43] "GET /posts/detail/ HTTP/1.1" 500 80920
Internal Server Error: /posts/detail/
Traceback (most recent call last):
  File "D:\trydjango\lib\site-packages\django\core\handlers\base.py", line 149, in get_response
    response = self.process_exception_by_middleware(e, request)
  File "D:\trydjango\lib\site-packages\django\core\handlers\base.py", line 147, in get_response
    response = wrapped_callback(request, *callback_args, **callback_kwargs)
  File "D:\trydjango\src\posts\views.py", line 12, in post_detail
    return render(self,'post_detail.html',context)
  File "D:\trydjango\lib\site-packages\django\shortcuts.py", line 67, in render
    template_name, context, request=request, using=using)
  File "D:\trydjango\lib\site-packages\django\template\loader.py", line 96, in render_to_string
    template = get_template(template_name, using=using)
  File "D:\trydjango\lib\site-packages\django\template\loader.py", line 43, in get_template
    raise TemplateDoesNotExist(template_name, chain=chain)
TemplateDoesNotExist: post_detail.html
[05/Feb/2019 14:17:46] "GET /posts/detail/ HTTP/1.1" 500 80920
Internal Server Error: /posts/detail/
Traceback (most recent call last):
  File "D:\trydjango\lib\site-packages\django\core\handlers\base.py", line 149, in get_response
    response = self.process_exception_by_middleware(e, request)
  File "D:\trydjango\lib\site-packages\django\core\handlers\base.py", line 147, in get_response
    response = wrapped_callback(request, *callback_args, **callback_kwargs)
  File "D:\trydjango\src\posts\views.py", line 12, in post_detail
    return render(self,'post_detail.html',context)
  File "D:\trydjango\lib\site-packages\django\shortcuts.py", line 67, in render
    template_name, context, request=request, using=using)
  File "D:\trydjango\lib\site-packages\django\template\loader.py", line 96, in render_to_string
    template = get_template(template_name, using=using)
  File "D:\trydjango\lib\site-packages\django\template\loader.py", line 43, in get_template
    raise TemplateDoesNotExist(template_name, chain=chain)
TemplateDoesNotExist: post_detail.html
Internal Server Error: /posts/detail/
Traceback (most recent call last):
  File "D:\trydjango\lib\site-packages\django\core\handlers\base.py", line 149, in get_response
    response = self.process_exception_by_middleware(e, request)
  File "D:\trydjango\lib\site-packages\django\core\handlers\base.py", line 147, in get_response
    response = wrapped_callback(request, *callback_args, **callback_kwargs)
  File "D:\trydjango\src\posts\views.py", line 12, in post_detail
    return render(self,'post_detail.html',context)
  File "D:\trydjango\lib\site-packages\django\shortcuts.py", line 67, in render
    template_name, context, request=request, using=using)
  File "D:\trydjango\lib\site-packages\django\template\loader.py", line 96, in render_to_string
    template = get_template(template_name, using=using)
  File "D:\trydjango\lib\site-packages\django\template\loader.py", line 43, in get_template
    raise TemplateDoesNotExist(template_name, chain=chain)
TemplateDoesNotExist: post_detail.html
Internal Server Error: /posts/detail/
Traceback (most recent call last):
  File "D:\trydjango\lib\site-packages\django\core\handlers\base.py", line 149, in get_response
    response = self.process_exception_by_middleware(e, request)
  File "D:\trydjango\lib\site-packages\django\core\handlers\base.py", line 147, in get_response
    response = wrapped_callback(request, *callback_args, **callback_kwargs)
  File "D:\trydjango\src\posts\views.py", line 12, in post_detail
    return render(self,'post_detail.html',context)
  File "D:\trydjango\lib\site-packages\django\shortcuts.py", line 67, in render
    template_name, context, request=request, using=using)
  File "D:\trydjango\lib\site-packages\django\template\loader.py", line 96, in render_to_string
    template = get_template(template_name, using=using)
  File "D:\trydjango\lib\site-packages\django\template\loader.py", line 43, in get_template
    raise TemplateDoesNotExist(template_name, chain=chain)
TemplateDoesNotExist: post_detail.html
[05/Feb/2019 14:17:46] "GET /posts/detail/ HTTP/1.1" 500 80920
Traceback (most recent call last):
  File "c:\programdata\anaconda2\Lib\wsgiref\handlers.py", line 86, in run
    self.finish_response()
  File "c:\programdata\anaconda2\Lib\wsgiref\handlers.py", line 128, in finish_response
    self.write(data)
  File "c:\programdata\anaconda2\Lib\wsgiref\handlers.py", line 212, in write
    self.send_headers()
  File "c:\programdata\anaconda2\Lib\wsgiref\handlers.py", line 270, in send_headers
    self.send_preamble()
  File "c:\programdata\anaconda2\Lib\wsgiref\handlers.py", line 194, in send_preamble
    'Date: %s\r\n' % format_date_time(time.time())
  File "c:\programdata\anaconda2\Lib\socket.py", line 328, in write
    self.flush()
  File "c:\programdata\anaconda2\Lib\socket.py", line 307, in flush
    self._sock.sendall(view[write_offset:write_offset+buffer_size])
error: [Errno 10053] An established connection was aborted by the software in your host machine
[05/Feb/2019 14:17:46] "GET /posts/detail/ HTTP/1.1" 500 59
----------------------------------------
Exception happened during processing of request from ('127.0.0.1', 64136)
Traceback (most recent call last):
  File "c:\programdata\anaconda2\Lib\SocketServer.py", line 596, in process_request_thread
    self.finish_request(request, client_address)
  File "c:\programdata\anaconda2\Lib\SocketServer.py", line 331, in finish_request
    self.RequestHandlerClass(request, client_address, self)
  File "D:\trydjango\lib\site-packages\django\core\servers\basehttp.py", line 99, in __init__
    super(WSGIRequestHandler, self).__init__(*args, **kwargs)
  File "c:\programdata\anaconda2\Lib\SocketServer.py", line 654, in __init__
    self.finish()
  File "c:\programdata\anaconda2\Lib\SocketServer.py", line 713, in finish
    self.wfile.close()
  File "c:\programdata\anaconda2\Lib\socket.py", line 283, in close
    self.flush()
  File "c:\programdata\anaconda2\Lib\socket.py", line 307, in flush
    self._sock.sendall(view[write_offset:write_offset+buffer_size])
error: [Errno 10053] An established connection was aborted by the software in your host machine
----------------------------------------
[05/Feb/2019 14:17:46] "GET /posts/detail/ HTTP/1.1" 500 80920
Traceback (most recent call last):
  File "c:\programdata\anaconda2\Lib\wsgiref\handlers.py", line 86, in run
    self.finish_response()
  File "c:\programdata\anaconda2\Lib\wsgiref\handlers.py", line 128, in finish_response
    self.write(data)
  File "c:\programdata\anaconda2\Lib\wsgiref\handlers.py", line 212, in write
    self.send_headers()
  File "c:\programdata\anaconda2\Lib\wsgiref\handlers.py", line 270, in send_headers
    self.send_preamble()
  File "c:\programdata\anaconda2\Lib\wsgiref\handlers.py", line 194, in send_preamble
    'Date: %s\r\n' % format_date_time(time.time())
  File "c:\programdata\anaconda2\Lib\socket.py", line 328, in write
    self.flush()
  File "c:\programdata\anaconda2\Lib\socket.py", line 307, in flush
    self._sock.sendall(view[write_offset:write_offset+buffer_size])
error: [Errno 10053] An established connection was aborted by the software in your host machine
[05/Feb/2019 14:17:46] "GET /posts/detail/ HTTP/1.1" 500 59
----------------------------------------
Exception happened during processing of request from ('127.0.0.1', 64137)
Traceback (most recent call last):
  File "c:\programdata\anaconda2\Lib\SocketServer.py", line 596, in process_request_thread
    self.finish_request(request, client_address)
  File "c:\programdata\anaconda2\Lib\SocketServer.py", line 331, in finish_request
    self.RequestHandlerClass(request, client_address, self)
  File "D:\trydjango\lib\site-packages\django\core\servers\basehttp.py", line 99, in __init__
    super(WSGIRequestHandler, self).__init__(*args, **kwargs)
  File "c:\programdata\anaconda2\Lib\SocketServer.py", line 654, in __init__
    self.finish()
  File "c:\programdata\anaconda2\Lib\SocketServer.py", line 713, in finish
    self.wfile.close()
  File "c:\programdata\anaconda2\Lib\socket.py", line 283, in close
    self.flush()
  File "c:\programdata\anaconda2\Lib\socket.py", line 307, in flush
    self._sock.sendall(view[write_offset:write_offset+buffer_size])
error: [Errno 10053] An established connection was aborted by the software in your host machine
----------------------------------------
[05/Feb/2019 14:17:46] "GET /posts/detail/ HTTP/1.1" 500 80920
Internal Server Error: /posts/detail/
Traceback (most recent call last):
  File "D:\trydjango\lib\site-packages\django\core\handlers\base.py", line 149, in get_response
    response = self.process_exception_by_middleware(e, request)
  File "D:\trydjango\lib\site-packages\django\core\handlers\base.py", line 147, in get_response
    response = wrapped_callback(request, *callback_args, **callback_kwargs)
  File "D:\trydjango\src\posts\views.py", line 12, in post_detail
    return render(self,'post_detail.html',context)
  File "D:\trydjango\lib\site-packages\django\shortcuts.py", line 67, in render
    template_name, context, request=request, using=using)
  File "D:\trydjango\lib\site-packages\django\template\loader.py", line 96, in render_to_string
    template = get_template(template_name, using=using)
  File "D:\trydjango\lib\site-packages\django\template\loader.py", line 43, in get_template
    raise TemplateDoesNotExist(template_name, chain=chain)
TemplateDoesNotExist: post_detail.html
[05/Feb/2019 14:18:09] "GET /posts/detail/ HTTP/1.1" 500 80920
Internal Server Error: /posts/detail/
Traceback (most recent call last):
  File "D:\trydjango\lib\site-packages\django\core\handlers\base.py", line 149, in get_response
    response = self.process_exception_by_middleware(e, request)
  File "D:\trydjango\lib\site-packages\django\core\handlers\base.py", line 147, in get_response
    response = wrapped_callback(request, *callback_args, **callback_kwargs)
  File "D:\trydjango\src\posts\views.py", line 12, in post_detail
    return render(self,'post_detail.html',context)
  File "D:\trydjango\lib\site-packages\django\shortcuts.py", line 67, in render
    template_name, context, request=request, using=using)
  File "D:\trydjango\lib\site-packages\django\template\loader.py", line 96, in render_to_string
    template = get_template(template_name, using=using)
  File "D:\trydjango\lib\site-packages\django\template\loader.py", line 43, in get_template
    raise TemplateDoesNotExist(template_name, chain=chain)
TemplateDoesNotExist: post_detail.html
[05/Feb/2019 14:18:27] "GET /posts/detail/ HTTP/1.1" 500 80920
[05/Feb/2019 14:18:31] "GET /posts/detail/ HTTP/1.1" 200 127
[05/Feb/2019 14:19:22] "GET /posts/detail/ HTTP/1.1" 200 126
[05/Feb/2019 14:19:40] "GET /posts/detail/ HTTP/1.1" 200 113
Performing system checks...

System check identified no issues (0 silenced).
February 05, 2019 - 14:20:10
Django version 1.9, using settings 'trydjango.settings'
Starting development server at http://127.0.0.1:8000/
Quit the server with CTRL-BREAK.
[05/Feb/2019 14:20:11] "GET /posts/detail/ HTTP/1.1" 200 113
Performing system checks...

System check identified no issues (0 silenced).
February 05, 2019 - 14:20:18
Django version 1.9, using settings 'trydjango.settings'
Starting development server at http://127.0.0.1:8000/
Quit the server with CTRL-BREAK.
[05/Feb/2019 14:20:18] "GET /posts/detail/ HTTP/1.1" 200 113
Performing system checks...

System check identified no issues (0 silenced).
February 05, 2019 - 14:20:43
Django version 1.9, using settings 'trydjango.settings'
Starting development server at http://127.0.0.1:8000/
Quit the server with CTRL-BREAK.
Internal Server Error: /posts/detail/
Traceback (most recent call last):
  File "D:\trydjango\lib\site-packages\django\core\handlers\base.py", line 149, in get_response
    response = self.process_exception_by_middleware(e, request)
  File "D:\trydjango\lib\site-packages\django\core\handlers\base.py", line 147, in get_response
    response = wrapped_callback(request, *callback_args, **callback_kwargs)
  File "D:\trydjango\src\posts\views.py", line 9, in post_detail
    print(queryset)
TypeError: __str__ returned non-string (type tuple)
[05/Feb/2019 14:20:46] "GET /posts/detail/ HTTP/1.1" 500 64398
Performing system checks...

System check identified no issues (0 silenced).
February 05, 2019 - 14:21:12
Django version 1.9, using settings 'trydjango.settings'
Starting development server at http://127.0.0.1:8000/
Quit the server with CTRL-BREAK.
Internal Server Error: /posts/detail/
Traceback (most recent call last):
  File "D:\trydjango\lib\site-packages\django\core\handlers\base.py", line 149, in get_response
    response = self.process_exception_by_middleware(e, request)
  File "D:\trydjango\lib\site-packages\django\core\handlers\base.py", line 147, in get_response
    response = wrapped_callback(request, *callback_args, **callback_kwargs)
  File "D:\trydjango\src\posts\views.py", line 9, in post_detail
    print(queryset)
TypeError: __str__ returned non-string (type tuple)
[05/Feb/2019 14:21:17] "GET /posts/detail/ HTTP/1.1" 500 64388
Performing system checks...

System check identified no issues (0 silenced).
February 05, 2019 - 14:21:51
Django version 1.9, using settings 'trydjango.settings'
Starting development server at http://127.0.0.1:8000/
Quit the server with CTRL-BREAK.
Query
[05/Feb/2019 14:21:53] "GET /posts/detail/ HTTP/1.1" 200 113
Performing system checks...

System check identified no issues (0 silenced).
February 05, 2019 - 14:23:04
Django version 1.9, using settings 'trydjango.settings'
Starting development server at http://127.0.0.1:8000/
Quit the server with CTRL-BREAK.
Title
[05/Feb/2019 14:23:08] "GET /posts/detail/ HTTP/1.1" 200 113
Performing system checks...

System check identified no issues (0 silenced).
February 05, 2019 - 14:23:59
Django version 1.9, using settings 'trydjango.settings'
Starting development server at http://127.0.0.1:8000/
Quit the server with CTRL-BREAK.
Title,Hello world!!!,
[05/Feb/2019 14:24:08] "GET /posts/detail/ HTTP/1.1" 200 113
Performing system checks...

System check identified no issues (0 silenced).
February 05, 2019 - 14:25:15
Django version 1.9, using settings 'trydjango.settings'
Starting development server at http://127.0.0.1:8000/
Quit the server with CTRL-BREAK.
Title,Hello world!!!,
[05/Feb/2019 14:25:26] "GET /posts/detail/ HTTP/1.1" 200 113
Title,Hello world!!!,
[05/Feb/2019 14:25:26] "GET /posts/detail/ HTTP/1.1" 200 113
Title,Hello world!!!,
[05/Feb/2019 14:25:27] "GET /posts/detail/ HTTP/1.1" 200 113
Title,Hello world!!!,
[05/Feb/2019 14:25:27] "GET /posts/detail/ HTTP/1.1" 200 113
Title,Hello world!!!,
[05/Feb/2019 14:25:54] "GET /posts/detail/ HTTP/1.1" 200 113
Title,Hello world!!!,
[05/Feb/2019 14:26:26] "GET /posts/detail/ HTTP/1.1" 200 223
Title,Hello world!!!,
[05/Feb/2019 14:26:49] "GET /posts/detail/ HTTP/1.1" 200 201
Performing system checks...

System check identified no issues (0 silenced).
February 05, 2019 - 14:27:20
Django version 1.9, using settings 'trydjango.settings'
Starting development server at http://127.0.0.1:8000/
Quit the server with CTRL-BREAK.
[05/Feb/2019 14:27:20] "GET /posts/detail/ HTTP/1.1" 200 205
Performing system checks...

System check identified no issues (0 silenced).
February 05, 2019 - 14:27:29
Django version 1.9, using settings 'trydjango.settings'
Starting development server at http://127.0.0.1:8000/
Quit the server with CTRL-BREAK.
Not Found: /posts/detail/
[05/Feb/2019 14:27:29] "GET /posts/detail/ HTTP/1.1" 404 1727
Performing system checks...

System check identified no issues (0 silenced).
February 05, 2019 - 14:27:34
Django version 1.9, using settings 'trydjango.settings'
Starting development server at http://127.0.0.1:8000/
Quit the server with CTRL-BREAK.
[05/Feb/2019 14:27:34] "GET /posts/detail/ HTTP/1.1" 200 203
Performing system checks...

System check identified no issues (0 silenced).
February 05, 2019 - 14:33:23
Django version 1.9, using settings 'trydjango.settings'
Starting development server at http://127.0.0.1:8000/
Quit the server with CTRL-BREAK.
Performing system checks...

System check identified no issues (0 silenced).
February 05, 2019 - 14:33:41
Django version 1.9, using settings 'trydjango.settings'
Starting development server at http://127.0.0.1:8000/
Quit the server with CTRL-BREAK.
Not Found: /posts/detail/1
[05/Feb/2019 14:33:45] "GET /posts/detail/1 HTTP/1.1" 301 0
[05/Feb/2019 14:33:45] "GET /posts/detail/1/ HTTP/1.1" 200 203
[05/Feb/2019 14:33:50] "GET /posts/detail/2/ HTTP/1.1" 200 199
Not Found: /posts/detail/2x/
[05/Feb/2019 14:33:55] "GET /posts/detail/2x/ HTTP/1.1" 404 2780
Not Found: /posts/detail/15/
[05/Feb/2019 14:34:01] "GET /posts/detail/15/ HTTP/1.1" 404 1733
[05/Feb/2019 14:34:05] "GET /posts/detail/4/ HTTP/1.1" 200 203
[05/Feb/2019 14:34:10] "GET /posts/detail/4/ HTTP/1.1" 200 203
[05/Feb/2019 14:34:15] "GET /posts/detail/3/ HTTP/1.1" 200 197
Performing system checks...

System check identified no issues (0 silenced).
February 05, 2019 - 14:34:37
Django version 1.9, using settings 'trydjango.settings'
Starting development server at http://127.0.0.1:8000/
Quit the server with CTRL-BREAK.
Performing system checks...

System check identified no issues (0 silenced).
February 05, 2019 - 14:34:46
Django version 1.9, using settings 'trydjango.settings'
Starting development server at http://127.0.0.1:8000/
Quit the server with CTRL-BREAK.
[05/Feb/2019 14:34:51] "GET /posts/3/ HTTP/1.1" 200 197
[05/Feb/2019 14:34:56] "GET /posts/5/ HTTP/1.1" 200 203
Performing system checks...

System check identified no issues (0 silenced).
February 05, 2019 - 14:35:28
Django version 1.9, using settings 'trydjango.settings'
Starting development server at http://127.0.0.1:8000/
Quit the server with CTRL-BREAK.
[05/Feb/2019 14:52:44] "GET /posts/5/ HTTP/1.1" 200 203
[05/Feb/2019 14:52:48] "GET /posts/ HTTP/1.1" 200 1494
Not Found: /posts/posts/2/
[05/Feb/2019 14:52:54] "GET /posts/posts/2/ HTTP/1.1" 404 2767
Not Found: /posts/posts/2/
[05/Feb/2019 14:53:11] "GET /posts/posts/2/ HTTP/1.1" 404 2767
Not Found: /posts/posts/2/
[05/Feb/2019 14:53:16] "GET /posts/posts/2/ HTTP/1.1" 404 2767
Not Found: /posts/posts/2/
[05/Feb/2019 14:53:24] "GET /posts/posts/2/ HTTP/1.1" 404 2767
Not Found: /posts/posts/2/
[05/Feb/2019 14:53:27] "GET /posts/posts/2/ HTTP/1.1" 404 2767
Not Found: /posts/posts/1/
[05/Feb/2019 14:53:31] "GET /posts/posts/1/ HTTP/1.1" 404 2767
[05/Feb/2019 14:53:40] "GET /posts/ HTTP/1.1" 200 1494
Not Found: /post/1/
[05/Feb/2019 14:53:42] "GET /post/1/ HTTP/1.1" 404 2034
[05/Feb/2019 14:53:49] "GET /posts/ HTTP/1.1" 200 1507
[05/Feb/2019 14:53:51] "GET /posts/1/ HTTP/1.1" 200 203
Performing system checks...

System check identified no issues (0 silenced).
February 05, 2019 - 14:54:58
Django version 1.9, using settings 'trydjango.settings'
Starting development server at http://127.0.0.1:8000/
Quit the server with CTRL-BREAK.
[05/Feb/2019 14:56:31] "GET /posts/1/ HTTP/1.1" 200 203
Internal Server Error: /posts/
Traceback (most recent call last):
  File "D:\trydjango\lib\site-packages\django\core\handlers\base.py", line 149, in get_response
    response = self.process_exception_by_middleware(e, request)
  File "D:\trydjango\lib\site-packages\django\core\handlers\base.py", line 147, in get_response
    response = wrapped_callback(request, *callback_args, **callback_kwargs)
  File "D:\trydjango\src\posts\views.py", line 25, in post_list
    return render(self,'index.html',context)
  File "D:\trydjango\lib\site-packages\django\shortcuts.py", line 67, in render
    template_name, context, request=request, using=using)
  File "D:\trydjango\lib\site-packages\django\template\loader.py", line 97, in render_to_string
    return template.render(context, request)
  File "D:\trydjango\lib\site-packages\django\template\backends\django.py", line 95, in render
    return self.template.render(context)
  File "D:\trydjango\lib\site-packages\django\template\base.py", line 206, in render
    return self._render(context)
  File "D:\trydjango\lib\site-packages\django\template\base.py", line 197, in _render
    return self.nodelist.render(context)
  File "D:\trydjango\lib\site-packages\django\template\base.py", line 988, in render
    bit = node.render_annotated(context)
  File "D:\trydjango\lib\site-packages\django\template\base.py", line 955, in render_annotated
    return self.render(context)
  File "D:\trydjango\lib\site-packages\django\template\defaulttags.py", line 220, in render
    nodelist.append(node.render_annotated(context))
  File "D:\trydjango\lib\site-packages\django\template\base.py", line 955, in render_annotated
    return self.render(context)
  File "D:\trydjango\lib\site-packages\django\template\defaulttags.py", line 499, in render
    url = reverse(view_name, args=args, kwargs=kwargs, current_app=current_app)
  File "D:\trydjango\lib\site-packages\django\core\urlresolvers.py", line 600, in reverse
    return force_text(iri_to_uri(resolver._reverse_with_prefix(view, prefix, *args, **kwargs)))
  File "D:\trydjango\lib\site-packages\django\core\urlresolvers.py", line 443, in _reverse_with_prefix
    raise ValueError("Don't mix *args and **kwargs in call to reverse()!")
ValueError: Don't mix *args and **kwargs in call to reverse()!
[05/Feb/2019 14:56:34] "GET /posts/ HTTP/1.1" 500 127064
[05/Feb/2019 14:56:54] "GET /posts/ HTTP/1.1" 200 2078
[05/Feb/2019 14:56:58] "GET /posts/1/ HTTP/1.1" 200 203
[05/Feb/2019 14:57:01] "GET /posts/2/ HTTP/1.1" 200 199
Performing system checks...

System check identified no issues (0 silenced).
February 05, 2019 - 15:00:38
Django version 1.9, using settings 'trydjango.settings'
Starting development server at http://127.0.0.1:8000/
Quit the server with CTRL-BREAK.
[05/Feb/2019 15:00:40] "GET /posts/ HTTP/1.1" 200 2649
[05/Feb/2019 15:00:40] "GET /posts/ HTTP/1.1" 200 2649
[05/Feb/2019 15:00:40] "GET /posts/ HTTP/1.1" 200 2649
Not Found: /posts/1
[05/Feb/2019 15:00:42] "GET /posts/1 HTTP/1.1" 301 0
[05/Feb/2019 15:00:42] "GET /posts/1/ HTTP/1.1" 200 203
Performing system checks...

System check identified no issues (0 silenced).
February 05, 2019 - 15:03:16
Django version 1.9, using settings 'trydjango.settings'
Starting development server at http://127.0.0.1:8000/
Quit the server with CTRL-BREAK.
[05/Feb/2019 15:03:20] "GET /posts/ HTTP/1.1" 200 2662
[05/Feb/2019 15:03:20] "GET /posts/ HTTP/1.1" 200 2662
[05/Feb/2019 15:03:20] "GET /posts/ HTTP/1.1" 200 2662
[05/Feb/2019 15:03:20] "GET /posts/ HTTP/1.1" 200 2662
[05/Feb/2019 15:03:21] "GET /posts/1/ HTTP/1.1" 200 203
[05/Feb/2019 15:03:24] "GET /posts/2/ HTTP/1.1" 200 199
Performing system checks...

System check identified no issues (0 silenced).
February 05, 2019 - 15:04:01
Django version 1.9, using settings 'trydjango.settings'
Starting development server at http://127.0.0.1:8000/
Quit the server with CTRL-BREAK.
[05/Feb/2019 15:04:04] "GET /posts/ HTTP/1.1" 200 2844
[05/Feb/2019 15:04:05] "GET /posts/ HTTP/1.1" 200 2844
[05/Feb/2019 15:04:05] "GET /posts/ HTTP/1.1" 200 2844
[05/Feb/2019 15:04:05] "GET /posts/ HTTP/1.1" 200 2844
[05/Feb/2019 15:04:06] "GET /posts/detail/1/ HTTP/1.1" 200 203
Performing system checks...

System check identified no issues (0 silenced).
February 05, 2019 - 15:04:17
Django version 1.9, using settings 'trydjango.settings'
Starting development server at http://127.0.0.1:8000/
Quit the server with CTRL-BREAK.
Performing system checks...

Unhandled exception in thread started by <function wrapper at 0x0000000006808C88>
Traceback (most recent call last):
  File "D:\trydjango\lib\site-packages\django\utils\autoreload.py", line 226, in wrapper
    fn(*args, **kwargs)
  File "D:\trydjango\lib\site-packages\django\core\management\commands\runserver.py", line 116, in inner_run
    self.check(display_num_errors=True)
  File "D:\trydjango\lib\site-packages\django\core\management\base.py", line 426, in check
    include_deployment_checks=include_deployment_checks,
  File "D:\trydjango\lib\site-packages\django\core\checks\registry.py", line 75, in run_checks
    new_errors = check(app_configs=app_configs)
  File "D:\trydjango\lib\site-packages\django\core\checks\urls.py", line 10, in check_url_config
    return check_resolver(resolver)
  File "D:\trydjango\lib\site-packages\django\core\checks\urls.py", line 19, in check_resolver
    for pattern in resolver.url_patterns:
  File "D:\trydjango\lib\site-packages\django\utils\functional.py", line 33, in __get__
    res = instance.__dict__[self.name] = self.func(instance)
  File "D:\trydjango\lib\site-packages\django\core\urlresolvers.py", line 417, in url_patterns
    patterns = getattr(self.urlconf_module, "urlpatterns", self.urlconf_module)
  File "D:\trydjango\lib\site-packages\django\utils\functional.py", line 33, in __get__
    res = instance.__dict__[self.name] = self.func(instance)
  File "D:\trydjango\lib\site-packages\django\core\urlresolvers.py", line 410, in urlconf_module
    return import_module(self.urlconf_name)
  File "c:\programdata\anaconda2\Lib\importlib\__init__.py", line 37, in import_module
    __import__(name)
  File "D:\trydjango\src\trydjango\urls.py", line 24, in <module>
    url(r'^posts/', include("posts.urls"), namespace="posts"),
TypeError: url() got an unexpected keyword argument 'namespace'
Performing system checks...

System check identified no issues (0 silenced).
February 05, 2019 - 15:07:01
Django version 1.9, using settings 'trydjango.settings'
Starting development server at http://127.0.0.1:8000/
Quit the server with CTRL-BREAK.
Internal Server Error: /posts/
Traceback (most recent call last):
  File "D:\trydjango\lib\site-packages\django\core\handlers\base.py", line 149, in get_response
    response = self.process_exception_by_middleware(e, request)
  File "D:\trydjango\lib\site-packages\django\core\handlers\base.py", line 147, in get_response
    response = wrapped_callback(request, *callback_args, **callback_kwargs)
  File "D:\trydjango\src\posts\views.py", line 25, in post_list
    return render(self,'index.html',context)
  File "D:\trydjango\lib\site-packages\django\shortcuts.py", line 67, in render
    template_name, context, request=request, using=using)
  File "D:\trydjango\lib\site-packages\django\template\loader.py", line 97, in render_to_string
    return template.render(context, request)
  File "D:\trydjango\lib\site-packages\django\template\backends\django.py", line 95, in render
    return self.template.render(context)
  File "D:\trydjango\lib\site-packages\django\template\base.py", line 206, in render
    return self._render(context)
  File "D:\trydjango\lib\site-packages\django\template\base.py", line 197, in _render
    return self.nodelist.render(context)
  File "D:\trydjango\lib\site-packages\django\template\base.py", line 988, in render
    bit = node.render_annotated(context)
  File "D:\trydjango\lib\site-packages\django\template\base.py", line 955, in render_annotated
    return self.render(context)
  File "D:\trydjango\lib\site-packages\django\template\defaulttags.py", line 220, in render
    nodelist.append(node.render_annotated(context))
  File "D:\trydjango\lib\site-packages\django\template\base.py", line 955, in render_annotated
    return self.render(context)
  File "D:\trydjango\lib\site-packages\django\template\defaulttags.py", line 513, in render
    six.reraise(*exc_info)
  File "D:\trydjango\lib\site-packages\django\template\defaulttags.py", line 499, in render
    url = reverse(view_name, args=args, kwargs=kwargs, current_app=current_app)
  File "D:\trydjango\lib\site-packages\django\core\urlresolvers.py", line 600, in reverse
    return force_text(iri_to_uri(resolver._reverse_with_prefix(view, prefix, *args, **kwargs)))
  File "D:\trydjango\lib\site-packages\django\core\urlresolvers.py", line 508, in _reverse_with_prefix
    (lookup_view_s, args, kwargs, len(patterns), patterns))
NoReverseMatch: Reverse for 'detail' with arguments '()' and keyword arguments '{u'id': 1}' not found. 0 pattern(s) tried: []
[05/Feb/2019 15:07:04] "GET /posts/ HTTP/1.1" 500 136073
Performing system checks...

System check identified no issues (0 silenced).
February 05, 2019 - 15:07:34
Django version 1.9, using settings 'trydjango.settings'
Starting development server at http://127.0.0.1:8000/
Quit the server with CTRL-BREAK.
Internal Server Error: /posts/
Traceback (most recent call last):
  File "D:\trydjango\lib\site-packages\django\core\handlers\base.py", line 149, in get_response
    response = self.process_exception_by_middleware(e, request)
  File "D:\trydjango\lib\site-packages\django\core\handlers\base.py", line 147, in get_response
    response = wrapped_callback(request, *callback_args, **callback_kwargs)
  File "D:\trydjango\src\posts\views.py", line 25, in post_list
    return render(self,'index.html',context)
  File "D:\trydjango\lib\site-packages\django\shortcuts.py", line 67, in render
    template_name, context, request=request, using=using)
  File "D:\trydjango\lib\site-packages\django\template\loader.py", line 97, in render_to_string
    return template.render(context, request)
  File "D:\trydjango\lib\site-packages\django\template\backends\django.py", line 95, in render
    return self.template.render(context)
  File "D:\trydjango\lib\site-packages\django\template\base.py", line 206, in render
    return self._render(context)
  File "D:\trydjango\lib\site-packages\django\template\base.py", line 197, in _render
    return self.nodelist.render(context)
  File "D:\trydjango\lib\site-packages\django\template\base.py", line 988, in render
    bit = node.render_annotated(context)
  File "D:\trydjango\lib\site-packages\django\template\base.py", line 955, in render_annotated
    return self.render(context)
  File "D:\trydjango\lib\site-packages\django\template\defaulttags.py", line 220, in render
    nodelist.append(node.render_annotated(context))
  File "D:\trydjango\lib\site-packages\django\template\base.py", line 955, in render_annotated
    return self.render(context)
  File "D:\trydjango\lib\site-packages\django\template\defaulttags.py", line 513, in render
    six.reraise(*exc_info)
  File "D:\trydjango\lib\site-packages\django\template\defaulttags.py", line 499, in render
    url = reverse(view_name, args=args, kwargs=kwargs, current_app=current_app)
  File "D:\trydjango\lib\site-packages\django\core\urlresolvers.py", line 600, in reverse
    return force_text(iri_to_uri(resolver._reverse_with_prefix(view, prefix, *args, **kwargs)))
  File "D:\trydjango\lib\site-packages\django\core\urlresolvers.py", line 508, in _reverse_with_prefix
    (lookup_view_s, args, kwargs, len(patterns), patterns))
NoReverseMatch: Reverse for 'detail' with arguments '()' and keyword arguments '{u'id': 1}' not found. 0 pattern(s) tried: []
[05/Feb/2019 15:07:35] "GET /posts/ HTTP/1.1" 500 136073
Performing system checks...

System check identified no issues (0 silenced).
February 05, 2019 - 15:07:50
Django version 1.9, using settings 'trydjango.settings'
Starting development server at http://127.0.0.1:8000/
Quit the server with CTRL-BREAK.
Internal Server Error: /posts/
Traceback (most recent call last):
  File "D:\trydjango\lib\site-packages\django\core\handlers\base.py", line 149, in get_response
    response = self.process_exception_by_middleware(e, request)
  File "D:\trydjango\lib\site-packages\django\core\handlers\base.py", line 147, in get_response
    response = wrapped_callback(request, *callback_args, **callback_kwargs)
  File "D:\trydjango\src\posts\views.py", line 25, in post_list
    return render(self,'index.html',context)
  File "D:\trydjango\lib\site-packages\django\shortcuts.py", line 67, in render
    template_name, context, request=request, using=using)
  File "D:\trydjango\lib\site-packages\django\template\loader.py", line 97, in render_to_string
    return template.render(context, request)
  File "D:\trydjango\lib\site-packages\django\template\backends\django.py", line 95, in render
    return self.template.render(context)
  File "D:\trydjango\lib\site-packages\django\template\base.py", line 206, in render
    return self._render(context)
  File "D:\trydjango\lib\site-packages\django\template\base.py", line 197, in _render
    return self.nodelist.render(context)
  File "D:\trydjango\lib\site-packages\django\template\base.py", line 988, in render
    bit = node.render_annotated(context)
  File "D:\trydjango\lib\site-packages\django\template\base.py", line 955, in render_annotated
    return self.render(context)
  File "D:\trydjango\lib\site-packages\django\template\defaulttags.py", line 220, in render
    nodelist.append(node.render_annotated(context))
  File "D:\trydjango\lib\site-packages\django\template\base.py", line 955, in render_annotated
    return self.render(context)
  File "D:\trydjango\lib\site-packages\django\template\defaulttags.py", line 513, in render
    six.reraise(*exc_info)
  File "D:\trydjango\lib\site-packages\django\template\defaulttags.py", line 499, in render
    url = reverse(view_name, args=args, kwargs=kwargs, current_app=current_app)
  File "D:\trydjango\lib\site-packages\django\core\urlresolvers.py", line 600, in reverse
    return force_text(iri_to_uri(resolver._reverse_with_prefix(view, prefix, *args, **kwargs)))
  File "D:\trydjango\lib\site-packages\django\core\urlresolvers.py", line 508, in _reverse_with_prefix
    (lookup_view_s, args, kwargs, len(patterns), patterns))
NoReverseMatch: Reverse for 'detail' with arguments '()' and keyword arguments '{u'id': 1}' not found. 0 pattern(s) tried: []
[05/Feb/2019 15:07:51] "GET /posts/ HTTP/1.1" 500 136073
[05/Feb/2019 15:08:51] "GET /posts/ HTTP/1.1" 200 2091
Performing system checks...

System check identified no issues (0 silenced).
February 05, 2019 - 15:30:51
Django version 1.9, using settings 'trydjango.settings'
Starting development server at http://127.0.0.1:8000/
Quit the server with CTRL-BREAK.
Internal Server Error: /posts/create/
Traceback (most recent call last):
  File "D:\trydjango\lib\site-packages\django\core\handlers\base.py", line 149, in get_response
    response = self.process_exception_by_middleware(e, request)
  File "D:\trydjango\lib\site-packages\django\core\handlers\base.py", line 147, in get_response
    response = wrapped_callback(request, *callback_args, **callback_kwargs)
  File "D:\trydjango\src\posts\views.py", line 11, in post_create
    return render(self,'post_form.html',context)
  File "D:\trydjango\lib\site-packages\django\shortcuts.py", line 67, in render
    template_name, context, request=request, using=using)
  File "D:\trydjango\lib\site-packages\django\template\loader.py", line 96, in render_to_string
    template = get_template(template_name, using=using)
  File "D:\trydjango\lib\site-packages\django\template\loader.py", line 32, in get_template
    return engine.get_template(template_name, dirs)
  File "D:\trydjango\lib\site-packages\django\template\backends\django.py", line 40, in get_template
    return Template(self.engine.get_template(template_name, dirs), self)
  File "D:\trydjango\lib\site-packages\django\template\engine.py", line 190, in get_template
    template, origin = self.find_template(template_name, dirs)
  File "D:\trydjango\lib\site-packages\django\template\engine.py", line 157, in find_template
    name, template_dirs=dirs, skip=skip,
  File "D:\trydjango\lib\site-packages\django\template\loaders\base.py", line 46, in get_template
    contents, origin, origin.template_name, self.engine,
  File "D:\trydjango\lib\site-packages\django\template\base.py", line 189, in __init__
    self.nodelist = self.compile_nodelist()
  File "D:\trydjango\lib\site-packages\django\template\base.py", line 230, in compile_nodelist
    return parser.parse()
  File "D:\trydjango\lib\site-packages\django\template\base.py", line 508, in parse
    self.invalid_block_tag(token, command, parse_until)
  File "D:\trydjango\lib\site-packages\django\template\base.py", line 568, in invalid_block_tag
    "or load this tag?" % (token.lineno, command)
TemplateSyntaxError: Invalid block tag on line 9: 'form.as_p'. Did you forget to register or load this tag?
[05/Feb/2019 15:32:06] "GET /posts/create/ HTTP/1.1" 500 115594
[05/Feb/2019 15:32:34] "GET /posts/create/ HTTP/1.1" 200 350
[05/Feb/2019 15:33:04] "GET /posts/create/ HTTP/1.1" 200 401
Forbidden (CSRF token missing or incorrect.): /posts/create/
[05/Feb/2019 15:33:59] "POST /posts/create/ HTTP/1.1" 403 2274
Forbidden (CSRF token missing or incorrect.): /posts/create/
[05/Feb/2019 15:34:18] "POST /posts/create/ HTTP/1.1" 403 2274
Forbidden (CSRF token missing or incorrect.): /posts/create/
[05/Feb/2019 15:34:25] "POST /posts/create/ HTTP/1.1" 403 2274
[05/Feb/2019 15:34:32] "GET /posts/create/ HTTP/1.1" 200 494
[05/Feb/2019 15:34:34] "POST /posts/create/ HTTP/1.1" 200 494
Performing system checks...

System check identified no issues (0 silenced).
February 05, 2019 - 15:35:40
Django version 1.9, using settings 'trydjango.settings'
Starting development server at http://127.0.0.1:8000/
Quit the server with CTRL-BREAK.
Internal Server Error: /posts/create/
Traceback (most recent call last):
  File "D:\trydjango\lib\site-packages\django\core\handlers\base.py", line 149, in get_response
    response = self.process_exception_by_middleware(e, request)
  File "D:\trydjango\lib\site-packages\django\core\handlers\base.py", line 147, in get_response
    response = wrapped_callback(request, *callback_args, **callback_kwargs)
  File "D:\trydjango\src\posts\views.py", line 11, in post_create
    if self.method == POST:
NameError: global name 'POST' is not defined
[05/Feb/2019 15:35:47] "POST /posts/create/ HTTP/1.1" 500 65636
Performing system checks...

System check identified no issues (0 silenced).
February 05, 2019 - 15:36:05
Django version 1.9, using settings 'trydjango.settings'
Starting development server at http://127.0.0.1:8000/
Quit the server with CTRL-BREAK.
<QueryDict: {u'content': [u'asdsa'], u'csrfmiddlewaretoken': [u'skbMdonkmave6NN3RLT8wkhDVWLj3ZXT'], u'submit': [u'Submit'], u'title': [u'a']}>
[05/Feb/2019 15:36:05] "POST /posts/create/ HTTP/1.1" 200 494
Performing system checks...

System check identified no issues (0 silenced).
February 05, 2019 - 15:38:30
Django version 1.9, using settings 'trydjango.settings'
Starting development server at http://127.0.0.1:8000/
Quit the server with CTRL-BREAK.
Performing system checks...

System check identified no issues (0 silenced).
February 05, 2019 - 15:38:55
Django version 1.9, using settings 'trydjango.settings'
Starting development server at http://127.0.0.1:8000/
Quit the server with CTRL-BREAK.
Internal Server Error: /posts/create/
Traceback (most recent call last):
  File "D:\trydjango\lib\site-packages\django\core\handlers\base.py", line 149, in get_response
    response = self.process_exception_by_middleware(e, request)
  File "D:\trydjango\lib\site-packages\django\core\handlers\base.py", line 147, in get_response
    response = wrapped_callback(request, *callback_args, **callback_kwargs)
  File "D:\trydjango\src\posts\views.py", line 7, in post_create
    form = PostForm(request.POST or none)
NameError: global name 'request' is not defined
[05/Feb/2019 15:39:11] "POST /posts/create/ HTTP/1.1" 500 65086
Performing system checks...

System check identified no issues (0 silenced).
February 05, 2019 - 15:39:25
Django version 1.9, using settings 'trydjango.settings'
Starting development server at http://127.0.0.1:8000/
Quit the server with CTRL-BREAK.
<QueryDict: {u'content': [u'Ravinder Baid is a true legend'], u'csrfmiddlewaretoken': [u'skbMdonkmave6NN3RLT8wkhDVWLj3ZXT'], u'submit': [u'Submit'], u'title': [u'Legend']}>
[05/Feb/2019 15:39:27] "POST /posts/create/ HTTP/1.1" 200 539
<QueryDict: {u'content': [u'Ravinder Baid is a true legend'], u'csrfmiddlewaretoken': [u'skbMdonkmave6NN3RLT8wkhDVWLj3ZXT'], u'submit': [u'Submit'], u'title': [u'Legend']}>
[05/Feb/2019 15:39:28] "POST /posts/create/ HTTP/1.1" 200 539
[05/Feb/2019 15:39:33] "GET /posts/ HTTP/1.1" 200 1744
<QueryDict: {u'content': [u'Ravinder Baid is a true legend'], u'csrfmiddlewaretoken': [u'skbMdonkmave6NN3RLT8wkhDVWLj3ZXT'], u'submit': [u'Submit'], u'title': [u'Legend']}>
[05/Feb/2019 15:40:05] "POST /posts/create/ HTTP/1.1" 200 539
<QueryDict: {u'content': [u'Ravinder Baid is a true legend'], u'csrfmiddlewaretoken': [u'skbMdonkmave6NN3RLT8wkhDVWLj3ZXT'], u'submit': [u'Submit'], u'title': [u'Legend']}>
[05/Feb/2019 15:40:08] "POST /posts/create/ HTTP/1.1" 200 539
[05/Feb/2019 15:40:10] "GET /posts/ HTTP/1.1" 200 2069
Performing system checks...

System check identified no issues (0 silenced).
February 05, 2019 - 15:41:30
Django version 1.9, using settings 'trydjango.settings'
Starting development server at http://127.0.0.1:8000/
Quit the server with CTRL-BREAK.
Internal Server Error: /posts/create/
Traceback (most recent call last):
  File "D:\trydjango\lib\site-packages\django\core\handlers\base.py", line 149, in get_response
    response = self.process_exception_by_middleware(e, request)
  File "D:\trydjango\lib\site-packages\django\core\handlers\base.py", line 147, in get_response
    response = wrapped_callback(request, *callback_args, **callback_kwargs)
  File "D:\trydjango\src\posts\views.py", line 7, in post_create
    form = PostForm(self.POST or none)
NameError: global name 'none' is not defined
[05/Feb/2019 15:41:43] "GET /posts/create/ HTTP/1.1" 500 63879
Performing system checks...

System check identified no issues (0 silenced).
February 05, 2019 - 15:42:08
Django version 1.9, using settings 'trydjango.settings'
Starting development server at http://127.0.0.1:8000/
Quit the server with CTRL-BREAK.
[05/Feb/2019 15:42:10] "GET /posts/create/ HTTP/1.1" 200 494
{'content': u'Hi hello how do you do', 'title': u'Creativity'}
[05/Feb/2019 15:42:30] "POST /posts/create/ HTTP/1.1" 200 535
Performing system checks...

System check identified no issues (0 silenced).
February 05, 2019 - 15:55:36
Django version 1.9, using settings 'trydjango.settings'
Starting development server at http://127.0.0.1:8000/
Quit the server with CTRL-BREAK.
Performing system checks...

System check identified no issues (0 silenced).
February 05, 2019 - 15:56:05
Django version 1.9, using settings 'trydjango.settings'
Starting development server at http://127.0.0.1:8000/
Quit the server with CTRL-BREAK.
[05/Feb/2019 16:00:09] "GET /posts/ HTTP/1.1" 200 2201
Internal Server Error: /posts/1/
Traceback (most recent call last):
  File "D:\trydjango\lib\site-packages\django\core\handlers\base.py", line 149, in get_response
    response = self.process_exception_by_middleware(e, request)
  File "D:\trydjango\lib\site-packages\django\core\handlers\base.py", line 147, in get_response
    response = wrapped_callback(request, *callback_args, **callback_kwargs)
  File "D:\trydjango\src\posts\views.py", line 26, in post_detail
    return render(self,'post_detail.html',context)
  File "D:\trydjango\lib\site-packages\django\shortcuts.py", line 67, in render
    template_name, context, request=request, using=using)
  File "D:\trydjango\lib\site-packages\django\template\loader.py", line 97, in render_to_string
    return template.render(context, request)
  File "D:\trydjango\lib\site-packages\django\template\backends\django.py", line 95, in render
    return self.template.render(context)
  File "D:\trydjango\lib\site-packages\django\template\base.py", line 206, in render
    return self._render(context)
  File "D:\trydjango\lib\site-packages\django\template\base.py", line 197, in _render
    return self.nodelist.render(context)
  File "D:\trydjango\lib\site-packages\django\template\base.py", line 988, in render
    bit = node.render_annotated(context)
  File "D:\trydjango\lib\site-packages\django\template\base.py", line 955, in render_annotated
    return self.render(context)
  File "D:\trydjango\lib\site-packages\django\template\defaulttags.py", line 513, in render
    six.reraise(*exc_info)
  File "D:\trydjango\lib\site-packages\django\template\defaulttags.py", line 499, in render
    url = reverse(view_name, args=args, kwargs=kwargs, current_app=current_app)
  File "D:\trydjango\lib\site-packages\django\core\urlresolvers.py", line 600, in reverse
    return force_text(iri_to_uri(resolver._reverse_with_prefix(view, prefix, *args, **kwargs)))
  File "D:\trydjango\lib\site-packages\django\core\urlresolvers.py", line 508, in _reverse_with_prefix
    (lookup_view_s, args, kwargs, len(patterns), patterns))
NoReverseMatch: Reverse for 'update' with arguments '()' and keyword arguments '{u'id': 1}' not found. 0 pattern(s) tried: []
[05/Feb/2019 16:00:13] "GET /posts/1/ HTTP/1.1" 500 121298
Performing system checks...

System check identified no issues (0 silenced).
February 05, 2019 - 16:01:08
Django version 1.9, using settings 'trydjango.settings'
Starting development server at http://127.0.0.1:8000/
Quit the server with CTRL-BREAK.
Internal Server Error: /posts/1/
Traceback (most recent call last):
  File "D:\trydjango\lib\site-packages\django\core\handlers\base.py", line 149, in get_response
    response = self.process_exception_by_middleware(e, request)
  File "D:\trydjango\lib\site-packages\django\core\handlers\base.py", line 147, in get_response
    response = wrapped_callback(request, *callback_args, **callback_kwargs)
  File "D:\trydjango\src\posts\views.py", line 26, in post_detail
    return render(self,'post_detail.html',context)
  File "D:\trydjango\lib\site-packages\django\shortcuts.py", line 67, in render
    template_name, context, request=request, using=using)
  File "D:\trydjango\lib\site-packages\django\template\loader.py", line 97, in render_to_string
    return template.render(context, request)
  File "D:\trydjango\lib\site-packages\django\template\backends\django.py", line 95, in render
    return self.template.render(context)
  File "D:\trydjango\lib\site-packages\django\template\base.py", line 206, in render
    return self._render(context)
  File "D:\trydjango\lib\site-packages\django\template\base.py", line 197, in _render
    return self.nodelist.render(context)
  File "D:\trydjango\lib\site-packages\django\template\base.py", line 988, in render
    bit = node.render_annotated(context)
  File "D:\trydjango\lib\site-packages\django\template\base.py", line 955, in render_annotated
    return self.render(context)
  File "D:\trydjango\lib\site-packages\django\template\defaulttags.py", line 513, in render
    six.reraise(*exc_info)
  File "D:\trydjango\lib\site-packages\django\template\defaulttags.py", line 499, in render
    url = reverse(view_name, args=args, kwargs=kwargs, current_app=current_app)
  File "D:\trydjango\lib\site-packages\django\core\urlresolvers.py", line 600, in reverse
    return force_text(iri_to_uri(resolver._reverse_with_prefix(view, prefix, *args, **kwargs)))
  File "D:\trydjango\lib\site-packages\django\core\urlresolvers.py", line 508, in _reverse_with_prefix
    (lookup_view_s, args, kwargs, len(patterns), patterns))
NoReverseMatch: Reverse for 'update' with arguments '()' and keyword arguments '{u'id': 1}' not found. 0 pattern(s) tried: []
[05/Feb/2019 16:01:27] "GET /posts/1/ HTTP/1.1" 500 121433
[05/Feb/2019 16:01:31] "GET /posts/ HTTP/1.1" 200 2201
[05/Feb/2019 16:01:32] "GET /posts/ HTTP/1.1" 200 2201
[05/Feb/2019 16:01:32] "GET /posts/ HTTP/1.1" 200 2201
[05/Feb/2019 16:01:33] "GET /posts/ HTTP/1.1" 200 2201
Internal Server Error: /posts/1/
Traceback (most recent call last):
  File "D:\trydjango\lib\site-packages\django\core\handlers\base.py", line 149, in get_response
    response = self.process_exception_by_middleware(e, request)
  File "D:\trydjango\lib\site-packages\django\core\handlers\base.py", line 147, in get_response
    response = wrapped_callback(request, *callback_args, **callback_kwargs)
  File "D:\trydjango\src\posts\views.py", line 26, in post_detail
    return render(self,'post_detail.html',context)
  File "D:\trydjango\lib\site-packages\django\shortcuts.py", line 67, in render
    template_name, context, request=request, using=using)
  File "D:\trydjango\lib\site-packages\django\template\loader.py", line 97, in render_to_string
    return template.render(context, request)
  File "D:\trydjango\lib\site-packages\django\template\backends\django.py", line 95, in render
    return self.template.render(context)
  File "D:\trydjango\lib\site-packages\django\template\base.py", line 206, in render
    return self._render(context)
  File "D:\trydjango\lib\site-packages\django\template\base.py", line 197, in _render
    return self.nodelist.render(context)
  File "D:\trydjango\lib\site-packages\django\template\base.py", line 988, in render
    bit = node.render_annotated(context)
  File "D:\trydjango\lib\site-packages\django\template\base.py", line 955, in render_annotated
    return self.render(context)
  File "D:\trydjango\lib\site-packages\django\template\defaulttags.py", line 513, in render
    six.reraise(*exc_info)
  File "D:\trydjango\lib\site-packages\django\template\defaulttags.py", line 499, in render
    url = reverse(view_name, args=args, kwargs=kwargs, current_app=current_app)
  File "D:\trydjango\lib\site-packages\django\core\urlresolvers.py", line 600, in reverse
    return force_text(iri_to_uri(resolver._reverse_with_prefix(view, prefix, *args, **kwargs)))
  File "D:\trydjango\lib\site-packages\django\core\urlresolvers.py", line 508, in _reverse_with_prefix
    (lookup_view_s, args, kwargs, len(patterns), patterns))
NoReverseMatch: Reverse for 'update' with arguments '()' and keyword arguments '{u'id': 1}' not found. 0 pattern(s) tried: []
[05/Feb/2019 16:01:33] "GET /posts/1/ HTTP/1.1" 500 121298
[05/Feb/2019 16:03:24] "GET /posts/1/ HTTP/1.1" 200 201
Internal Server Error: /posts/1/edit/
Traceback (most recent call last):
  File "D:\trydjango\lib\site-packages\django\core\handlers\base.py", line 149, in get_response
    response = self.process_exception_by_middleware(e, request)
  File "D:\trydjango\lib\site-packages\django\core\handlers\base.py", line 147, in get_response
    response = wrapped_callback(request, *callback_args, **callback_kwargs)
TypeError: post_update() got an unexpected keyword argument 'id'
[05/Feb/2019 16:03:43] "GET /posts/1/edit/ HTTP/1.1" 500 60989
Performing system checks...

System check identified no issues (0 silenced).
February 05, 2019 - 16:04:09
Django version 1.9, using settings 'trydjango.settings'
Starting development server at http://127.0.0.1:8000/
Quit the server with CTRL-BREAK.
[05/Feb/2019 16:04:09] "GET /posts/1/edit/ HTTP/1.1" 200 522
Internal Server Error: /posts/1/
Traceback (most recent call last):
  File "D:\trydjango\lib\site-packages\django\core\handlers\base.py", line 149, in get_response
    response = self.process_exception_by_middleware(e, request)
  File "D:\trydjango\lib\site-packages\django\core\handlers\base.py", line 147, in get_response
    response = wrapped_callback(request, *callback_args, **callback_kwargs)
  File "D:\trydjango\src\posts\views.py", line 26, in post_detail
    return render(self,'post_detail.html',context)
  File "D:\trydjango\lib\site-packages\django\shortcuts.py", line 67, in render
    template_name, context, request=request, using=using)
  File "D:\trydjango\lib\site-packages\django\template\loader.py", line 97, in render_to_string
    return template.render(context, request)
  File "D:\trydjango\lib\site-packages\django\template\backends\django.py", line 95, in render
    return self.template.render(context)
  File "D:\trydjango\lib\site-packages\django\template\base.py", line 206, in render
    return self._render(context)
  File "D:\trydjango\lib\site-packages\django\template\base.py", line 197, in _render
    return self.nodelist.render(context)
  File "D:\trydjango\lib\site-packages\django\template\base.py", line 988, in render
    bit = node.render_annotated(context)
  File "D:\trydjango\lib\site-packages\django\template\base.py", line 955, in render_annotated
    return self.render(context)
  File "D:\trydjango\lib\site-packages\django\template\defaulttags.py", line 513, in render
    six.reraise(*exc_info)
  File "D:\trydjango\lib\site-packages\django\template\defaulttags.py", line 499, in render
    url = reverse(view_name, args=args, kwargs=kwargs, current_app=current_app)
  File "D:\trydjango\lib\site-packages\django\core\urlresolvers.py", line 600, in reverse
    return force_text(iri_to_uri(resolver._reverse_with_prefix(view, prefix, *args, **kwargs)))
  File "D:\trydjango\lib\site-packages\django\core\urlresolvers.py", line 508, in _reverse_with_prefix
    (lookup_view_s, args, kwargs, len(patterns), patterns))
NoReverseMatch: Reverse for 'update' with arguments '()' and keyword arguments '{u'id': 1}' not found. 0 pattern(s) tried: []
[05/Feb/2019 16:04:21] "GET /posts/1/ HTTP/1.1" 500 121433
Internal Server Error: /posts/1/
Traceback (most recent call last):
  File "D:\trydjango\lib\site-packages\django\core\handlers\base.py", line 149, in get_response
    response = self.process_exception_by_middleware(e, request)
  File "D:\trydjango\lib\site-packages\django\core\handlers\base.py", line 147, in get_response
    response = wrapped_callback(request, *callback_args, **callback_kwargs)
  File "D:\trydjango\src\posts\views.py", line 26, in post_detail
    return render(self,'post_detail.html',context)
  File "D:\trydjango\lib\site-packages\django\shortcuts.py", line 67, in render
    template_name, context, request=request, using=using)
  File "D:\trydjango\lib\site-packages\django\template\loader.py", line 97, in render_to_string
    return template.render(context, request)
  File "D:\trydjango\lib\site-packages\django\template\backends\django.py", line 95, in render
    return self.template.render(context)
  File "D:\trydjango\lib\site-packages\django\template\base.py", line 206, in render
    return self._render(context)
  File "D:\trydjango\lib\site-packages\django\template\base.py", line 197, in _render
    return self.nodelist.render(context)
  File "D:\trydjango\lib\site-packages\django\template\base.py", line 988, in render
    bit = node.render_annotated(context)
  File "D:\trydjango\lib\site-packages\django\template\base.py", line 955, in render_annotated
    return self.render(context)
  File "D:\trydjango\lib\site-packages\django\template\defaulttags.py", line 513, in render
    six.reraise(*exc_info)
  File "D:\trydjango\lib\site-packages\django\template\defaulttags.py", line 499, in render
    url = reverse(view_name, args=args, kwargs=kwargs, current_app=current_app)
  File "D:\trydjango\lib\site-packages\django\core\urlresolvers.py", line 600, in reverse
    return force_text(iri_to_uri(resolver._reverse_with_prefix(view, prefix, *args, **kwargs)))
  File "D:\trydjango\lib\site-packages\django\core\urlresolvers.py", line 508, in _reverse_with_prefix
    (lookup_view_s, args, kwargs, len(patterns), patterns))
NoReverseMatch: Reverse for 'update' with arguments '()' and keyword arguments '{u'id': 1}' not found. 0 pattern(s) tried: []
[05/Feb/2019 16:05:09] "GET /posts/1/ HTTP/1.1" 500 121486
[05/Feb/2019 16:05:23] "GET /posts/1/ HTTP/1.1" 200 201
[05/Feb/2019 16:05:29] "GET /posts/1/edit/ HTTP/1.1" 200 522
[05/Feb/2019 16:05:40] "POST /posts/1/edit/ HTTP/1.1" 302 0
[05/Feb/2019 16:05:40] "GET /posts/1/ HTTP/1.1" 200 201
[05/Feb/2019 16:05:50] "GET /posts/1/ HTTP/1.1" 200 222
[05/Feb/2019 16:06:25] "GET /posts/1/ HTTP/1.1" 200 231
[05/Feb/2019 19:00:47] "GET /posts/ HTTP/1.1" 200 2213
[05/Feb/2019 19:00:55] "GET /posts/1/ HTTP/1.1" 200 231
Performing system checks...

Unhandled exception in thread started by <function wrapper at 0x0000000006B1FC88>
Traceback (most recent call last):
  File "D:\trydjango\lib\site-packages\django\utils\autoreload.py", line 226, in wrapper
    fn(*args, **kwargs)
  File "D:\trydjango\lib\site-packages\django\core\management\commands\runserver.py", line 116, in inner_run
    self.check(display_num_errors=True)
  File "D:\trydjango\lib\site-packages\django\core\management\base.py", line 426, in check
    include_deployment_checks=include_deployment_checks,
  File "D:\trydjango\lib\site-packages\django\core\checks\registry.py", line 75, in run_checks
    new_errors = check(app_configs=app_configs)
  File "D:\trydjango\lib\site-packages\django\core\checks\urls.py", line 10, in check_url_config
    return check_resolver(resolver)
  File "D:\trydjango\lib\site-packages\django\core\checks\urls.py", line 19, in check_resolver
    for pattern in resolver.url_patterns:
  File "D:\trydjango\lib\site-packages\django\utils\functional.py", line 33, in __get__
    res = instance.__dict__[self.name] = self.func(instance)
  File "D:\trydjango\lib\site-packages\django\core\urlresolvers.py", line 417, in url_patterns
    patterns = getattr(self.urlconf_module, "urlpatterns", self.urlconf_module)
  File "D:\trydjango\lib\site-packages\django\utils\functional.py", line 33, in __get__
    res = instance.__dict__[self.name] = self.func(instance)
  File "D:\trydjango\lib\site-packages\django\core\urlresolvers.py", line 410, in urlconf_module
    return import_module(self.urlconf_name)
  File "c:\programdata\anaconda2\Lib\importlib\__init__.py", line 37, in import_module
    __import__(name)
  File "D:\trydjango\src\trydjango\urls.py", line 24, in <module>
    url(r'^posts/', include("posts.urls", namespace="posts")),
  File "D:\trydjango\lib\site-packages\django\conf\urls\__init__.py", line 52, in include
    urlconf_module = import_module(urlconf_module)
  File "c:\programdata\anaconda2\Lib\importlib\__init__.py", line 37, in import_module
    __import__(name)
  File "D:\trydjango\src\posts\urls.py", line 4, in <module>
    from .views import (
  File "D:\trydjango\src\posts\views.py", line 1, in <module>
    from django.http import HttpResponse, HttpResponseRedirect, redirect
ImportError: cannot import name redirect
Performing system checks...

Unhandled exception in thread started by <function wrapper at 0x00000000071BAC88>
Traceback (most recent call last):
  File "D:\trydjango\lib\site-packages\django\utils\autoreload.py", line 226, in wrapper
    fn(*args, **kwargs)
  File "D:\trydjango\lib\site-packages\django\core\management\commands\runserver.py", line 116, in inner_run
    self.check(display_num_errors=True)
  File "D:\trydjango\lib\site-packages\django\core\management\base.py", line 426, in check
    include_deployment_checks=include_deployment_checks,
  File "D:\trydjango\lib\site-packages\django\core\checks\registry.py", line 75, in run_checks
    new_errors = check(app_configs=app_configs)
  File "D:\trydjango\lib\site-packages\django\core\checks\urls.py", line 10, in check_url_config
    return check_resolver(resolver)
  File "D:\trydjango\lib\site-packages\django\core\checks\urls.py", line 19, in check_resolver
    for pattern in resolver.url_patterns:
  File "D:\trydjango\lib\site-packages\django\utils\functional.py", line 33, in __get__
    res = instance.__dict__[self.name] = self.func(instance)
  File "D:\trydjango\lib\site-packages\django\core\urlresolvers.py", line 417, in url_patterns
    patterns = getattr(self.urlconf_module, "urlpatterns", self.urlconf_module)
  File "D:\trydjango\lib\site-packages\django\utils\functional.py", line 33, in __get__
    res = instance.__dict__[self.name] = self.func(instance)
  File "D:\trydjango\lib\site-packages\django\core\urlresolvers.py", line 410, in urlconf_module
    return import_module(self.urlconf_name)
  File "c:\programdata\anaconda2\Lib\importlib\__init__.py", line 37, in import_module
    __import__(name)
  File "D:\trydjango\src\trydjango\urls.py", line 24, in <module>
    url(r'^posts/', include("posts.urls", namespace="posts")),
  File "D:\trydjango\lib\site-packages\django\conf\urls\__init__.py", line 52, in include
    urlconf_module = import_module(urlconf_module)
  File "c:\programdata\anaconda2\Lib\importlib\__init__.py", line 37, in import_module
    __import__(name)
  File "D:\trydjango\src\posts\urls.py", line 4, in <module>
    from .views import (
  File "D:\trydjango\src\posts\views.py", line 1, in <module>
    from django.http import HttpResponse, HttpResponseRedirect, redirect
ImportError: cannot import name redirect
Performing system checks...

System check identified no issues (0 silenced).
February 05, 2019 - 19:07:07
Django version 1.9, using settings 'trydjango.settings'
Starting development server at http://127.0.0.1:8000/
Quit the server with CTRL-BREAK.
Not Found: /posts/delete/1/
[05/Feb/2019 19:07:17] "GET /posts/delete/1/ HTTP/1.1" 404 2846
Internal Server Error: /posts/delete/1
Traceback (most recent call last):
  File "D:\trydjango\lib\site-packages\django\core\handlers\base.py", line 149, in get_response
    response = self.process_exception_by_middleware(e, request)
  File "D:\trydjango\lib\site-packages\django\core\handlers\base.py", line 147, in get_response
    response = wrapped_callback(request, *callback_args, **callback_kwargs)
  File "D:\trydjango\src\posts\views.py", line 58, in post_delete
    messages.success("Successfully deleted")
TypeError: success() takes at least 2 arguments (1 given)
[05/Feb/2019 19:07:26] "GET /posts/delete/1 HTTP/1.1" 500 64025
Performing system checks...

System check identified no issues (0 silenced).
February 05, 2019 - 19:08:06
Django version 1.9, using settings 'trydjango.settings'
Starting development server at http://127.0.0.1:8000/
Quit the server with CTRL-BREAK.
Internal Server Error: /posts/delete/1
Traceback (most recent call last):
  File "D:\trydjango\lib\site-packages\django\core\handlers\base.py", line 149, in get_response
    response = self.process_exception_by_middleware(e, request)
  File "D:\trydjango\lib\site-packages\django\core\handlers\base.py", line 147, in get_response
    response = wrapped_callback(request, *callback_args, **callback_kwargs)
  File "D:\trydjango\src\posts\views.py", line 59, in post_delete
    return redirect("posts:lists")
  File "D:\trydjango\lib\site-packages\django\shortcuts.py", line 116, in redirect
    return redirect_class(resolve_url(to, *args, **kwargs))
  File "D:\trydjango\lib\site-packages\django\shortcuts.py", line 204, in resolve_url
    return urlresolvers.reverse(to, args=args, kwargs=kwargs)
  File "D:\trydjango\lib\site-packages\django\core\urlresolvers.py", line 600, in reverse
    return force_text(iri_to_uri(resolver._reverse_with_prefix(view, prefix, *args, **kwargs)))
  File "D:\trydjango\lib\site-packages\django\core\urlresolvers.py", line 508, in _reverse_with_prefix
    (lookup_view_s, args, kwargs, len(patterns), patterns))
NoReverseMatch: Reverse for 'lists' with arguments '()' and keyword arguments '{}' not found. 0 pattern(s) tried: []
[05/Feb/2019 19:08:15] "GET /posts/delete/1 HTTP/1.1" 500 83611
Performing system checks...

System check identified no issues (0 silenced).
February 05, 2019 - 19:09:04
Django version 1.9, using settings 'trydjango.settings'
Starting development server at http://127.0.0.1:8000/
Quit the server with CTRL-BREAK.
[05/Feb/2019 19:09:08] "GET /posts/delete/1 HTTP/1.1" 302 0
[05/Feb/2019 19:09:08] "GET /posts/ HTTP/1.1" 200 2213
[05/Feb/2019 19:09:19] "GET /posts/delete/1 HTTP/1.1" 302 0
[05/Feb/2019 19:09:19] "GET /posts/ HTTP/1.1" 200 2213
Performing system checks...

System check identified no issues (0 silenced).
February 05, 2019 - 19:09:36
Django version 1.9, using settings 'trydjango.settings'
Starting development server at http://127.0.0.1:8000/
Quit the server with CTRL-BREAK.
Performing system checks...

System check identified no issues (0 silenced).
February 05, 2019 - 19:10:37
Django version 1.9, using settings 'trydjango.settings'
Starting development server at http://127.0.0.1:8000/
Quit the server with CTRL-BREAK.
Internal Server Error: /posts/delete/1
Traceback (most recent call last):
  File "D:\trydjango\lib\site-packages\django\core\handlers\base.py", line 149, in get_response
    response = self.process_exception_by_middleware(e, request)
  File "D:\trydjango\lib\site-packages\django\core\handlers\base.py", line 147, in get_response
    response = wrapped_callback(request, *callback_args, **callback_kwargs)
  File "D:\trydjango\src\posts\views.py", line 58, in post_delete
    queryset.deleted()
AttributeError: 'Post' object has no attribute 'deleted'
[05/Feb/2019 19:10:48] "GET /posts/delete/1 HTTP/1.1" 500 64916
Internal Server Error: /posts/delete/2
Traceback (most recent call last):
  File "D:\trydjango\lib\site-packages\django\core\handlers\base.py", line 149, in get_response
    response = self.process_exception_by_middleware(e, request)
  File "D:\trydjango\lib\site-packages\django\core\handlers\base.py", line 147, in get_response
    response = wrapped_callback(request, *callback_args, **callback_kwargs)
  File "D:\trydjango\src\posts\views.py", line 58, in post_delete
    queryset.deleted()
AttributeError: 'Post' object has no attribute 'deleted'
[05/Feb/2019 19:11:23] "GET /posts/delete/2 HTTP/1.1" 500 64894
Performing system checks...

System check identified no issues (0 silenced).
February 05, 2019 - 19:12:11
Django version 1.9, using settings 'trydjango.settings'
Starting development server at http://127.0.0.1:8000/
Quit the server with CTRL-BREAK.
[05/Feb/2019 19:12:31] "GET /posts/2/ HTTP/1.1" 200 209
Not Found: /posts/delete/2/
[05/Feb/2019 19:12:40] "GET /posts/delete/2/ HTTP/1.1" 404 2846
[05/Feb/2019 19:12:53] "GET /posts/delete/2 HTTP/1.1" 302 0
[05/Feb/2019 19:12:53] "GET /posts/ HTTP/1.1" 200 2106
[06/Feb/2019 10:54:30] "GET /posts/ HTTP/1.1" 200 2106
[06/Feb/2019 10:54:32] "GET /posts/1/ HTTP/1.1" 200 499
Not Found: /posts/1/delete
[06/Feb/2019 10:54:44] "GET /posts/1/delete HTTP/1.1" 404 2843
Not Found: /posts/delete/1/
[06/Feb/2019 10:54:59] "GET /posts/delete/1/ HTTP/1.1" 404 2846
[06/Feb/2019 10:55:07] "GET /posts/delete/1 HTTP/1.1" 302 0
[06/Feb/2019 10:55:07] "GET /posts/ HTTP/1.1" 200 1977
[06/Feb/2019 10:55:12] "GET /posts/3/ HTTP/1.1" 200 304
Performing system checks...

System check identified no issues (0 silenced).
February 06, 2019 - 11:10:46
Django version 1.9, using settings 'trydjango.settings'
Starting development server at http://127.0.0.1:8000/
Quit the server with CTRL-BREAK.
[06/Feb/2019 11:10:56] "GET /posts/3/ HTTP/1.1" 200 209
[06/Feb/2019 11:10:59] "GET /posts/ HTTP/1.1" 200 2011
Internal Server Error: /posts/create/
Traceback (most recent call last):
  File "D:\trydjango\lib\site-packages\django\core\handlers\base.py", line 149, in get_response
    response = self.process_exception_by_middleware(e, request)
  File "D:\trydjango\lib\site-packages\django\core\handlers\base.py", line 147, in get_response
    response = wrapped_callback(request, *callback_args, **callback_kwargs)
  File "D:\trydjango\src\posts\views.py", line 19, in post_create
    return render(self,'post_form.html',context)
  File "D:\trydjango\lib\site-packages\django\shortcuts.py", line 67, in render
    template_name, context, request=request, using=using)
  File "D:\trydjango\lib\site-packages\django\template\loader.py", line 96, in render_to_string
    template = get_template(template_name, using=using)
  File "D:\trydjango\lib\site-packages\django\template\loader.py", line 32, in get_template
    return engine.get_template(template_name, dirs)
  File "D:\trydjango\lib\site-packages\django\template\backends\django.py", line 40, in get_template
    return Template(self.engine.get_template(template_name, dirs), self)
  File "D:\trydjango\lib\site-packages\django\template\engine.py", line 190, in get_template
    template, origin = self.find_template(template_name, dirs)
  File "D:\trydjango\lib\site-packages\django\template\engine.py", line 157, in find_template
    name, template_dirs=dirs, skip=skip,
  File "D:\trydjango\lib\site-packages\django\template\loaders\base.py", line 46, in get_template
    contents, origin, origin.template_name, self.engine,
  File "D:\trydjango\lib\site-packages\django\template\base.py", line 189, in __init__
    self.nodelist = self.compile_nodelist()
  File "D:\trydjango\lib\site-packages\django\template\base.py", line 230, in compile_nodelist
    return parser.parse()
  File "D:\trydjango\lib\site-packages\django\template\base.py", line 514, in parse
    raise self.error(token, e)
TemplateSyntaxError: Invalid block tag on line 10: 'enblock', expected 'endblock'. Did you forget to register or load this tag?
[06/Feb/2019 11:12:52] "GET /posts/create/ HTTP/1.1" 500 112521
[06/Feb/2019 11:13:23] "GET /posts/create/ HTTP/1.1" 200 544
[06/Feb/2019 11:17:40] "GET /posts/ HTTP/1.1" 200 2008
[06/Feb/2019 11:17:42] "GET /posts/3/ HTTP/1.1" 200 274
[06/Feb/2019 11:21:03] "GET /posts/3/ HTTP/1.1" 200 306
[06/Feb/2019 11:21:10] "GET /posts/ HTTP/1.1" 200 2024
[06/Feb/2019 11:23:39] "GET /posts/ HTTP/1.1" 200 154
Performing system checks...

System check identified no issues (0 silenced).
February 06, 2019 - 11:24:09
Django version 1.9, using settings 'trydjango.settings'
Starting development server at http://127.0.0.1:8000/
Quit the server with CTRL-BREAK.
[06/Feb/2019 11:24:09] "GET /posts/ HTTP/1.1" 200 2038
[06/Feb/2019 11:24:12] "GET /posts/3/ HTTP/1.1" 200 306
[06/Feb/2019 11:27:16] "GET /posts/create/ HTTP/1.1" 200 576
[06/Feb/2019 11:27:32] "POST /posts/create/ HTTP/1.1" 302 0
[06/Feb/2019 11:27:32] "GET /posts/19/ HTTP/1.1" 200 327
[06/Feb/2019 11:27:38] "GET /posts/ HTTP/1.1" 200 2165
[06/Feb/2019 11:27:41] "GET /posts/3/ HTTP/1.1" 200 307
Performing system checks...

System check identified no issues (0 silenced).
February 06, 2019 - 11:29:40
Django version 1.9, using settings 'trydjango.settings'
Starting development server at http://127.0.0.1:8000/
Quit the server with CTRL-BREAK.
[06/Feb/2019 11:29:46] "GET /posts/ HTTP/1.1" 200 2165
[06/Feb/2019 11:29:47] "GET /posts/create/ HTTP/1.1" 200 702
[06/Feb/2019 11:29:59] "POST /posts/create/ HTTP/1.1" 302 0
[06/Feb/2019 11:29:59] "GET /posts/20/ HTTP/1.1" 200 448
Performing system checks...

System check identified no issues (0 silenced).
February 06, 2019 - 13:57:33
Django version 1.9, using settings 'trydjango.settings'
Starting development server at http://127.0.0.1:8000/
Quit the server with CTRL-BREAK.
Performing system checks...

Unhandled exception in thread started by <function wrapper at 0x000000000689CC88>
Traceback (most recent call last):
  File "D:\trydjango\lib\site-packages\django\utils\autoreload.py", line 226, in wrapper
    fn(*args, **kwargs)
  File "D:\trydjango\lib\site-packages\django\core\management\commands\runserver.py", line 116, in inner_run
    self.check(display_num_errors=True)
  File "D:\trydjango\lib\site-packages\django\core\management\base.py", line 426, in check
    include_deployment_checks=include_deployment_checks,
  File "D:\trydjango\lib\site-packages\django\core\checks\registry.py", line 75, in run_checks
    new_errors = check(app_configs=app_configs)
  File "D:\trydjango\lib\site-packages\django\core\checks\urls.py", line 10, in check_url_config
    return check_resolver(resolver)
  File "D:\trydjango\lib\site-packages\django\core\checks\urls.py", line 19, in check_resolver
    for pattern in resolver.url_patterns:
  File "D:\trydjango\lib\site-packages\django\utils\functional.py", line 33, in __get__
    res = instance.__dict__[self.name] = self.func(instance)
  File "D:\trydjango\lib\site-packages\django\core\urlresolvers.py", line 417, in url_patterns
    patterns = getattr(self.urlconf_module, "urlpatterns", self.urlconf_module)
  File "D:\trydjango\lib\site-packages\django\utils\functional.py", line 33, in __get__
    res = instance.__dict__[self.name] = self.func(instance)
  File "D:\trydjango\lib\site-packages\django\core\urlresolvers.py", line 410, in urlconf_module
    return import_module(self.urlconf_name)
  File "c:\programdata\anaconda2\Lib\importlib\__init__.py", line 37, in import_module
    __import__(name)
  File "D:\trydjango\src\trydjango\urls.py", line 30, in <module>
    urlpatterns+=+ static(settings.STATIC_URL, document_root=settings.STATIC_ROOT)
TypeError: bad operand type for unary +: 'list'
Performing system checks...

System check identified no issues (0 silenced).
February 06, 2019 - 13:59:37
Django version 1.9, using settings 'trydjango.settings'
Starting development server at http://127.0.0.1:8000/
Quit the server with CTRL-BREAK.
^C
(trydjango) D:\trydjango\src>python manage.py collectstatic
Traceback (most recent call last):
  File "manage.py", line 10, in <module>
    execute_from_command_line(sys.argv)
  File "D:\trydjango\lib\site-packages\django\core\management\__init__.py", line 350, in execute_from_command_line
    utility.execute()
  File "D:\trydjango\lib\site-packages\django\core\management\__init__.py", line 342, in execute
    self.fetch_command(subcommand).run_from_argv(self.argv)
  File "D:\trydjango\lib\site-packages\django\core\management\__init__.py", line 195, in fetch_command
    klass = load_command_class(app_name, subcommand)
  File "D:\trydjango\lib\site-packages\django\core\management\__init__.py", line 40, in load_command_class
    return module.Command()
  File "D:\trydjango\lib\site-packages\django\contrib\staticfiles\management\commands\collectstatic.py", line 32, in __init__
    self.storage.path('')
  File "D:\trydjango\lib\site-packages\django\contrib\staticfiles\storage.py", line 48, in path
    raise ImproperlyConfigured("You're using the staticfiles app "
django.core.exceptions.ImproperlyConfigured: You're using the staticfiles app without having set the STATIC_ROOT setting to a filesystem path.

(trydjango) D:\trydjango\src>python manage.py collectstatic

You have requested to collect static files at the destination
location as specified in your settings:

    D:\trydjango\static_cdn

This will overwrite existing files!
Are you sure you want to do this?

Type 'yes' to continue, or 'no' to cancel: yes
Traceback (most recent call last):
  File "manage.py", line 10, in <module>
    execute_from_command_line(sys.argv)
  File "D:\trydjango\lib\site-packages\django\core\management\__init__.py", line 350, in execute_from_command_line
    utility.execute()
  File "D:\trydjango\lib\site-packages\django\core\management\__init__.py", line 342, in execute
    self.fetch_command(subcommand).run_from_argv(self.argv)
  File "D:\trydjango\lib\site-packages\django\core\management\base.py", line 348, in run_from_argv
    self.execute(*args, **cmd_options)
  File "D:\trydjango\lib\site-packages\django\core\management\base.py", line 399, in execute
    output = self.handle(*args, **options)
  File "D:\trydjango\lib\site-packages\django\contrib\staticfiles\management\commands\collectstatic.py", line 176, in handle
    collected = self.collect()
  File "D:\trydjango\lib\site-packages\django\contrib\staticfiles\management\commands\collectstatic.py", line 98, in collect
    for path, storage in finder.list(self.ignore_patterns):
  File "D:\trydjango\lib\site-packages\django\contrib\staticfiles\finders.py", line 112, in list
    for path in utils.get_files(storage, ignore_patterns):
  File "D:\trydjango\lib\site-packages\django\contrib\staticfiles\utils.py", line 28, in get_files
    directories, files = storage.listdir(location)
  File "D:\trydjango\lib\site-packages\django\core\files\storage.py", line 299, in listdir
    for entry in os.listdir(path):
WindowsError: [Error 3] The system cannot find the path specified: u'D:\\trydjango\\src\\static\\*.*'

(trydjango) D:\trydjango\src>python manage.py collectstatic

You have requested to collect static files at the destination
location as specified in your settings:

    D:\trydjango\static_cdn

This will overwrite existing files!
Are you sure you want to do this?

Type 'yes' to continue, or 'no' to cancel: yes
Copying 'D:\trydjango\lib\site-packages\django\contrib\admin\static\admin\css\base.css'
Copying 'D:\trydjango\lib\site-packages\django\contrib\admin\static\admin\css\changelists.css'
Copying 'D:\trydjango\lib\site-packages\django\contrib\admin\static\admin\css\dashboard.css'
Copying 'D:\trydjango\lib\site-packages\django\contrib\admin\static\admin\css\fonts.css'
Copying 'D:\trydjango\lib\site-packages\django\contrib\admin\static\admin\css\forms.css'
Copying 'D:\trydjango\lib\site-packages\django\contrib\admin\static\admin\css\login.css'
Copying 'D:\trydjango\lib\site-packages\django\contrib\admin\static\admin\css\rtl.css'
Copying 'D:\trydjango\lib\site-packages\django\contrib\admin\static\admin\css\widgets.css'
Copying 'D:\trydjango\lib\site-packages\django\contrib\admin\static\admin\fonts\LICENSE.txt'
Copying 'D:\trydjango\lib\site-packages\django\contrib\admin\static\admin\fonts\README.txt'
Copying 'D:\trydjango\lib\site-packages\django\contrib\admin\static\admin\fonts\Roboto-Bold-webfont.woff'
Copying 'D:\trydjango\lib\site-packages\django\contrib\admin\static\admin\fonts\Roboto-Light-webfont.woff'
Copying 'D:\trydjango\lib\site-packages\django\contrib\admin\static\admin\fonts\Roboto-Regular-webfont.woff'
Copying 'D:\trydjango\lib\site-packages\django\contrib\admin\static\admin\img\calendar-icons.svg'
Copying 'D:\trydjango\lib\site-packages\django\contrib\admin\static\admin\img\icon-addlink.svg'
Copying 'D:\trydjango\lib\site-packages\django\contrib\admin\static\admin\img\icon-alert.svg'
Copying 'D:\trydjango\lib\site-packages\django\contrib\admin\static\admin\img\icon-calendar.svg'
Copying 'D:\trydjango\lib\site-packages\django\contrib\admin\static\admin\img\icon-changelink.svg'
Copying 'D:\trydjango\lib\site-packages\django\contrib\admin\static\admin\img\icon-clock.svg'
Copying 'D:\trydjango\lib\site-packages\django\contrib\admin\static\admin\img\icon-deletelink.svg'
Copying 'D:\trydjango\lib\site-packages\django\contrib\admin\static\admin\img\icon-no.svg'
Copying 'D:\trydjango\lib\site-packages\django\contrib\admin\static\admin\img\icon-unknown-alt.svg'
Copying 'D:\trydjango\lib\site-packages\django\contrib\admin\static\admin\img\icon-unknown.svg'
Copying 'D:\trydjango\lib\site-packages\django\contrib\admin\static\admin\img\icon-yes.svg'
Copying 'D:\trydjango\lib\site-packages\django\contrib\admin\static\admin\img\inline-delete.svg'
Copying 'D:\trydjango\lib\site-packages\django\contrib\admin\static\admin\img\LICENSE'
Copying 'D:\trydjango\lib\site-packages\django\contrib\admin\static\admin\img\README.txt'
Copying 'D:\trydjango\lib\site-packages\django\contrib\admin\static\admin\img\search.svg'
Copying 'D:\trydjango\lib\site-packages\django\contrib\admin\static\admin\img\selector-icons.svg'
Copying 'D:\trydjango\lib\site-packages\django\contrib\admin\static\admin\img\sorting-icons.svg'
Copying 'D:\trydjango\lib\site-packages\django\contrib\admin\static\admin\img\tooltag-add.svg'
Copying 'D:\trydjango\lib\site-packages\django\contrib\admin\static\admin\img\tooltag-arrowright.svg'
Copying 'D:\trydjango\lib\site-packages\django\contrib\admin\static\admin\img\gis\move_vertex_off.svg'
Copying 'D:\trydjango\lib\site-packages\django\contrib\admin\static\admin\img\gis\move_vertex_on.svg'
Copying 'D:\trydjango\lib\site-packages\django\contrib\admin\static\admin\js\actions.js'
Copying 'D:\trydjango\lib\site-packages\django\contrib\admin\static\admin\js\actions.min.js'
Copying 'D:\trydjango\lib\site-packages\django\contrib\admin\static\admin\js\calendar.js'
Copying 'D:\trydjango\lib\site-packages\django\contrib\admin\static\admin\js\collapse.js'
Copying 'D:\trydjango\lib\site-packages\django\contrib\admin\static\admin\js\collapse.min.js'
Copying 'D:\trydjango\lib\site-packages\django\contrib\admin\static\admin\js\core.js'
Copying 'D:\trydjango\lib\site-packages\django\contrib\admin\static\admin\js\inlines.js'
Copying 'D:\trydjango\lib\site-packages\django\contrib\admin\static\admin\js\inlines.min.js'
Copying 'D:\trydjango\lib\site-packages\django\contrib\admin\static\admin\js\jquery.init.js'
Copying 'D:\trydjango\lib\site-packages\django\contrib\admin\static\admin\js\prepopulate.js'
Copying 'D:\trydjango\lib\site-packages\django\contrib\admin\static\admin\js\prepopulate.min.js'
Copying 'D:\trydjango\lib\site-packages\django\contrib\admin\static\admin\js\SelectBox.js'
Copying 'D:\trydjango\lib\site-packages\django\contrib\admin\static\admin\js\SelectFilter2.js'
Copying 'D:\trydjango\lib\site-packages\django\contrib\admin\static\admin\js\timeparse.js'
Copying 'D:\trydjango\lib\site-packages\django\contrib\admin\static\admin\js\urlify.js'
Copying 'D:\trydjango\lib\site-packages\django\contrib\admin\static\admin\js\admin\DateTimeShortcuts.js'
Copying 'D:\trydjango\lib\site-packages\django\contrib\admin\static\admin\js\admin\RelatedObjectLookups.js'
Copying 'D:\trydjango\lib\site-packages\django\contrib\admin\static\admin\js\vendor\jquery\jquery.js'
Copying 'D:\trydjango\lib\site-packages\django\contrib\admin\static\admin\js\vendor\jquery\jquery.min.js'
Copying 'D:\trydjango\lib\site-packages\django\contrib\admin\static\admin\js\vendor\jquery\LICENSE-JQUERY.txt'
Copying 'D:\trydjango\lib\site-packages\django\contrib\admin\static\admin\js\vendor\xregexp\LICENSE-XREGEXP.txt'
Copying 'D:\trydjango\lib\site-packages\django\contrib\admin\static\admin\js\vendor\xregexp\xregexp.min.js'

56 static files copied to 'D:\trydjango\static_cdn'.

(trydjango) D:\trydjango\src>python manage.py collectstatic

You have requested to collect static files at the destination
location as specified in your settings:

    D:\trydjango\static_cdn

This will overwrite existing files!
Are you sure you want to do this?

Type 'yes' to continue, or 'no' to cancel: yes
Copying 'D:\trydjango\src\static\css\base.css'

1 static file copied to 'D:\trydjango\static_cdn', 56 unmodified.

(trydjango) D:\trydjango\src>python manage.py runserver
Performing system checks...

System check identified no issues (0 silenced).
February 06, 2019 - 14:06:53
Django version 1.9, using settings 'trydjango.settings'
Starting development server at http://127.0.0.1:8000/
Quit the server with CTRL-BREAK.
[06/Feb/2019 14:06:56] "GET /posts/20/ HTTP/1.1" 200 412
[06/Feb/2019 14:06:56] "GET /static/css/base.html HTTP/1.1" 404 1753
[06/Feb/2019 14:07:00] "GET /static/css/base.html HTTP/1.1" 404 1753
[06/Feb/2019 14:07:48] "GET /posts/20/ HTTP/1.1" 200 411
[06/Feb/2019 14:07:48] "GET /static/css/base.css HTTP/1.1" 200 23
[06/Feb/2019 14:09:56] "GET /posts/20/ HTTP/1.1" 200 412
[06/Feb/2019 14:09:56] "GET /static/css/base.css HTTP/1.1" 304 0
Performing system checks...

System check identified no issues (0 silenced).
February 06, 2019 - 14:10:25
Django version 1.9, using settings 'trydjango.settings'
Starting development server at http://127.0.0.1:8000/
Quit the server with CTRL-BREAK.
[06/Feb/2019 14:10:27] "GET /posts/20/ HTTP/1.1" 200 415
[06/Feb/2019 14:10:27] "GET /staticabc/css/base.css HTTP/1.1" 200 23
Performing system checks...

System check identified no issues (0 silenced).
February 06, 2019 - 14:10:39
Django version 1.9, using settings 'trydjango.settings'
Starting development server at http://127.0.0.1:8000/
Quit the server with CTRL-BREAK.
Performing system checks...

System check identified no issues (0 silenced).
February 06, 2019 - 14:11:37
Django version 1.9, using settings 'trydjango.settings'
Starting development server at http://127.0.0.1:8000/
Quit the server with CTRL-BREAK.

(trydjango) D:\trydjango\src>python manage.py runserver
Performing system checks...

System check identified no issues (0 silenced).
February 06, 2019 - 15:44:19
Django version 1.9, using settings 'trydjango.settings'
Starting development server at http://127.0.0.1:8000/
Quit the server with CTRL-BREAK.
[06/Feb/2019 15:44:21] "GET /admin/ HTTP/1.1" 200 4562
[06/Feb/2019 15:44:21] "GET /static/admin/css/base.css HTTP/1.1" 304 0
[06/Feb/2019 15:44:21] "GET /static/admin/css/dashboard.css HTTP/1.1" 304 0
[06/Feb/2019 15:44:21] "GET /static/admin/css/fonts.css HTTP/1.1" 304 0
[06/Feb/2019 15:44:21] "GET /static/admin/img/icon-changelink.svg HTTP/1.1" 304 0
[06/Feb/2019 15:44:21] "GET /static/admin/img/icon-addlink.svg HTTP/1.1" 304 0
[06/Feb/2019 15:44:21] "GET /static/admin/fonts/Roboto-Light-webfont.woff HTTP/1.1" 304 0
[06/Feb/2019 15:44:21] "GET /static/admin/fonts/Roboto-Bold-webfont.woff HTTP/1.1" 304 0
[06/Feb/2019 15:44:21] "GET /static/admin/fonts/Roboto-Regular-webfont.woff HTTP/1.1" 304 0
Internal Server Error: /admin/posts/post/
Traceback (most recent call last):
  File "D:\trydjango\lib\site-packages\django\core\handlers\base.py", line 149, in get_response
    response = self.process_exception_by_middleware(e, request)
  File "D:\trydjango\lib\site-packages\django\core\handlers\base.py", line 147, in get_response
    response = wrapped_callback(request, *callback_args, **callback_kwargs)
  File "D:\trydjango\lib\site-packages\django\contrib\admin\options.py", line 541, in wrapper
    return self.admin_site.admin_view(view)(*args, **kwargs)
  File "D:\trydjango\lib\site-packages\django\utils\decorators.py", line 149, in _wrapped_view
    response = view_func(request, *args, **kwargs)
  File "D:\trydjango\lib\site-packages\django\views\decorators\cache.py", line 57, in _wrapped_view_func
    response = view_func(request, *args, **kwargs)
  File "D:\trydjango\lib\site-packages\django\contrib\admin\sites.py", line 244, in inner
    return view(request, *args, **kwargs)
  File "D:\trydjango\lib\site-packages\django\utils\decorators.py", line 67, in _wrapper
    return bound_func(*args, **kwargs)
  File "D:\trydjango\lib\site-packages\django\utils\decorators.py", line 149, in _wrapped_view
    response = view_func(request, *args, **kwargs)
  File "D:\trydjango\lib\site-packages\django\utils\decorators.py", line 63, in bound_func
    return func.__get__(self, type(self))(*args2, **kwargs2)
  File "D:\trydjango\lib\site-packages\django\contrib\admin\options.py", line 1575, in changelist_view
    selection_note=_('0 of %(cnt)s selected') % {'cnt': len(cl.result_list)},
  File "D:\trydjango\lib\site-packages\django\db\models\query.py", line 240, in __len__
    self._fetch_all()
  File "D:\trydjango\lib\site-packages\django\db\models\query.py", line 1074, in _fetch_all
    self._result_cache = list(self.iterator())
  File "D:\trydjango\lib\site-packages\django\db\models\query.py", line 52, in __iter__
    results = compiler.execute_sql()
  File "D:\trydjango\lib\site-packages\django\db\models\sql\compiler.py", line 852, in execute_sql
    cursor.execute(sql, params)
  File "D:\trydjango\lib\site-packages\django\db\backends\utils.py", line 79, in execute
    return super(CursorDebugWrapper, self).execute(sql, params)
  File "D:\trydjango\lib\site-packages\django\db\backends\utils.py", line 64, in execute
    return self.cursor.execute(sql, params)
  File "D:\trydjango\lib\site-packages\django\db\utils.py", line 95, in __exit__
    six.reraise(dj_exc_type, dj_exc_value, traceback)
  File "D:\trydjango\lib\site-packages\django\db\backends\utils.py", line 64, in execute
    return self.cursor.execute(sql, params)
  File "D:\trydjango\lib\site-packages\django\db\backends\sqlite3\base.py", line 323, in execute
    return Database.Cursor.execute(self, query, params)
OperationalError: no such column: posts_post.subhead
[06/Feb/2019 15:44:25] "GET /admin/posts/post/ HTTP/1.1" 500 136673
[06/Feb/2019 15:44:34] "GET /admin/posts/ HTTP/1.1" 200 2201
[06/Feb/2019 15:44:37] "GET /admin/posts/post/add/ HTTP/1.1" 200 6320
[06/Feb/2019 15:44:37] "GET /static/admin/css/forms.css HTTP/1.1" 304 0
[06/Feb/2019 15:44:37] "GET /static/admin/js/core.js HTTP/1.1" 304 0
[06/Feb/2019 15:44:37] "GET /static/admin/js/admin/RelatedObjectLookups.js HTTP/1.1" 304 0
[06/Feb/2019 15:44:37] "GET /static/admin/js/vendor/jquery/jquery.js HTTP/1.1" 304 0
[06/Feb/2019 15:44:37] "GET /static/admin/js/jquery.init.js HTTP/1.1" 304 0
[06/Feb/2019 15:44:37] "GET /static/admin/js/actions.js HTTP/1.1" 304 0
[06/Feb/2019 15:44:37] "GET /static/admin/css/widgets.css HTTP/1.1" 304 0
[06/Feb/2019 15:44:37] "GET /static/admin/js/urlify.js HTTP/1.1" 304 0
[06/Feb/2019 15:44:37] "GET /static/admin/js/prepopulate.js HTTP/1.1" 304 0
[06/Feb/2019 15:44:37] "GET /static/admin/js/vendor/xregexp/xregexp.min.js HTTP/1.1" 304 0
[06/Feb/2019 15:44:37] "GET /admin/jsi18n/ HTTP/1.1" 200 3217

(trydjango) D:\trydjango\src>python manage.py migrate
Operations to perform:
  Apply all migrations: admin, contenttypes, posts, auth, sessions
Running migrations:
  No migrations to apply.
  Your models have changes that are not yet reflected in a migration, and so won't be applied.
  Run 'manage.py makemigrations' to make new migrations, and then re-run 'manage.py migrate' to apply them.

(trydjango) D:\trydjango\src>python manage.py migrate
Operations to perform:
  Apply all migrations: admin, contenttypes, posts, auth, sessions
Running migrations:
  Rendering model states... DONE
  Applying contenttypes.0001_initial... OK
  Applying auth.0001_initial... OK
  Applying admin.0001_initial... OK
  Applying admin.0002_logentry_remove_auto_add... OK
  Applying contenttypes.0002_remove_content_type_name... OK
  Applying auth.0002_alter_permission_name_max_length... OK
  Applying auth.0003_alter_user_email_max_length... OK
  Applying auth.0004_alter_user_username_opts... OK
  Applying auth.0005_alter_user_last_login_null... OK
  Applying auth.0006_require_contenttypes_0002... OK
  Applying auth.0007_alter_validators_add_error_messages... OK
  Applying posts.0001_initial... OK
  Applying sessions.0001_initial... OK

(trydjango) D:\trydjango\src>python manage.py migrate
Operations to perform:
  Apply all migrations: admin, contenttypes, auth, sessions
Running migrations:
  Rendering model states... DONE
  Applying contenttypes.0001_initial... OK
  Applying auth.0001_initial... OK
  Applying admin.0001_initial... OK
  Applying admin.0002_logentry_remove_auto_add... OK
  Applying contenttypes.0002_remove_content_type_name... OK
  Applying auth.0002_alter_permission_name_max_length... OK
  Applying auth.0003_alter_user_email_max_length... OK
  Applying auth.0004_alter_user_username_opts... OK
  Applying auth.0005_alter_user_last_login_null... OK
  Applying auth.0006_require_contenttypes_0002... OK
  Applying auth.0007_alter_validators_add_error_messages... OK
  Applying sessions.0001_initial... OK

(trydjango) D:\trydjango\src>python manage.py makemigrations
No changes detected

(trydjango) D:\trydjango\src>python manage.py migrate
Operations to perform:
  Apply all migrations: admin, contenttypes, auth, sessions
Running migrations:
  No migrations to apply.

(trydjango) D:\trydjango\src>python manage.py migrate polls
CommandError: App 'polls' does not have migrations.

(trydjango) D:\trydjango\src>python manage.py migrate post
CommandError: App 'post' does not have migrations.

(trydjango) D:\trydjango\src>python manage.py migrate Posts
CommandError: App 'Posts' does not have migrations.

(trydjango) D:\trydjango\src>python manage.py migrate Post
CommandError: App 'Post' does not have migrations.

(trydjango) D:\trydjango\src>python manage.py makemigrations
No changes detected

(trydjango) D:\trydjango\src>python manage.py shell
Python 2.7.15 |Anaconda, Inc.| (default, May  1 2018, 18:37:09) [MSC v.1500 64 bit (AMD64)] on win32
Type "help", "copyright", "credits" or "license" for more information.
(InteractiveConsole)
>>> from models import Post
Traceback (most recent call last):
  File "<console>", line 1, in <module>
ImportError: No module named models
>>> from .models import Post
Traceback (most recent call last):
  File "<console>", line 1, in <module>
ImportError: No module named models
>>> from posts.models import Post
>>> Post
<class 'posts.models.Post'>
>>> query = Post()
>>> Post.objects.all()
Traceback (most recent call last):
  File "<console>", line 1, in <module>
  File "D:\trydjango\lib\site-packages\django\db\models\query.py", line 234, in __repr__
    data = list(self[:REPR_OUTPUT_SIZE + 1])
  File "D:\trydjango\lib\site-packages\django\db\models\query.py", line 258, in __iter__
    self._fetch_all()
  File "D:\trydjango\lib\site-packages\django\db\models\query.py", line 1074, in _fetch_all
    self._result_cache = list(self.iterator())
  File "D:\trydjango\lib\site-packages\django\db\models\query.py", line 52, in __iter__
    results = compiler.execute_sql()
  File "D:\trydjango\lib\site-packages\django\db\models\sql\compiler.py", line 852, in execute_sql
    cursor.execute(sql, params)
  File "D:\trydjango\lib\site-packages\django\db\backends\utils.py", line 79, in execute
    return super(CursorDebugWrapper, self).execute(sql, params)
  File "D:\trydjango\lib\site-packages\django\db\backends\utils.py", line 64, in execute
    return self.cursor.execute(sql, params)
  File "D:\trydjango\lib\site-packages\django\db\utils.py", line 95, in __exit__
    six.reraise(dj_exc_type, dj_exc_value, traceback)
  File "D:\trydjango\lib\site-packages\django\db\backends\utils.py", line 64, in execute
    return self.cursor.execute(sql, params)
  File "D:\trydjango\lib\site-packages\django\db\backends\sqlite3\base.py", line 323, in execute
    return Database.Cursor.execute(self, query, params)
OperationalError: no such table: posts_post
>>> query.title = "Ra"
>>> query.content = "Hello"
>>> query.save()
Traceback (most recent call last):
  File "<console>", line 1, in <module>
  File "D:\trydjango\lib\site-packages\django\db\models\base.py", line 700, in save
    force_update=force_update, update_fields=update_fields)
  File "D:\trydjango\lib\site-packages\django\db\models\base.py", line 728, in save_base
    updated = self._save_table(raw, cls, force_insert, force_update, using, update_fields)
  File "D:\trydjango\lib\site-packages\django\db\models\base.py", line 812, in _save_table
    result = self._do_insert(cls._base_manager, using, fields, update_pk, raw)
  File "D:\trydjango\lib\site-packages\django\db\models\base.py", line 851, in _do_insert
    using=using, raw=raw)
  File "D:\trydjango\lib\site-packages\django\db\models\manager.py", line 122, in manager_method
    return getattr(self.get_queryset(), name)(*args, **kwargs)
  File "D:\trydjango\lib\site-packages\django\db\models\query.py", line 1039, in _insert
    return query.get_compiler(using=using).execute_sql(return_id)
  File "D:\trydjango\lib\site-packages\django\db\models\sql\compiler.py", line 1064, in execute_sql
    cursor.execute(sql, params)
  File "D:\trydjango\lib\site-packages\django\db\backends\utils.py", line 79, in execute
    return super(CursorDebugWrapper, self).execute(sql, params)
  File "D:\trydjango\lib\site-packages\django\db\backends\utils.py", line 64, in execute
    return self.cursor.execute(sql, params)
  File "D:\trydjango\lib\site-packages\django\db\utils.py", line 95, in __exit__
    six.reraise(dj_exc_type, dj_exc_value, traceback)
  File "D:\trydjango\lib\site-packages\django\db\backends\utils.py", line 64, in execute
    return self.cursor.execute(sql, params)
  File "D:\trydjango\lib\site-packages\django\db\backends\sqlite3\base.py", line 323, in execute
    return Database.Cursor.execute(self, query, params)
OperationalError: no such table: posts_post
>>> ^Z


(trydjango) D:\trydjango\src>python manage.py migrate
Operations to perform:
  Apply all migrations: admin, contenttypes, auth, sessions
Running migrations:
  No migrations to apply.

(trydjango) D:\trydjango\src>python manage.py runserver
Performing system checks...

System check identified no issues (0 silenced).
February 06, 2019 - 16:00:00
Django version 1.9, using settings 'trydjango.settings'
Starting development server at http://127.0.0.1:8000/
Quit the server with CTRL-BREAK.
[06/Feb/2019 16:00:03] "GET /posts/create/ HTTP/1.1" 200 790
[06/Feb/2019 16:00:03] "GET /static/css/base.css HTTP/1.1" 304 0
Internal Server Error: /posts/create/
Traceback (most recent call last):
  File "D:\trydjango\lib\site-packages\django\core\handlers\base.py", line 149, in get_response
    response = self.process_exception_by_middleware(e, request)
  File "D:\trydjango\lib\site-packages\django\core\handlers\base.py", line 147, in get_response
    response = wrapped_callback(request, *callback_args, **callback_kwargs)
  File "D:\trydjango\src\posts\views.py", line 12, in post_create
    instance.save()
  File "D:\trydjango\lib\site-packages\django\db\models\base.py", line 700, in save
    force_update=force_update, update_fields=update_fields)
  File "D:\trydjango\lib\site-packages\django\db\models\base.py", line 728, in save_base
    updated = self._save_table(raw, cls, force_insert, force_update, using, update_fields)
  File "D:\trydjango\lib\site-packages\django\db\models\base.py", line 812, in _save_table
    result = self._do_insert(cls._base_manager, using, fields, update_pk, raw)
  File "D:\trydjango\lib\site-packages\django\db\models\base.py", line 851, in _do_insert
    using=using, raw=raw)
  File "D:\trydjango\lib\site-packages\django\db\models\manager.py", line 122, in manager_method
    return getattr(self.get_queryset(), name)(*args, **kwargs)
  File "D:\trydjango\lib\site-packages\django\db\models\query.py", line 1039, in _insert
    return query.get_compiler(using=using).execute_sql(return_id)
  File "D:\trydjango\lib\site-packages\django\db\models\sql\compiler.py", line 1064, in execute_sql
    cursor.execute(sql, params)
  File "D:\trydjango\lib\site-packages\django\db\backends\utils.py", line 79, in execute
    return super(CursorDebugWrapper, self).execute(sql, params)
  File "D:\trydjango\lib\site-packages\django\db\backends\utils.py", line 64, in execute
    return self.cursor.execute(sql, params)
  File "D:\trydjango\lib\site-packages\django\db\utils.py", line 95, in __exit__
    six.reraise(dj_exc_type, dj_exc_value, traceback)
  File "D:\trydjango\lib\site-packages\django\db\backends\utils.py", line 64, in execute
    return self.cursor.execute(sql, params)
  File "D:\trydjango\lib\site-packages\django\db\backends\sqlite3\base.py", line 323, in execute
    return Database.Cursor.execute(self, query, params)
OperationalError: no such table: posts_post
[06/Feb/2019 16:00:14] "POST /posts/create/ HTTP/1.1" 500 122128
[06/Feb/2019 16:00:26] "GET /admin/auth/user/ HTTP/1.1" 302 0
[06/Feb/2019 16:00:26] "GET /admin/login/?next=/admin/auth/user/ HTTP/1.1" 200 1703
[06/Feb/2019 16:00:26] "GET /static/admin/css/login.css HTTP/1.1" 304 0
[06/Feb/2019 16:00:26] "GET /static/admin/css/fonts.css HTTP/1.1" 304 0
[06/Feb/2019 16:00:26] "GET /static/admin/fonts/Roboto-Regular-webfont.woff HTTP/1.1" 304 0
[06/Feb/2019 16:00:26] "GET /static/admin/fonts/Roboto-Light-webfont.woff HTTP/1.1" 304 0
[06/Feb/2019 16:00:28] "POST /admin/login/?next=/admin/auth/user/ HTTP/1.1" 200 1872
[06/Feb/2019 16:00:28] "GET /static/admin/fonts/Roboto-Bold-webfont.woff HTTP/1.1" 304 0

(trydjango) D:\trydjango\src>python manage.py createsuperuser
Username (leave blank to use 'ravinder.baid'):
Email address:
Password:
Password (again):
Superuser created successfully.

(trydjango) D:\trydjango\src>python manage.py runserver
Performing system checks...

System check identified no issues (0 silenced).
February 06, 2019 - 16:01:07
Django version 1.9, using settings 'trydjango.settings'
Starting development server at http://127.0.0.1:8000/
Quit the server with CTRL-BREAK.
[06/Feb/2019 16:01:10] "GET /admin/login/?next=/admin/auth/user/ HTTP/1.1" 200 1703
[06/Feb/2019 16:01:12] "POST /admin/login/?next=/admin/auth/user/ HTTP/1.1" 302 0
[06/Feb/2019 16:01:13] "GET /admin/auth/user/ HTTP/1.1" 200 6614
[06/Feb/2019 16:01:13] "GET /static/admin/css/changelists.css HTTP/1.1" 304 0
[06/Feb/2019 16:01:13] "GET /static/admin/img/search.svg HTTP/1.1" 304 0
[06/Feb/2019 16:01:13] "GET /static/admin/img/icon-yes.svg HTTP/1.1" 304 0
[06/Feb/2019 16:01:13] "GET /admin/jsi18n/ HTTP/1.1" 200 3217
[06/Feb/2019 16:01:13] "GET /static/admin/img/tooltag-add.svg HTTP/1.1" 304 0
[06/Feb/2019 16:01:13] "GET /static/admin/img/sorting-icons.svg HTTP/1.1" 200 1097

(trydjango) D:\trydjango\src>python manage.py migrate
Operations to perform:
  Apply all migrations: admin, contenttypes, auth, sessions
Running migrations:
  No migrations to apply.

(trydjango) D:\trydjango\src>python manage.py makemigrations
No changes detected

(trydjango) D:\trydjango\src>python manage.py makemigrations
No changes detected

(trydjango) D:\trydjango\src>python manage.py migrate
Operations to perform:
  Apply all migrations: admin, contenttypes, auth, sessions
Running migrations:
  Rendering model states... DONE
  Applying contenttypes.0001_initial... OK
  Applying auth.0001_initial... OK
  Applying admin.0001_initial... OK
  Applying admin.0002_logentry_remove_auto_add... OK
  Applying contenttypes.0002_remove_content_type_name... OK
  Applying auth.0002_alter_permission_name_max_length... OK
  Applying auth.0003_alter_user_email_max_length... OK
  Applying auth.0004_alter_user_username_opts... OK
  Applying auth.0005_alter_user_last_login_null... OK
  Applying auth.0006_require_contenttypes_0002... OK
  Applying auth.0007_alter_validators_add_error_messages... OK
  Applying sessions.0001_initial... OK

(trydjango) D:\trydjango\src>python manage.py makemigrations
No changes detected

(trydjango) D:\trydjango\src>python manage.py migrate Post
CommandError: App 'Post' does not have migrations.

(trydjango) D:\trydjango\src>python manage.py migrate posts
CommandError: App 'posts' does not have migrations.

(trydjango) D:\trydjango\src>
(trydjango) D:\trydjango\src>python manage.py migrate
Operations to perform:
  Apply all migrations: admin, contenttypes, auth, sessions
Running migrations:
  No migrations to apply.

(trydjango) D:\trydjango\src>python manage.py migrate
Operations to perform:
  Apply all migrations: admin, contenttypes, auth, sessions
Running migrations:
  No migrations to apply.
  Your models have changes that are not yet reflected in a migration, and so won't be applied.
  Run 'manage.py makemigrations' to make new migrations, and then re-run 'manage.py migrate' to apply them.

(trydjango) D:\trydjango\src>python manage.py makemigrations
Migrations for 'posts':
  0001_initial.py:
    - Create model Post

(trydjango) D:\trydjango\src>python manage.py runserver
Performing system checks...

System check identified no issues (0 silenced).

You have unapplied migrations; your app may not work properly until they are applied.
Run 'python manage.py migrate' to apply them.
February 06, 2019 - 16:20:11
Django version 1.9, using settings 'trydjango.settings'
Starting development server at http://127.0.0.1:8000/
Quit the server with CTRL-BREAK.
[06/Feb/2019 16:20:12] "GET /admin/ HTTP/1.1" 302 0
[06/Feb/2019 16:20:12] "GET /admin/login/?next=/admin/ HTTP/1.1" 200 1683
[06/Feb/2019 16:20:14] "POST /admin/login/?next=/admin/ HTTP/1.1" 200 1852

(trydjango) D:\trydjango\src>python manage.py createsuperuser
Username (leave blank to use 'ravinder.baid'):
Email address:
Password:
Password (again):
Superuser created successfully.

(trydjango) D:\trydjango\src>python manage.py runserver
Performing system checks...

System check identified no issues (0 silenced).

You have unapplied migrations; your app may not work properly until they are applied.
Run 'python manage.py migrate' to apply them.
February 06, 2019 - 16:20:46
Django version 1.9, using settings 'trydjango.settings'
Starting development server at http://127.0.0.1:8000/
Quit the server with CTRL-BREAK.
[06/Feb/2019 16:20:46] "GET /admin/login/?next=/admin/ HTTP/1.1" 200 1683
[06/Feb/2019 16:20:47] "POST /admin/login/?next=/admin/ HTTP/1.1" 302 0
[06/Feb/2019 16:20:47] "GET /admin/ HTTP/1.1" 200 3416
Internal Server Error: /posts/
Traceback (most recent call last):
  File "D:\trydjango\lib\site-packages\django\core\handlers\base.py", line 149, in get_response
    response = self.process_exception_by_middleware(e, request)
  File "D:\trydjango\lib\site-packages\django\core\handlers\base.py", line 147, in get_response
    response = wrapped_callback(request, *callback_args, **callback_kwargs)
  File "D:\trydjango\src\posts\views.py", line 43, in post_list
    return render(self,'post_list.html',context)
  File "D:\trydjango\lib\site-packages\django\shortcuts.py", line 67, in render
    template_name, context, request=request, using=using)
  File "D:\trydjango\lib\site-packages\django\template\loader.py", line 97, in render_to_string
    return template.render(context, request)
  File "D:\trydjango\lib\site-packages\django\template\backends\django.py", line 95, in render
    return self.template.render(context)
  File "D:\trydjango\lib\site-packages\django\template\base.py", line 206, in render
    return self._render(context)
  File "D:\trydjango\lib\site-packages\django\template\base.py", line 197, in _render
    return self.nodelist.render(context)
  File "D:\trydjango\lib\site-packages\django\template\base.py", line 988, in render
    bit = node.render_annotated(context)
  File "D:\trydjango\lib\site-packages\django\template\base.py", line 955, in render_annotated
    return self.render(context)
  File "D:\trydjango\lib\site-packages\django\template\loader_tags.py", line 173, in render
    return compiled_parent._render(context)
  File "D:\trydjango\lib\site-packages\django\template\base.py", line 197, in _render
    return self.nodelist.render(context)
  File "D:\trydjango\lib\site-packages\django\template\base.py", line 988, in render
    bit = node.render_annotated(context)
  File "D:\trydjango\lib\site-packages\django\template\base.py", line 955, in render_annotated
    return self.render(context)
  File "D:\trydjango\lib\site-packages\django\template\loader_tags.py", line 69, in render
    result = block.nodelist.render(context)
  File "D:\trydjango\lib\site-packages\django\template\base.py", line 988, in render
    bit = node.render_annotated(context)
  File "D:\trydjango\lib\site-packages\django\template\base.py", line 955, in render_annotated
    return self.render(context)
  File "D:\trydjango\lib\site-packages\django\template\defaulttags.py", line 168, in render
    len_values = len(values)
  File "D:\trydjango\lib\site-packages\django\db\models\query.py", line 240, in __len__
    self._fetch_all()
  File "D:\trydjango\lib\site-packages\django\db\models\query.py", line 1074, in _fetch_all
    self._result_cache = list(self.iterator())
  File "D:\trydjango\lib\site-packages\django\db\models\query.py", line 52, in __iter__
    results = compiler.execute_sql()
  File "D:\trydjango\lib\site-packages\django\db\models\sql\compiler.py", line 852, in execute_sql
    cursor.execute(sql, params)
  File "D:\trydjango\lib\site-packages\django\db\backends\utils.py", line 79, in execute
    return super(CursorDebugWrapper, self).execute(sql, params)
  File "D:\trydjango\lib\site-packages\django\db\backends\utils.py", line 64, in execute
    return self.cursor.execute(sql, params)
  File "D:\trydjango\lib\site-packages\django\db\utils.py", line 95, in __exit__
    six.reraise(dj_exc_type, dj_exc_value, traceback)
  File "D:\trydjango\lib\site-packages\django\db\backends\utils.py", line 64, in execute
    return self.cursor.execute(sql, params)
  File "D:\trydjango\lib\site-packages\django\db\backends\sqlite3\base.py", line 323, in execute
    return Database.Cursor.execute(self, query, params)
OperationalError: no such table: posts_post
[06/Feb/2019 16:20:56] "GET /posts/ HTTP/1.1" 500 168423
[06/Feb/2019 16:21:06] "GET /posts/create/ HTTP/1.1" 200 790
[06/Feb/2019 16:21:06] "GET /static/css/base.css HTTP/1.1" 304 0
Internal Server Error: /posts/create/
Traceback (most recent call last):
  File "D:\trydjango\lib\site-packages\django\core\handlers\base.py", line 149, in get_response
    response = self.process_exception_by_middleware(e, request)
  File "D:\trydjango\lib\site-packages\django\core\handlers\base.py", line 147, in get_response
    response = wrapped_callback(request, *callback_args, **callback_kwargs)
  File "D:\trydjango\src\posts\views.py", line 12, in post_create
    instance.save()
  File "D:\trydjango\lib\site-packages\django\db\models\base.py", line 700, in save
    force_update=force_update, update_fields=update_fields)
  File "D:\trydjango\lib\site-packages\django\db\models\base.py", line 728, in save_base
    updated = self._save_table(raw, cls, force_insert, force_update, using, update_fields)
  File "D:\trydjango\lib\site-packages\django\db\models\base.py", line 812, in _save_table
    result = self._do_insert(cls._base_manager, using, fields, update_pk, raw)
  File "D:\trydjango\lib\site-packages\django\db\models\base.py", line 851, in _do_insert
    using=using, raw=raw)
  File "D:\trydjango\lib\site-packages\django\db\models\manager.py", line 122, in manager_method
    return getattr(self.get_queryset(), name)(*args, **kwargs)
  File "D:\trydjango\lib\site-packages\django\db\models\query.py", line 1039, in _insert
    return query.get_compiler(using=using).execute_sql(return_id)
  File "D:\trydjango\lib\site-packages\django\db\models\sql\compiler.py", line 1064, in execute_sql
    cursor.execute(sql, params)
  File "D:\trydjango\lib\site-packages\django\db\backends\utils.py", line 79, in execute
    return super(CursorDebugWrapper, self).execute(sql, params)
  File "D:\trydjango\lib\site-packages\django\db\backends\utils.py", line 64, in execute
    return self.cursor.execute(sql, params)
  File "D:\trydjango\lib\site-packages\django\db\utils.py", line 95, in __exit__
    six.reraise(dj_exc_type, dj_exc_value, traceback)
  File "D:\trydjango\lib\site-packages\django\db\backends\utils.py", line 64, in execute
    return self.cursor.execute(sql, params)
  File "D:\trydjango\lib\site-packages\django\db\backends\sqlite3\base.py", line 323, in execute
    return Database.Cursor.execute(self, query, params)
OperationalError: no such table: posts_post
[06/Feb/2019 16:21:11] "POST /posts/create/ HTTP/1.1" 500 122135
Performing system checks...

System check identified no issues (0 silenced).

You have unapplied migrations; your app may not work properly until they are applied.
Run 'python manage.py migrate' to apply them.
February 06, 2019 - 16:21:56
Django version 1.9, using settings 'trydjango.settings'
Starting development server at http://127.0.0.1:8000/
Quit the server with CTRL-BREAK.

(trydjango) D:\trydjango\src>python manage.py migrate
Operations to perform:
  Apply all migrations: admin, contenttypes, posts, auth, sessions
Running migrations:
  Rendering model states... DONE
  Applying posts.0001_initial... OK

(trydjango) D:\trydjango\src>python manage.py runserver
Performing system checks...

System check identified no issues (0 silenced).
February 06, 2019 - 16:22:22
Django version 1.9, using settings 'trydjango.settings'
Starting development server at http://127.0.0.1:8000/
Quit the server with CTRL-BREAK.
[06/Feb/2019 16:22:25] "POST /posts/create/ HTTP/1.1" 302 0
[06/Feb/2019 16:22:26] "GET /posts/1/ HTTP/1.1" 200 525
Not Found: /posts
[06/Feb/2019 16:22:30] "GET /posts HTTP/1.1" 301 0
[06/Feb/2019 16:22:30] "GET /posts/ HTTP/1.1" 200 379
[06/Feb/2019 16:22:32] "GET /posts/1/ HTTP/1.1" 200 401
[06/Feb/2019 16:28:21] "GET /posts/delete/1 HTTP/1.1" 302 0
[06/Feb/2019 16:28:22] "GET /posts/ HTTP/1.1" 200 392
[06/Feb/2019 16:28:25] "GET /posts/ HTTP/1.1" 200 268
Performing system checks...

System check identified no issues (0 silenced).
February 06, 2019 - 16:39:45
Django version 1.9, using settings 'trydjango.settings'
Starting development server at http://127.0.0.1:8000/
Quit the server with CTRL-BREAK.
/static/
[06/Feb/2019 16:39:54] "GET /posts/create/ HTTP/1.1" 200 790
[06/Feb/2019 16:39:54] "GET /static/css/base.css HTTP/1.1" 304 0
[06/Feb/2019 16:39:54] "GET /static/css/base.css HTTP/1.1" 304 0
/static/
[06/Feb/2019 16:40:15] "POST /posts/create/ HTTP/1.1" 302 0
[06/Feb/2019 16:40:15] "GET /posts/2/ HTTP/1.1" 200 521
[06/Feb/2019 16:40:21] "GET /posts/ HTTP/1.1" 200 375
Performing system checks...

System check identified no issues (0 silenced).
February 06, 2019 - 16:40:44
Django version 1.9, using settings 'trydjango.settings'
Starting development server at http://127.0.0.1:8000/
Quit the server with CTRL-BREAK.
Forbidden (CSRF token missing or incorrect.): /posts/create/
[06/Feb/2019 16:51:00] "POST /posts/create/ HTTP/1.1" 403 2274
Forbidden (CSRF token missing or incorrect.): /posts/create/
[06/Feb/2019 16:51:04] "POST /posts/create/ HTTP/1.1" 403 2274
[06/Feb/2019 16:51:08] "GET /posts/create/ HTTP/1.1" 200 790
